Workbook

Sheet 00_대시보드
A1: ① 오늘의 리스크 대시보드
A2: =TEXT(TODAY(),"yyyy-mm-dd (aaa)")&" | 손익보다 리스크를 먼저 본다. 🔴가 하나라도 있으면 신규 매수 금지."
A4: Ⅰ. 한눈에 보는 상태 | I4: Ⅸ. 리스크 추이 (01_일별로그 자동)
A5: 계좌 순자산 (Asset) | B5: ★ 오늘 청산하면 남는 돈 | C5: 실질 주식 Exposure | D5: 실질 레버리지 | E5: 담보비율 | F5: 청산까지 여력 | G5: 위반 | H5: 기한초과 체크
A6: ='03_포지션'!$B$41 | B6: ='03_포지션'!$B$43-'09_CF_원금'!$F$135 | C6: ='03_포지션'!$B$37 | D6: ='03_포지션'!$B$54 | E6: ='03_포지션'!$B$51 | F6: ='03_포지션'!$B$52 | G6: ='02_룰북'!$G$22 | H6: ='02_룰북'!$H$47
A7: 총평가 − 신용 | B7: 순수 자기자본 − 해외주식 예상세액 | C7: 레버ETF 배수 반영 | D7: Expo ÷ 자기자본 | E7: 국장 기준 | F7: 몇 % 더 빠지면 청산 | G7: 룰북 🔴 | H7: 룰북 체크리스트
A9: Ⅱ. 이번 주 투자 기조 (09_뷰트래커에서 갱신)
A10: 상태 | B10: 다음 점검일 | C10: 한 줄 기조 | D10: 레버리지 스탠스 | E10: 뷰트래커 제안 | F10: 무효화 조건 발동
A11: ='05_뷰트래커'!$D$5 | B11: ='05_뷰트래커'!$B$5 | C11: ='05_뷰트래커'!$E$5 | D11: ='05_뷰트래커'!$F$5 | E11: ='05_뷰트래커'!$G$5 | F11: ='05_뷰트래커'!$G$12
A13: Ⅲ. 계좌별 현황
A14: 계좌 | B14: 평가금액(명목) | C14: 신용 | D14: 순자산 (Asset) | E14: 누적 원금 | F14: 누적 손익 | G14: 수익률 | H14: 비고
A15: 국장 | B15: =SUMIFS('03_포지션'!$I$17:$I$31,'03_포지션'!$C$17:$C$31,"국장")+'03_포지션'!$B$6 | C15: ='03_포지션'!$C$6 | D15: =B15-C15 | E15: ='09_CF_원금'!$B$97 | F15: =D15-E15 | G15: =IF(E15<=0,"산출불가",F15/E15) | H15: =IF(E15<=0,"⚠️ 계좌간 이체로 원금 0 이하 → %는 무의미","")
A16: 미장 | B16: =SUMIFS('03_포지션'!$I$17:$I$31,'03_포지션'!$C$17:$C$31,"미장")+'03_포지션'!$B$7 | C16: ='03_포지션'!$C$7 | D16: =B16-C16 | E16: ='09_CF_원금'!$B$98 | F16: =D16-E16 | G16: =IF(E16<=0,"산출불가",F16/E16) | H16: =IF(E16<=0,"⚠️ 계좌간 이체로 원금 0 이하 → %는 무의미","")
A17: ISA | B17: =SUMIFS('03_포지션'!$I$17:$I$31,'03_포지션'!$C$17:$C$31,"ISA")+'03_포지션'!$B$8 | C17: ='03_포지션'!$C$8 | D17: =B17-C17 | E17: ='09_CF_원금'!$B$99 | F17: =D17-E17 | G17: =IF(E17<=0,"산출불가",F17/E17) | H17: =IF(E17<=0,"⚠️ 계좌간 이체로 원금 0 이하 → %는 무의미","")
A18: 합계 | B18: =SUM(B15:B17) | C18: =SUM(C15:C17) | D18: =SUM(D15:D17) | E18: =SUM(E15:E17) | F18: =SUM(F15:F17) | G18: =IFERROR(F18/E18,"")
A20: Ⅳ. 차입 현황
A21: 증권사 신용 | B21: 내재 레버리지 | C21: 증권 차입 | D21: ★ 증권 차입 ÷ 연봉 | E21: 연봉(세전) | F21: 회사대출 | G21: 총 차입 | H21: ★ 총 차입 ÷ 연봉
A22: ='03_포지션'!$B$40 | B22: ='03_포지션'!$B$44 | C22: ='03_포지션'!$B$45 | D22: ='03_포지션'!$B$65 | E22: ='09_CF_원금'!$B$108 | F22: ='03_포지션'!$B$42 | G22: =C22+F22 | H22: =G22/E22
A24: Ⅴ. 비용 차감 후 실질 손익 — 신용이자는 이미 예수금에서 빠져나가 손익에 반영되어 있으므로 여기서 또 빼지 않습니다
A25: 표면 누적손익 | B25: (참고) 누적 지급이자 | C25: (−) 누적 강의·구독비 | D25: (−) 해외주식 예상 세액 | E25: 실질 누적 순손익 | F25: 실질 수익률
A26: =$F$18 | B26: ='09_CF_원금'!$E$127 | C26: ='09_CF_원금'!$B$179 | D26: ='09_CF_원금'!$F$135 | E26: =A26-C26-D26 | F26: =IFERROR(E26/'09_CF_원금'!$B$100,"")
A27: 표면 손익에 이미 반영 (차감 X) | B27: ↑ 차감하지 않음. 규모만 인지 | C27: 실제 지출 | D27: 미실현 부채 — 차감함 | E27: 표면 − 강의비 − 세금
A28: Ⅵ. 리스크 신호등 — 규칙 전문과 '위반 시 행동'은 02_룰북에 있습니다
A29: ID | B29: 측정지표 | C29: 내 기준 | D29: 현재값 | E29: 신호
A30: ='02_룰북'!A6 | B30: ='02_룰북'!C6 | C30: ='02_룰북'!D6 | D30: ='02_룰북'!F6 | E30: ='02_룰북'!G6
A31: ='02_룰북'!A7 | B31: ='02_룰북'!C7 | C31: ='02_룰북'!D7 | D31: ='02_룰북'!F7 | E31: ='02_룰북'!G7
A32: ='02_룰북'!A8 | B32: ='02_룰북'!C8 | C32: ='02_룰북'!D8 | D32: ='02_룰북'!F8 | E32: ='02_룰북'!G8
A33: ='02_룰북'!A9 | B33: ='02_룰북'!C9 | C33: ='02_룰북'!D9 | D33: ='02_룰북'!F9 | E33: ='02_룰북'!G9
A34: ='02_룰북'!A10 | B34: ='02_룰북'!C10 | C34: ='02_룰북'!D10 | D34: ='02_룰북'!F10 | E34: ='02_룰북'!G10
A35: ='02_룰북'!A11 | B35: ='02_룰북'!C11 | C35: ='02_룰북'!D11 | D35: ='02_룰북'!F11 | E35: ='02_룰북'!G11
A36: ='02_룰북'!A12 | B36: ='02_룰북'!C12 | C36: ='02_룰북'!D12 | D36: ='02_룰북'!F12 | E36: ='02_룰북'!G12
A37: ='02_룰북'!A13 | B37: ='02_룰북'!C13 | C37: ='02_룰북'!D13 | D37: ='02_룰북'!F13 | E37: ='02_룰북'!G13
A38: ='02_룰북'!A14 | B38: ='02_룰북'!C14 | C38: ='02_룰북'!D14 | D38: ='02_룰북'!F14 | E38: ='02_룰북'!G14
A39: ='02_룰북'!A15 | B39: ='02_룰북'!C15 | C39: ='02_룰북'!D15 | D39: ='02_룰북'!F15 | E39: ='02_룰북'!G15
A48: Ⅶ. 매수 버튼을 누르기 전 1분 — 하나라도 '아니오'면 오늘은 사지 않는다
A49: ☐ | B49: 1. 어제 이전에 계획된 매수이고, 이번 주 기조(Ⅱ)와 맞는가?
A50: ☐ | B50: 2. 손절가와, 손절 시 잃을 금액을 지금 숫자로 말할 수 있는가?
A51: ☐ | B51: 3. 계획 물량의 50% 이하인가? 오늘 하루 총매수가 순자산의 15%를 넘지 않는가? ← 5/29·6/9·7/6
A52: ☐ | B52: 4. 이 종목, 최근 3거래일 안에 매도한 적 없는가? (익절 후 재진입 쿨다운) ← 6/25
A53: ☐ | B53: 5. 이 종목 물타기 3회째 아닌가? 직전 매수에서 5거래일 지났는가? ← 7/6~10
...

Sheet 01_일별로그
A1: ① 일별 로그 — 왼쪽이 볼 것, 가운데가 넣을 것, 오른쪽(숨김)이 계산용
A2: 매일 넣는 건 P·W(국장 총평가·국장 순자산) 2칸 + 감정점수뿐입니다. 하늘색 열(Q~U)은 값을 안 넣으면 전일 값을 그대로 이어받습니다 — 주말에 03_포지션 갱신할 때만 바꿔주세요.
A4: 날짜 | B4: 순자산 (Equity) | C4: 일손익 | D4: 누적손익 | E4: MDD | F4: 청산까지 여력(근사) | G4: ★차입÷연봉 | H4: 차입비중 | I4: 현금비중 | J4: 국장 손익 | K4: 미장 손익 | L4: ISA 손익 | M4: 감정점수 (1~5) | N4: 위반 규칙ID | O4: 메모 | P4: 국장 총평가 (명목) | Q4: 미장 평가 (이월) | R4: ISA 평가 (이월) | S4: 예수금 합계 (이월) | T4: 신용잔고 (자동) | U4: 실질 주식Expo (이월) | V4: 총평가(명목) | W4: 국장 순자산 | X4: 국장 원금 | Y4: 미장 원금 | Z4: ISA 원금 | AA4: 외부투입원금 | AB4: 내재레버리지 | AC4: 총차입 | AD4: 순자산 전고점 | AE4: NQ100 | AF4: 누적손익(과거) | AG4: 국장손익(과거) | AH4: 미장손익(과거) | AI4: ISA손익(과거) | AJ4: 월키 | AK4: 위반일
A5: 45957 | B5: =IF(V5<>"",V5-T5,IF(AF5<>"",AA5+AF5,"")) | D5: =IF(OR(B5="",AA5=""),"",B5-AA5) | E5: =IF(OR(B5="",AD5=0),"",MIN(0,B5/AD5-1)) | F5: =IF(OR(U5="",T5=0,T5=""),"",(P5-T5*1.4)/U5) | G5: =IF(OR(AC5="",'09_CF_원금'!$B$108=0),"",AC5/'09_CF_원금'!$B$108) | H5: =IF(OR(U5="",U5=0,AC5=""),"",AC5/U5) | I5: =IF(OR(S5="",U5=""),"",S5/(U5+S5)) | J5: =IF(W5<>"",W5-X5,IF(AG5<>"",AG5,"")) | K5: =IF(Q5<>"",Q5-Y5,IF(AH5<>"",AH5,"")) | L5: =IF(R5<>"",R5-Z5,IF(AI5<>"",AI5,"")) | T5: =IF(OR(P5="",W5=""),"",P5-W5) | V5: =IF(P5="","",P5+IF(Q5="",0,Q5)+IF(R5="",0,R5)) | X5: =SUMIFS('09_CF_원금'!$E$6:$E$92,'09_CF_원금'!$D$6:$D$92,"국장",'09_CF_원금'!$A$6:$A$92,"<="&$A5)-SUMIFS('09_CF_원금'!$E$6:$E$92,'09_CF_원금'!$C$6:$C$92,"국장",'09_CF_원금'!$A$6:$A$92,"<="&$A5) | Y5: =SUMIFS('09_CF_원금'!$E$6:$E$92,'09_CF_원금'!$D$6:$D$92,"미장",'09_CF_원금'!$A$6:$A$92,"<="&$A5)-SUMIFS('09_CF_원금'!$E$6:$E$92,'09_CF_원금'!$C$6:$C$92,"미장",'09_CF_원금'!$A$6:$A$92,"<="&$A5) | Z5: =SUMIFS('09_CF_원금'!$E$6:$E$92,'09_CF_원금'!$D$6:$D$92,"ISA",'09_CF_원금'!$A$6:$A$92,"<="&$A5)-SUMIFS('09_CF_원금'!$E$6:$E$92,'09_CF_원금'!$C$6:$C$92,"ISA",'09_CF_원금'!$A$6:$A$92,"<="&$A5) | AA5: =IF($A5="","",X5+Y5+Z5+SUMIFS('09_CF_원금'!$E$6:$E$92,'09_CF_원금'!$D$6:$D$92,"중국",'09_CF_원금'!$A$6:$A$92,"<="&$A5)-SUMIFS('09_CF_원금'!$E$6:$E$92,'09_CF_원금'!$C$6:$C$92,"중국",'09_CF_원금'!$A$6:$A$92,"<="&$A5)+SUMIFS('09_CF_원금'!$E$6:$E$92,'09_CF_원금'!$D$6:$D$92,"업비트",'09_CF_원금'!$A$6:$A$92,"<="&$A5)-SUMIFS('09_CF_원금'!$E$6:$E$92,'09_CF_원금'!$C$6:$C$92,"업비트",'09_CF_원금'!$A$6:$A$92,"<="&$A5)) | AB5: =IF(OR(U5="",V5=""),"",U5-(V5-IF(S5="",0,S5))) | AC5: =IF(AB5="","",T5+AB5) | AD5: =IF(B5="","",MAX($B$5:B5)) | AE5: 25936 | AG5: 48440000 | AH5: 32256167 | AJ5: =IF($A5="","",YEAR($A5)*100+MONTH($A5)) | AK5: =IF($A5="","",IF($N5="",0,1))
A6: 45961 | B6: =IF(V6<>"",V6-T6,IF(AF6<>"",AA6+AF6,"")) | C6: =IF(OR(B6="",B5=""),"",B6-B5) | D6: =IF(OR(B6="",AA6=""),"",B6-AA6) | E6: =IF(OR(B6="",AD6=0),"",MIN(0,B6/AD6-1)) | F6: =IF(OR(U6="",T6=0,T6=""),"",(P6-T6*1.4)/U6) | G6: =IF(OR(AC6="",'09_CF_원금'!$B$108=0),"",AC6/'09_CF_원금'!$B$108) | H6: =IF(OR(U6="",U6=0,AC6=""),"",AC6/U6) | I6: =IF(OR(S6="",U6=""),"",S6/(U6+S6)) | J6: =IF(W6<>"",W6-X6,IF(AG6<>"",AG6,"")) | K6: =IF(Q6<>"",Q6-Y6,IF(AH6<>"",AH6,"")) | L6: =IF(R6<>"",R6-Z6,IF(AI6<>"",AI6,"")) | Q6: =IF($A6="","",IF(Q5="","",Q5)) | R6: =IF($A6="","",IF(R5="","",R5)) | S6: =IF($A6="","",IF(S5="","",S5)) | T6: =IF(OR(P6="",W6=""),"",P6-W6) | U6: =IF($A6="","",IF(U5="","",U5)) | V6: =IF(P6="","",P6+IF(Q6="",0,Q6)+IF(R6="",0,R6)) | X6: =SUMIFS('09_CF_원금'!$E$6:$E$92,'09_CF_원금'!$D$6:$D$92,"국장",'09_CF_원금'!$A$6:$A$92,"<="&$A6)-SUMIFS('09_CF_원금'!$E$6:$E$92,'09_CF_원금'!$C$6:$C$92,"국장",'09_CF_원금'!$A$6:$A$92,"<="&$A6) | Y6: =SUMIFS('09_CF_원금'!$E$6:$E$92,'09_CF_원금'!$D$6:$D$92,"미장",'09_CF_원금'!$A$6:$A$92,"<="&$A6)-SUMIFS('09_CF_원금'!$E$6:$E$92,'09_CF_원금'!$C$6:$C$92,"미장",'09_CF_원금'!$A$6:$A$92,"<="&$A6) | Z6: =SUMIFS('09_CF_원금'!$E$6:$E$92,'09_CF_원금'!$D$6:$D$92,"ISA",'09_CF_원금'!$A$6:$A$92,"<="&$A6)-SUMIFS('09_CF_원금'!$E$6:$E$92,'09_CF_원금'!$C$6:$C$92,"ISA",'09_CF_원금'!$A$6:$A$92,"<="&$A6) | AA6: =IF($A6="","",X6+Y6+Z6+SUMIFS('09_CF_원금'!$E$6:$E$92,'09_CF_원금'!$D$6:$D$92,"중국",'09_CF_원금'!$A$6:$A$92,"<="&$A6)-SUMIFS('09_CF_원금'!$E$6:$E$92,'09_CF_원금'!$C$6:$C$92,"중국",'09_CF_원금'!$A$6:$A$92,"<="&$A6)+SUMIFS('09_CF_원금'!$E$6:$E$92,'09_CF_원금'!$D$6:$D$92,"업비트",'09_CF_원금'!$A$6:$A$92,"<="&$A6)-SUMIFS('09_CF_원금'!$E$6:$E$92,'09_CF_원금'!$C$6:$C$92,"업비트",'09_CF_원금'!$A$6:$A$92,"<="&$A6)) | AB6: =IF(OR(U6="",V6=""),"",U6-(V6-IF(S6="",0,S6))) | AC6: =IF(AB6="","",T6+AB6) | AD6: =IF(B6="","",MAX($B$5:B6)) | AE6: 26004 | AG6: 57742218 | AH6: 33266033 | AJ6: =IF($A6="","",YEAR($A6)*100+MONTH($A6)) | AK6: =IF($A6="","",IF($N6="",0,1))
A7: 45968 | B7: =IF(V7<>"",V7-T7,IF(AF7<>"",AA7+AF7,"")) | C7: =IF(OR(B7="",B6=""),"",B7-B6) | D7: =IF(OR(B7="",AA7=""),"",B7-AA7) | E7: =IF(OR(B7="",AD7=0),"",MIN(0,B7/AD7-1)) | F7: =IF(OR(U7="",T7=0,T7=""),"",(P7-T7*1.4)/U7) | G7: =IF(OR(AC7="",'09_CF_원금'!$B$108=0),"",AC7/'09_CF_원금'!$B$108) | H7: =IF(OR(U7="",U7=0,AC7=""),"",AC7/U7) | I7: =IF(OR(S7="",U7=""),"",S7/(U7+S7)) | J7: =IF(W7<>"",W7-X7,IF(AG7<>"",AG7,"")) | K7: =IF(Q7<>"",Q7-Y7,IF(AH7<>"",AH7,"")) | L7: =IF(R7<>"",R7-Z7,IF(AI7<>"",AI7,"")) | Q7: =IF($A7="","",IF(Q6="","",Q6)) | R7: =IF($A7="","",IF(R6="","",R6)) | S7: =IF($A7="","",IF(S6="","",S6)) | T7: =IF(OR(P7="",W7=""),"",P7-W7) | U7: =IF($A7="","",IF(U6="","",U6)) | V7: =IF(P7="","",P7+IF(Q7="",0,Q7)+IF(R7="",0,R7)) | X7: =SUMIFS('09_CF_원금'!$E$6:$E$92,'09_CF_원금'!$D$6:$D$92,"국장",'09_CF_원금'!$A$6:$A$92,"<="&$A7)-SUMIFS('09_CF_원금'!$E$6:$E$92,'09_CF_원금'!$C$6:$C$92,"국장",'09_CF_원금'!$A$6:$A$92,"<="&$A7) | Y7: =SUMIFS('09_CF_원금'!$E$6:$E$92,'09_CF_원금'!$D$6:$D$92,"미장",'09_CF_원금'!$A$6:$A$92,"<="&$A7)-SUMIFS('09_CF_원금'!$E$6:$E$92,'09_CF_원금'!$C$6:$C$92,"미장",'09_CF_원금'!$A$6:$A$92,"<="&$A7) | Z7: =SUMIFS('09_CF_원금'!$E$6:$E$92,'09_CF_원금'!$D$6:$D$92,"ISA",'09_CF_원금'!$A$6:$A$92,"<="&$A7)-SUMIFS('09_CF_원금'!$E$6:$E$92,'09_CF_원금'!$C$6:$C$92,"ISA",'09_CF_원금'!$A$6:$A$92,"<="&$A7) | AA7: =IF($A7="","",X7+Y7+Z7+SUMIFS('09_CF_원금'!$E$6:$E$92,'09_CF_원금'!$D$6:$D$92,"중국",'09_CF_원금'!$A$6:$A$92,"<="&$A7)-SUMIFS('09_CF_원금'!$E$6:$E$92,'09_CF_원금'!$C$6:$C$92,"중국",'09_CF_원금'!$A$6:$A$92,"<="&$A7)+SUMIFS('09_CF_원금'!$E$6:$E$92,'09_CF_원금'!$D$6:$D$92,"업비트",'09_CF_원금'!$A$6:$A$92,"<="&$A7)-SUMIFS('09_CF_원금'!$E$6:$E$92,'09_CF_원금'!$C$6:$C$92,"업비트",'09_CF_원금'!$A$6:$A$92,"<="&$A7)) | AB7: =IF(OR(U7="",V7=""),"",U7-(V7-IF(S7="",0,S7))) | AC7: =IF(AB7="","",T7+AB7) | AD7: =IF(B7="","",MAX($B$5:B7)) | AE7: 25166.25 | AG7: 61665070 | AH7: 22042149 | AJ7: =IF($A7="","",YEAR($A7)*100+MONTH($A7)) | AK7: =IF($A7="","",IF($N7="",0,1))
A8: 45975 | B8: =IF(V8<>"",V8-T8,IF(AF8<>"",AA8+AF8,"")) | C8: =IF(OR(B8="",B7=""),"",B8-B7) | D8: =IF(OR(B8="",AA8=""),"",B8-AA8) | E8: =IF(OR(B8="",AD8=0),"",MIN(0,B8/AD8-1)) | F8: =IF(OR(U8="",T8=0,T8=""),"",(P8-T8*1.4)/U8) | G8: =IF(OR(AC8="",'09_CF_원금'!$B$108=0),"",AC8/'09_CF_원금'!$B$108) | H8: =IF(OR(U8="",U8=0,AC8=""),"",AC8/U8) | I8: =IF(OR(S8="",U8=""),"",S8/(U8+S8)) | J8: =IF(W8<>"",W8-X8,IF(AG8<>"",AG8,"")) | K8: =IF(Q8<>"",Q8-Y8,IF(AH8<>"",AH8,"")) | L8: =IF(R8<>"",R8-Z8,IF(AI8<>"",AI8,"")) | O8: 국장 조정세, 미국 AI 반등 기대 | Q8: =IF($A8="","",IF(Q7="","",Q7)) | R8: =IF($A8="","",IF(R7="","",R7)) | S8: =IF($A8="","",IF(S7="","",S7)) | T8: =IF(OR(P8="",W8=""),"",P8-W8) | U8: =IF($A8="","",IF(U7="","",U7)) | V8: =IF(P8="","",P8+IF(Q8="",0,Q8)+IF(R8="",0,R8)) | X8: =SUMIFS('09_CF_원금'!$E$6:$E$92,'09_CF_원금'!$D$6:$D$92,"국장",'09_CF_원금'!$A$6:$A$92,"<="&$A8)-SUMIFS('09_CF_원금'!$E$6:$E$92,'09_CF_원금'!$C$6:$C$92,"국장",'09_CF_원금'!$A$6:$A$92,"<="&$A8) | Y8: =SUMIFS('09_CF_원금'!$E$6:$E$92,'09_CF_원금'!$D$6:$D$92,"미장",'09_CF_원금'!$A$6:$A$92,"<="&$A8)-SUMIFS('09_CF_원금'!$E$6:$E$92,'09_CF_원금'!$C$6:$C$92,"미장",'09_CF_원금'!$A$6:$A$92,"<="&$A8) | Z8: =SUMIFS('09_CF_원금'!$E$6:$E$92,'09_CF_원금'!$D$6:$D$92,"ISA",'09_CF_원금'!$A$6:$A$92,"<="&$A8)-SUMIFS('09_CF_원금'!$E$6:$E$92,'09_CF_원금'!$C$6:$C$92,"ISA",'09_CF_원금'!$A$6:$A$92,"<="&$A8) | AA8: =IF($A8="","",X8+Y8+Z8+SUMIFS('09_CF_원금'!$E$6:$E$92,'09_CF_원금'!$D$6:$D$92,"중국",'09_CF_원금'!$A$6:$A$92,"<="&$A8)-SUMIFS('09_CF_원금'!$E$6:$E$92,'09_CF_원금'!$C$6:$C$92,"중국",'09_CF_원금'!$A$6:$A$92,"<="&$A8)+SUMIFS('09_CF_원금'!$E$6:$E$92,'09_CF_원금'!$D$6:$D$92,"업비트",'09_CF_원금'!$A$6:$A$92,"<="&$A8)-SUMIFS('09_CF_원금'!$E$6:$E$92,'09_CF_원금'!$C$6:$C$92,"업비트",'09_CF_원금'!$A$6:$A$92,"<="&$A8)) | AB8: =IF(OR(U8="",V8=""),"",U8-(V8-IF(S8="",0,S8))) | AC8: =IF(AB8="","",T8+AB8) | AD8: =IF(B8="","",MAX($B$5:B8)) | AE8: 25094 | AG8: 115959119 | AH8: 20504921 | AJ8: =IF($A8="","",YEAR($A8)*100+MONTH($A8)) | AK8: =IF($A8="","",IF($N8="",0,1))
A9: 45982 | B9: =IF(V9<>"",V9-T9,IF(AF9<>"",AA9+AF9,"")) | C9: =IF(OR(B9="",B8=""),"",B9-B8) | D9: =IF(OR(B9="",AA9=""),"",B9-AA9) | E9: =IF(OR(B9="",AD9=0),"",MIN(0,B9/AD9-1)) | F9: =IF(OR(U9="",T9=0,T9=""),"",(P9-T9*1.4)/U9) | G9: =IF(OR(AC9="",'09_CF_원금'!$B$108=0),"",AC9/'09_CF_원금'!$B$108) | H9: =IF(OR(U9="",U9=0,AC9=""),"",AC9/U9) | I9: =IF(OR(S9="",U9=""),"",S9/(U9+S9)) | J9: =IF(W9<>"",W9-X9,IF(AG9<>"",AG9,"")) | K9: =IF(Q9<>"",Q9-Y9,IF(AH9<>"",AH9,"")) | L9: =IF(R9<>"",R9-Z9,IF(AI9<>"",AI9,"")) | O9: 폭락장 속 포트 파괴 & 패닉바잉 (하이닉스) | Q9: =IF($A9="","",IF(Q8="","",Q8)) | R9: =IF($A9="","",IF(R8="","",R8)) | S9: =IF($A9="","",IF(S8="","",S8)) | T9: =IF(OR(P9="",W9=""),"",P9-W9) | U9: =IF($A9="","",IF(U8="","",U8)) | V9: =IF(P9="","",P9+IF(Q9="",0,Q9)+IF(R9="",0,R9)) | X9: =SUMIFS('09_CF_원금'!$E$6:$E$92,'09_CF_원금'!$D$6:$D$92,"국장",'09_CF_원금'!$A$6:$A$92,"<="&$A9)-SUMIFS('09_CF_원금'!$E$6:$E$92,'09_CF_원금'!$C$6:$C$92,"국장",'09_CF_원금'!$A$6:$A$92,"<="&$A9) | Y9: =SUMIFS('09_CF_원금'!$E$6:$E$92,'09_CF_원금'!$D$6:$D$92,"미장",'09_CF_원금'!$A$6:$A$92,"<="&$A9)-SUMIFS('09_CF_원금'!$E$6:$E$92,'09_CF_원금'!$C$6:$C$92,"미장",'09_CF_원금'!$A$6:$A$92,"<="&$A9) | Z9: =SUMIFS('09_CF_원금'!$E$6:$E$92,'09_CF_원금'!$D$6:$D$92,"ISA",'09_CF_원금'!$A$6:$A$92,"<="&$A9)-SUMIFS('09_CF_원금'!$E$6:$E$92,'09_CF_원금'!$C$6:$C$92,"ISA",'09_CF_원금'!$A$6:$A$92,"<="&$A9) | AA9: =IF($A9="","",X9+Y9+Z9+SUMIFS('09_CF_원금'!$E$6:$E$92,'09_CF_원금'!$D$6:$D$92,"중국",'09_CF_원금'!$A$6:$A$92,"<="&$A9)-SUMIFS('09_CF_원금'!$E$6:$E$92,'09_CF_원금'!$C$6:$C$92,"중국",'09_CF_원금'!$A$6:$A$92,"<="&$A9)+SUMIFS('09_CF_원금'!$E$6:$E$92,'09_CF_원금'!$D$6:$D$92,"업비트",'09_CF_원금'!$A$6:$A$92,"<="&$A9)-SUMIFS('09_CF_원금'!$E$6:$E$92,'09_CF_원금'!$C$6:$C$92,"업비트",'09_CF_원금'!$A$6:$A$92,"<="&$A9)) | AB9: =IF(OR(U9="",V9=""),"",U9-(V9-IF(S9="",0,S9))) | AC9: =IF(AB9="","",T9+AB9) | AD9: =IF(B9="","",MAX($B$5:B9)) | AE9: 24131 | AG9: 106186052 | AH9: 8500000 | AJ9: =IF($A9="","",YEAR($A9)*100+MONTH($A9)) | AK9: =IF($A9="","",IF($N9="",0,1))
A10: 45986 | B10: =IF(V10<>"",V10-T10,IF(AF10<>"",AA10+AF10,"")) | C10: =IF(OR(B10="",B9=""),"",B10-B9) | D10: =IF(OR(B10="",AA10=""),"",B10-AA10) | E10: =IF(OR(B10="",AD10=0),"",MIN(0,B10/AD10-1)) | F10: =IF(OR(U10="",T10=0,T10=""),"",(P10-T10*1.4)/U10) | G10: =IF(OR(AC10="",'09_CF_원금'!$B$108=0),"",AC10/'09_CF_원금'!$B$108) | H10: =IF(OR(U10="",U10=0,AC10=""),"",AC10/U10) | I10: =IF(OR(S10="",U10=""),"",S10/(U10+S10)) | J10: =IF(W10<>"",W10-X10,IF(AG10<>"",AG10,"")) | K10: =IF(Q10<>"",Q10-Y10,IF(AH10<>"",AH10,"")) | L10: =IF(R10<>"",R10-Z10,IF(AI10<>"",AI10,"")) | O10: 반등세 속 무지성 포모 바잉 | Q10: =IF($A10="","",IF(Q9="","",Q9)) | R10: =IF($A10="","",IF(R9="","",R9)) | S10: =IF($A10="","",IF(S9="","",S9)) | T10: =IF(OR(P10="",W10=""),"",P10-W10) | U10: =IF($A10="","",IF(U9="","",U9)) | V10: =IF(P10="","",P10+IF(Q10="",0,Q10)+IF(R10="",0,R10)) | X10: =SUMIFS('09_CF_원금'!$E$6:$E$92,'09_CF_원금'!$D$6:$D$92,"국장",'09_CF_원금'!$A$6:$A$92,"<="&$A10)-SUMIFS('09_CF_원금'!$E$6:$E$92,'09_CF_원금'!$C$6:$C$92,"국장",'09_CF_원금'!$A$6:$A$92,"<="&$A10) | Y10: =SUMIFS('09_CF_원금'!$E$6:$E$92,'09_CF_원금'!$D$6:$D$92,"미장",'09_CF_원금'!$A$6:$A$92,"<="&$A10)-SUMIFS('09_CF_원금'!$E$6:$E$92,'09_CF_원금'!$C$6:$C$92,"미장",'09_CF_원금'!$A$6:$A$92,"<="&$A10) | Z10: =SUMIFS('09_CF_원금'!$E$6:$E$92,'09_CF_원금'!$D$6:$D$92,"ISA",'09_CF_원금'!$A$6:$A$92,"<="&$A10)-SUMIFS('09_CF_원금'!$E$6:$E$92,'09_CF_원금'!$C$6:$C$92,"ISA",'09_CF_원금'!$A$6:$A$92,"<="&$A10) | AA10: =IF($A10="","",X10+Y10+Z10+SUMIFS('09_CF_원금'!$E$6:$E$92,'09_CF_원금'!$D$6:$D$92,"중국",'09_CF_원금'!$A$6:$A$92,"<="&$A10)-SUMIFS('09_CF_원금'!$E$6:$E$92,'09_CF_원금'!$C$6:$C$92,"중국",'09_CF_원금'!$A$6:$A$92,"<="&$A10)+SUMIFS('09_CF_원금'!$E$6:$E$92,'09_CF_원금'!$D$6:$D$92,"업비트",'09_CF_원금'!$A$6:$A$92,"<="&$A10)-SUMIFS('09_CF_원금'!$E$6:$E$92,'09_CF_원금'!$C$6:$C$92,"업비트",'09_CF_원금'!$A$6:$A$92,"<="&$A10)) | AB10: =IF(OR(U10="",V10=""),"",U10-(V10-IF(S10="",0,S10))) | AC10: =IF(AB10="","",T10+AB10) | AD10: =IF(B10="","",MAX($B$5:B10)) | AE10: 25085.5 | AG10: 99571864 | AH10: 17917003 | AJ10: =IF($A10="","",YEAR($A10)*100+MONTH($A10)) | AK10: =IF($A10="","",IF($N10="",0,1))
A11: 45996 | B11: =IF(V11<>"",V11-T11,IF(AF11<>"",AA11+AF11,"")) | C11: =IF(OR(B11="",B10=""),"",B11-B10) | D11: =IF(OR(B11="",AA11=""),"",B11-AA11) | E11: =IF(OR(B11="",AD11=0),"",MIN(0,B11/AD11-1)) | F11: =IF(OR(U11="",T11=0,T11=""),"",(P11-T11*1.4)/U11) | G11: =IF(OR(AC11="",'09_CF_원금'!$B$108=0),"",AC11/'09_CF_원금'!$B$108) | H11: =IF(OR(U11="",U11=0,AC11=""),"",AC11/U11) | I11: =IF(OR(S11="",U11=""),"",S11/(U11+S11)) | J11: =IF(W11<>"",W11-X11,IF(AG11<>"",AG11,"")) | K11: =IF(Q11<>"",Q11-Y11,IF(AH11<>"",AH11,"")) | L11: =IF(R11<>"",R11-Z11,IF(AI11<>"",AI11,"")) | O11: 과잉확신 속 신용투자 & 패닉바잉 물타기 (알테오젠) | Q11: =IF($A11="","",IF(Q10="","",Q10)) | R11: =IF($A11="","",IF(R10="","",R10)) | S11: =IF($A11="","",IF(S10="","",S10)) | T11: =IF(OR(P11="",W11=""),"",P11-W11) | U11: =IF($A11="","",IF(U10="","",U10)) | V11: =IF(P11="","",P11+IF(Q11="",0,Q11)+IF(R11="",0,R11)) | X11: =SUMIFS('09_CF_원금'!$E$6:$E$92,'09_CF_원금'!$D$6:$D$92,"국장",'09_CF_원금'!$A$6:$A$92,"<="&$A11)-SUMIFS('09_CF_원금'!$E$6:$E$92,'09_CF_원금'!$C$6:$C$92,"국장",'09_CF_원금'!$A$6:$A$92,"<="&$A11) | Y11: =SUMIFS('09_CF_원금'!$E$6:$E$92,'09_CF_원금'!$D$6:$D$92,"미장",'09_CF_원금'!$A$6:$A$92,"<="&$A11)-SUMIFS('09_CF_원금'!$E$6:$E$92,'09_CF_원금'!$C$6:$C$92,"미장",'09_CF_원금'!$A$6:$A$92,"<="&$A11) | Z11: =SUMIFS('09_CF_원금'!$E$6:$E$92,'09_CF_원금'!$D$6:$D$92,"ISA",'09_CF_원금'!$A$6:$A$92,"<="&$A11)-SUMIFS('09_CF_원금'!$E$6:$E$92,'09_CF_원금'!$C$6:$C$92,"ISA",'09_CF_원금'!$A$6:$A$92,"<="&$A11) | AA11: =IF($A11="","",X11+Y11+Z11+SUMIFS('09_CF_원금'!$E$6:$E$92,'09_CF_원금'!$D$6:$D$92,"중국",'09_CF_원금'!$A$6:$A$92,"<="&$A11)-SUMIFS('09_CF_원금'!$E$6:$E$92,'09_CF_원금'!$C$6:$C$92,"중국",'09_CF_원금'!$A$6:$A$92,"<="&$A11)+SUMIFS('09_CF_원금'!$E$6:$E$92,'09_CF_원금'!$D$6:$D$92,"업비트",'09_CF_원금'!$A$6:$A$92,"<="&$A11)-SUMIFS('09_CF_원금'!$E$6:$E$92,'09_CF_원금'!$C$6:$C$92,"업비트",'09_CF_원금'!$A$6:$A$92,"<="&$A11)) | AB11: =IF(OR(U11="",V11=""),"",U11-(V11-IF(S11="",0,S11))) | AC11: =IF(AB11="","",T11+AB11) | AD11: =IF(B11="","",MAX($B$5:B11)) | AE11: 25732 | AG11: 100497353 | AH11: 24928701 | AJ11: =IF($A11="","",YEAR($A11)*100+MONTH($A11)) | AK11: =IF($A11="","",IF($N11="",0,1))
A12: 45999 | B12: =IF(V12<>"",V12-T12,IF(AF12<>"",AA12+AF12,"")) | C12: =IF(OR(B12="",B11=""),"",B12-B11) | D12: =IF(OR(B12="",AA12=""),"",B12-AA12) | E12: =IF(OR(B12="",AD12=0),"",MIN(0,B12/AD12-1)) | F12: =IF(OR(U12="",T12=0,T12=""),"",(P12-T12*1.4)/U12) | G12: =IF(OR(AC12="",'09_CF_원금'!$B$108=0),"",AC12/'09_CF_원금'!$B$108) | H12: =IF(OR(U12="",U12=0,AC12=""),"",AC12/U12) | I12: =IF(OR(S12="",U12=""),"",S12/(U12+S12)) | J12: =IF(W12<>"",W12-X12,IF(AG12<>"",AG12,"")) | K12: =IF(Q12<>"",Q12-Y12,IF(AH12<>"",AH12,"")) | L12: =IF(R12<>"",R12-Z12,IF(AI12<>"",AI12,"")) | Q12: =IF($A12="","",IF(Q11="","",Q11)) | R12: =IF($A12="","",IF(R11="","",R11)) | S12: =IF($A12="","",IF(S11="","",S11)) | T12: =IF(OR(P12="",W12=""),"",P12-W12) | U12: =IF($A12="","",IF(U11="","",U11)) | V12: =IF(P12="","",P12+IF(Q12="",0,Q12)+IF(R12="",0,R12)) | X12: =SUMIFS('09_CF_원금'!$E$6:$E$92,'09_CF_원금'!$D$6:$D$92,"국장",'09_CF_원금'!$A$6:$A$92,"<="&$A12)-SUMIFS('09_CF_원금'!$E$6:$E$92,'09_CF_원금'!$C$6:$C$92,"국장",'09_CF_원금'!$A$6:$A$92,"<="&$A12) | Y12: =SUMIFS('09_CF_원금'!$E$6:$E$92,'09_CF_원금'!$D$6:$D$92,"미장",'09_CF_원금'!$A$6:$A$92,"<="&$A12)-SUMIFS('09_CF_원금'!$E$6:$E$92,'09_CF_원금'!$C$6:$C$92,"미장",'09_CF_원금'!$A$6:$A$92,"<="&$A12) | Z12: =SUMIFS('09_CF_원금'!$E$6:$E$92,'09_CF_원금'!$D$6:$D$92,"ISA",'09_CF_원금'!$A$6:$A$92,"<="&$A12)-SUMIFS('09_CF_원금'!$E$6:$E$92,'09_CF_원금'!$C$6:$C$92,"ISA",'09_CF_원금'!$A$6:$A$92,"<="&$A12) | AA12: =IF($A12="","",X12+Y12+Z12+SUMIFS('09_CF_원금'!$E$6:$E$92,'09_CF_원금'!$D$6:$D$92,"중국",'09_CF_원금'!$A$6:$A$92,"<="&$A12)-SUMIFS('09_CF_원금'!$E$6:$E$92,'09_CF_원금'!$C$6:$C$92,"중국",'09_CF_원금'!$A$6:$A$92,"<="&$A12)+SUMIFS('09_CF_원금'!$E$6:$E$92,'09_CF_원금'!$D$6:$D$92,"업비트",'09_CF_원금'!$A$6:$A$92,"<="&$A12)-SUMIFS('09_CF_원금'!$E$6:$E$92,'09_CF_원금'!$C$6:$C$92,"업비트",'09_CF_원금'!$A$6:$A$92,"<="&$A12)) | AB12: =IF(OR(U12="",V12=""),"",U12-(V12-IF(S12="",0,S12))) | AC12: =IF(AB12="","",T12+AB12) | AD12: =IF(B12="","",MAX($B$5:B12)) | AE12: 25723 | AG12: 101730146 | AH12: 26543123 | AJ12: =IF($A12="","",YEAR($A12)*100+MONTH($A12)) | AK12: =IF($A12="","",IF($N12="",0,1))
A13: 46010 | B13: =IF(V13<>"",V13-T13,IF(AF13<>"",AA13+AF13,"")) | C13: =IF(OR(B13="",B12=""),"",B13-B12) | D13: =IF(OR(B13="",AA13=""),"",B13-AA13) | E13: =IF(OR(B13="",AD13=0),"",MIN(0,B13/AD13-1)) | F13: =IF(OR(U13="",T13=0,T13=""),"",(P13-T13*1.4)/U13) | G13: =IF(OR(AC13="",'09_CF_원금'!$B$108=0),"",AC13/'09_CF_원금'!$B$108) | H13: =IF(OR(U13="",U13=0,AC13=""),"",AC13/U13) | I13: =IF(OR(S13="",U13=""),"",S13/(U13+S13)) | J13: =IF(W13<>"",W13-X13,IF(AG13<>"",AG13,"")) | K13: =IF(Q13<>"",Q13-Y13,IF(AH13<>"",AH13,"")) | L13: =IF(R13<>"",R13-Z13,IF(AI13<>"",AI13,"")) | O13: 무리한 현금소진/레버리지로 계좌 악화 | Q13: =IF($A13="","",IF(Q12="","",Q12)) | R13: =IF($A13="","",IF(R12="","",R12)) | S13: =IF($A13="","",IF(S12="","",S12)) | T13: =IF(OR(P13="",W13=""),"",P13-W13) | U13: =IF($A13="","",IF(U12="","",U12)) | V13: =IF(P13="","",P13+IF(Q13="",0,Q13)+IF(R13="",0,R13)) | X13: =SUMIFS('09_CF_원금'!$E$6:$E$92,'09_CF_원금'!$D$6:$D$92,"국장",'09_CF_원금'!$A$6:$A$92,"<="&$A13)-SUMIFS('09_CF_원금'!$E$6:$E$92,'09_CF_원금'!$C$6:$C$92,"국장",'09_CF_원금'!$A$6:$A$92,"<="&$A13) | Y13: =SUMIFS('09_CF_원금'!$E$6:$E$92,'09_CF_원금'!$D$6:$D$92,"미장",'09_CF_원금'!$A$6:$A$92,"<="&$A13)-SUMIFS('09_CF_원금'!$E$6:$E$92,'09_CF_원금'!$C$6:$C$92,"미장",'09_CF_원금'!$A$6:$A$92,"<="&$A13) | Z13: =SUMIFS('09_CF_원금'!$E$6:$E$92,'09_CF_원금'!$D$6:$D$92,"ISA",'09_CF_원금'!$A$6:$A$92,"<="&$A13)-SUMIFS('09_CF_원금'!$E$6:$E$92,'09_CF_원금'!$C$6:$C$92,"ISA",'09_CF_원금'!$A$6:$A$92,"<="&$A13) | AA13: =IF($A13="","",X13+Y13+Z13+SUMIFS('09_CF_원금'!$E$6:$E$92,'09_CF_원금'!$D$6:$D$92,"중국",'09_CF_원금'!$A$6:$A$92,"<="&$A13)-SUMIFS('09_CF_원금'!$E$6:$E$92,'09_CF_원금'!$C$6:$C$92,"중국",'09_CF_원금'!$A$6:$A$92,"<="&$A13)+SUMIFS('09_CF_원금'!$E$6:$E$92,'09_CF_원금'!$D$6:$D$92,"업비트",'09_CF_원금'!$A$6:$A$92,"<="&$A13)-SUMIFS('09_CF_원금'!$E$6:$E$92,'09_CF_원금'!$C$6:$C$92,"업비트",'09_CF_원금'!$A$6:$A$92,"<="&$A13)) | AB13: =IF(OR(U13="",V13=""),"",U13-(V13-IF(S13="",0,S13))) | AC13: =IF(AB13="","",T13+AB13) | AD13: =IF(B13="","",MAX($B$5:B13)) | AE13: 25574.75 | AG13: 100089765 | AH13: 23580388 | AJ13: =IF($A13="","",YEAR($A13)*100+MONTH($A13)) | AK13: =IF($A13="","",IF($N13="",0,1))
A14: 46017 | B14: =IF(V14<>"",V14-T14,IF(AF14<>"",AA14+AF14,"")) | C14: =IF(OR(B14="",B13=""),"",B14-B13) | D14: =IF(OR(B14="",AA14=""),"",B14-AA14) | E14: =IF(OR(B14="",AD14=0),"",MIN(0,B14/AD14-1)) | F14: =IF(OR(U14="",T14=0,T14=""),"",(P14-T14*1.4)/U14) | G14: =IF(OR(AC14="",'09_CF_원금'!$B$108=0),"",AC14/'09_CF_원금'!$B$108) | H14: =IF(OR(U14="",U14=0,AC14=""),"",AC14/U14) | I14: =IF(OR(S14="",U14=""),"",S14/(U14+S14)) | J14: =IF(W14<>"",W14-X14,IF(AG14<>"",AG14,"")) | K14: =IF(Q14<>"",Q14-Y14,IF(AH14<>"",AH14,"")) | L14: =IF(R14<>"",R14-Z14,IF(AI14<>"",AI14,"")) | Q14: =IF($A14="","",IF(Q13="","",Q13)) | R14: =IF($A14="","",IF(R13="","",R13)) | S14: =IF($A14="","",IF(S13="","",S13)) | T14: =IF(OR(P14="",W14=""),"",P14-W14) | U14: =IF($A14="","",IF(U13="","",U13)) | V14: =IF(P14="","",P14+IF(Q14="",0,Q14)+IF(R14="",0,R14)) | X14: =SUMIFS('09_CF_원금'!$E$6:$E$92,'09_CF_원금'!$D$6:$D$92,"국장",'09_CF_원금'!$A$6:$A$92,"<="&$A14)-SUMIFS('09_CF_원금'!$E$6:$E$92,'09_CF_원금'!$C$6:$C$92,"국장",'09_CF_원금'!$A$6:$A$92,"<="&$A14) | Y14: =SUMIFS('09_CF_원금'!$E$6:$E$92,'09_CF_원금'!$D$6:$D$92,"미장",'09_CF_원금'!$A$6:$A$92,"<="&$A14)-SUMIFS('09_CF_원금'!$E$6:$E$92,'09_CF_원금'!$C$6:$C$92,"미장",'09_CF_원금'!$A$6:$A$92,"<="&$A14) | Z14: =SUMIFS('09_CF_원금'!$E$6:$E$92,'09_CF_원금'!$D$6:$D$92,"ISA",'09_CF_원금'!$A$6:$A$92,"<="&$A14)-SUMIFS('09_CF_원금'!$E$6:$E$92,'09_CF_원금'!$C$6:$C$92,"ISA",'09_CF_원금'!$A$6:$A$92,"<="&$A14) | AA14: =IF($A14="","",X14+Y14+Z14+SUMIFS('09_CF_원금'!$E$6:$E$92,'09_CF_원금'!$D$6:$D$92,"중국",'09_CF_원금'!$A$6:$A$92,"<="&$A14)-SUMIFS('09_CF_원금'!$E$6:$E$92,'09_CF_원금'!$C$6:$C$92,"중국",'09_CF_원금'!$A$6:$A$92,"<="&$A14)+SUMIFS('09_CF_원금'!$E$6:$E$92,'09_CF_원금'!$D$6:$D$92,"업비트",'09_CF_원금'!$A$6:$A$92,"<="&$A14)-SUMIFS('09_CF_원금'!$E$6:$E$92,'09_CF_원금'!$C$6:$C$92,"업비트",'09_CF_원금'!$A$6:$A$92,"<="&$A14)) | AB14: =IF(OR(U14="",V14=""),"",U14-(V14-IF(S14="",0,S14))) | AC14: =IF(AB14="","",T14+AB14) | AD14: =IF(B14="","",MAX($B$5:B14)) | AE14: 25863 | AG14: 104193269 | AH14: 31850948 | AJ14: =IF($A14="","",YEAR($A14)*100+MONTH($A14)) | AK14: =IF($A14="","",IF($N14="",0,1))
A15: 46022 | B15: =IF(V15<>"",V15-T15,IF(AF15<>"",AA15+AF15,"")) | C15: =IF(OR(B15="",B14=""),"",B15-B14) | D15: =IF(OR(B15="",AA15=""),"",B15-AA15) | E15: =IF(OR(B15="",AD15=0),"",MIN(0,B15/AD15-1)) | F15: =IF(OR(U15="",T15=0,T15=""),"",(P15-T15*1.4)/U15) | G15: =IF(OR(AC15="",'09_CF_원금'!$B$108=0),"",AC15/'09_CF_원금'!$B$108) | H15: =IF(OR(U15="",U15=0,AC15=""),"",AC15/U15) | I15: =IF(OR(S15="",U15=""),"",S15/(U15+S15)) | J15: =IF(W15<>"",W15-X15,IF(AG15<>"",AG15,"")) | K15: =IF(Q15<>"",Q15-Y15,IF(AH15<>"",AH15,"")) | L15: =IF(R15<>"",R15-Z15,IF(AI15<>"",AI15,"")) | O15: '25년 마감 | Q15: =IF($A15="","",IF(Q14="","",Q14)) | R15: =IF($A15="","",IF(R14="","",R14)) | S15: =IF($A15="","",IF(S14="","",S14)) | T15: =IF(OR(P15="",W15=""),"",P15-W15) | U15: =IF($A15="","",IF(U14="","",U14)) | V15: =IF(P15="","",P15+IF(Q15="",0,Q15)+IF(R15="",0,R15)) | X15: =SUMIFS('09_CF_원금'!$E$6:$E$92,'09_CF_원금'!$D$6:$D$92,"국장",'09_CF_원금'!$A$6:$A$92,"<="&$A15)-SUMIFS('09_CF_원금'!$E$6:$E$92,'09_CF_원금'!$C$6:$C$92,"국장",'09_CF_원금'!$A$6:$A$92,"<="&$A15) | Y15: =SUMIFS('09_CF_원금'!$E$6:$E$92,'09_CF_원금'!$D$6:$D$92,"미장",'09_CF_원금'!$A$6:$A$92,"<="&$A15)-SUMIFS('09_CF_원금'!$E$6:$E$92,'09_CF_원금'!$C$6:$C$92,"미장",'09_CF_원금'!$A$6:$A$92,"<="&$A15) | Z15: =SUMIFS('09_CF_원금'!$E$6:$E$92,'09_CF_원금'!$D$6:$D$92,"ISA",'09_CF_원금'!$A$6:$A$92,"<="&$A15)-SUMIFS('09_CF_원금'!$E$6:$E$92,'09_CF_원금'!$C$6:$C$92,"ISA",'09_CF_원금'!$A$6:$A$92,"<="&$A15) | AA15: =IF($A15="","",X15+Y15+Z15+SUMIFS('09_CF_원금'!$E$6:$E$92,'09_CF_원금'!$D$6:$D$92,"중국",'09_CF_원금'!$A$6:$A$92,"<="&$A15)-SUMIFS('09_CF_원금'!$E$6:$E$92,'09_CF_원금'!$C$6:$C$92,"중국",'09_CF_원금'!$A$6:$A$92,"<="&$A15)+SUMIFS('09_CF_원금'!$E$6:$E$92,'09_CF_원금'!$D$6:$D$92,"업비트",'09_CF_원금'!$A$6:$A$92,"<="&$A15)-SUMIFS('09_CF_원금'!$E$6:$E$92,'09_CF_원금'!$C$6:$C$92,"업비트",'09_CF_원금'!$A$6:$A$92,"<="&$A15)) | AB15: =IF(OR(U15="",V15=""),"",U15-(V15-IF(S15="",0,S15))) | AC15: =IF(AB15="","",T15+AB15) | AD15: =IF(B15="","",MAX($B$5:B15)) | AE15: 25456.75 | AF15: 142830222 | AG15: 110805230 | AH15: 27430808 | AI15: 4594184 | AJ15: =IF($A15="","",YEAR($A15)*100+MONTH($A15)) | AK15: =IF($A15="","",IF($N15="",0,1))
A16: 46023 | B16: =IF(V16<>"",V16-T16,IF(AF16<>"",AA16+AF16,"")) | C16: =IF(OR(B16="",B15=""),"",B16-B15) | D16: =IF(OR(B16="",AA16=""),"",B16-AA16) | E16: =IF(OR(B16="",AD16=0),"",MIN(0,B16/AD16-1)) | F16: =IF(OR(U16="",T16=0,T16=""),"",(P16-T16*1.4)/U16) | G16: =IF(OR(AC16="",'09_CF_원금'!$B$108=0),"",AC16/'09_CF_원금'!$B$108) | H16: =IF(OR(U16="",U16=0,AC16=""),"",AC16/U16) | I16: =IF(OR(S16="",U16=""),"",S16/(U16+S16)) | J16: =IF(W16<>"",W16-X16,IF(AG16<>"",AG16,"")) | K16: =IF(Q16<>"",Q16-Y16,IF(AH16<>"",AH16,"")) | L16: =IF(R16<>"",R16-Z16,IF(AI16<>"",AI16,"")) | Q16: =IF($A16="","",IF(Q15="","",Q15)) | R16: =IF($A16="","",IF(R15="","",R15)) | S16: =IF($A16="","",IF(S15="","",S15)) | T16: =IF(OR(P16="",W16=""),"",P16-W16) | U16: =IF($A16="","",IF(U15="","",U15)) | V16: =IF(P16="","",P16+IF(Q16="",0,Q16)+IF(R16="",0,R16)) | X16: =SUMIFS('09_CF_원금'!$E$6:$E$92,'09_CF_원금'!$D$6:$D$92,"국장",'09_CF_원금'!$A$6:$A$92,"<="&$A16)-SUMIFS('09_CF_원금'!$E$6:$E$92,'09_CF_원금'!$C$6:$C$92,"국장",'09_CF_원금'!$A$6:$A$92,"<="&$A16) | Y16: =SUMIFS('09_CF_원금'!$E$6:$E$92,'09_CF_원금'!$D$6:$D$92,"미장",'09_CF_원금'!$A$6:$A$92,"<="&$A16)-SUMIFS('09_CF_원금'!$E$6:$E$92,'09_CF_원금'!$C$6:$C$92,"미장",'09_CF_원금'!$A$6:$A$92,"<="&$A16) | Z16: =SUMIFS('09_CF_원금'!$E$6:$E$92,'09_CF_원금'!$D$6:$D$92,"ISA",'09_CF_원금'!$A$6:$A$92,"<="&$A16)-SUMIFS('09_CF_원금'!$E$6:$E$92,'09_CF_원금'!$C$6:$C$92,"ISA",'09_CF_원금'!$A$6:$A$92,"<="&$A16) | AA16: =IF($A16="","",X16+Y16+Z16+SUMIFS('09_CF_원금'!$E$6:$E$92,'09_CF_원금'!$D$6:$D$92,"중국",'09_CF_원금'!$A$6:$A$92,"<="&$A16)-SUMIFS('09_CF_원금'!$E$6:$E$92,'09_CF_원금'!$C$6:$C$92,"중국",'09_CF_원금'!$A$6:$A$92,"<="&$A16)+SUMIFS('09_CF_원금'!$E$6:$E$92,'09_CF_원금'!$D$6:$D$92,"업비트",'09_CF_원금'!$A$6:$A$92,"<="&$A16)-SUMIFS('09_CF_원금'!$E$6:$E$92,'09_CF_원금'!$C$6:$C$92,"업비트",'09_CF_원금'!$A$6:$A$92,"<="&$A16)) | AB16: =IF(OR(U16="",V16=""),"",U16-(V16-IF(S16="",0,S16))) | AC16: =IF(AB16="","",T16+AB16) | AD16: =IF(B16="","",MAX($B$5:B16)) | AJ16: =IF($A16="","",YEAR($A16)*100+MONTH($A16)) | AK16: =IF($A16="","",IF($N16="",0,1))
A17: 46024 | B17: =IF(V17<>"",V17-T17,IF(AF17<>"",AA17+AF17,"")) | C17: =IF(OR(B17="",B16=""),"",B17-B16) | D17: =IF(OR(B17="",AA17=""),"",B17-AA17) | E17: =IF(OR(B17="",AD17=0),"",MIN(0,B17/AD17-1)) | F17: =IF(OR(U17="",T17=0,T17=""),"",(P17-T17*1.4)/U17) | G17: =IF(OR(AC17="",'09_CF_원금'!$B$108=0),"",AC17/'09_CF_원금'!$B$108) | H17: =IF(OR(U17="",U17=0,AC17=""),"",AC17/U17) | I17: =IF(OR(S17="",U17=""),"",S17/(U17+S17)) | J17: =IF(W17<>"",W17-X17,IF(AG17<>"",AG17,"")) | K17: =IF(Q17<>"",Q17-Y17,IF(AH17<>"",AH17,"")) | L17: =IF(R17<>"",R17-Z17,IF(AI17<>"",AI17,"")) | Q17: =IF($A17="","",IF(Q16="","",Q16)) | R17: =IF($A17="","",IF(R16="","",R16)) | S17: =IF($A17="","",IF(S16="","",S16)) | T17: =IF(OR(P17="",W17=""),"",P17-W17) | U17: =IF($A17="","",IF(U16="","",U16)) | V17: =IF(P17="","",P17+IF(Q17="",0,Q17)+IF(R17="",0,R17)) | X17: =SUMIFS('09_CF_원금'!$E$6:$E$92,'09_CF_원금'!$D$6:$D$92,"국장",'09_CF_원금'!$A$6:$A$92,"<="&$A17)-SUMIFS('09_CF_원금'!$E$6:$E$92,'09_CF_원금'!$C$6:$C$92,"국장",'09_CF_원금'!$A$6:$A$92,"<="&$A17) | Y17: =SUMIFS('09_CF_원금'!$E$6:$E$92,'09_CF_원금'!$D$6:$D$92,"미장",'09_CF_원금'!$A$6:$A$92,"<="&$A17)-SUMIFS('09_CF_원금'!$E$6:$E$92,'09_CF_원금'!$C$6:$C$92,"미장",'09_CF_원금'!$A$6:$A$92,"<="&$A17) | Z17: =SUMIFS('09_CF_원금'!$E$6:$E$92,'09_CF_원금'!$D$6:$D$92,"ISA",'09_CF_원금'!$A$6:$A$92,"<="&$A17)-SUMIFS('09_CF_원금'!$E$6:$E$92,'09_CF_원금'!$C$6:$C$92,"ISA",'09_CF_원금'!$A$6:$A$92,"<="&$A17) | AA17: =IF($A17="","",X17+Y17+Z17+SUMIFS('09_CF_원금'!$E$6:$E$92,'09_CF_원금'!$D$6:$D$92,"중국",'09_CF_원금'!$A$6:$A$92,"<="&$A17)-SUMIFS('09_CF_원금'!$E$6:$E$92,'09_CF_원금'!$C$6:$C$92,"중국",'09_CF_원금'!$A$6:$A$92,"<="&$A17)+SUMIFS('09_CF_원금'!$E$6:$E$92,'09_CF_원금'!$D$6:$D$92,"업비트",'09_CF_원금'!$A$6:$A$92,"<="&$A17)-SUMIFS('09_CF_원금'!$E$6:$E$92,'09_CF_원금'!$C$6:$C$92,"업비트",'09_CF_원금'!$A$6:$A$92,"<="&$A17)) | AB17: =IF(OR(U17="",V17=""),"",U17-(V17-IF(S17="",0,S17))) | AC17: =IF(AB17="","",T17+AB17) | AD17: =IF(B17="","",MAX($B$5:B17)) | AE17: 25385.25 | AF17: 151585850 | AG17: 113696755 | AH17: 31925364 | AI17: 5280829 | AJ17: =IF($A17="","",YEAR($A17)*100+MONTH($A17)) | AK17: =IF($A17="","",IF($N17="",0,1))
A18: 46027 | B18: =IF(V18<>"",V18-T18,IF(AF18<>"",AA18+AF18,"")) | C18: =IF(OR(B18="",B17=""),"",B18-B17) | D18: =IF(OR(B18="",AA18=""),"",B18-AA18) | E18: =IF(OR(B18="",AD18=0),"",MIN(0,B18/AD18-1)) | F18: =IF(OR(U18="",T18=0,T18=""),"",(P18-T18*1.4)/U18) | G18: =IF(OR(AC18="",'09_CF_원금'!$B$108=0),"",AC18/'09_CF_원금'!$B$108) | H18: =IF(OR(U18="",U18=0,AC18=""),"",AC18/U18) | I18: =IF(OR(S18="",U18=""),"",S18/(U18+S18)) | J18: =IF(W18<>"",W18-X18,IF(AG18<>"",AG18,"")) | K18: =IF(Q18<>"",Q18-Y18,IF(AH18<>"",AH18,"")) | L18: =IF(R18<>"",R18-Z18,IF(AI18<>"",AI18,"")) | Q18: =IF($A18="","",IF(Q17="","",Q17)) | R18: =IF($A18="","",IF(R17="","",R17)) | S18: =IF($A18="","",IF(S17="","",S17)) | T18: =IF(OR(P18="",W18=""),"",P18-W18) | U18: =IF($A18="","",IF(U17="","",U17)) | V18: =IF(P18="","",P18+IF(Q18="",0,Q18)+IF(R18="",0,R18)) | X18: =SUMIFS('09_CF_원금'!$E$6:$E$92,'09_CF_원금'!$D$6:$D$92,"국장",'09_CF_원금'!$A$6:$A$92,"<="&$A18)-SUMIFS('09_CF_원금'!$E$6:$E$92,'09_CF_원금'!$C$6:$C$92,"국장",'09_CF_원금'!$A$6:$A$92,"<="&$A18) | Y18: =SUMIFS('09_CF_원금'!$E$6:$E$92,'09_CF_원금'!$D$6:$D$92,"미장",'09_CF_원금'!$A$6:$A$92,"<="&$A18)-SUMIFS('09_CF_원금'!$E$6:$E$92,'09_CF_원금'!$C$6:$C$92,"미장",'09_CF_원금'!$A$6:$A$92,"<="&$A18) | Z18: =SUMIFS('09_CF_원금'!$E$6:$E$92,'09_CF_원금'!$D$6:$D$92,"ISA",'09_CF_원금'!$A$6:$A$92,"<="&$A18)-SUMIFS('09_CF_원금'!$E$6:$E$92,'09_CF_원금'!$C$6:$C$92,"ISA",'09_CF_원금'!$A$6:$A$92,"<="&$A18) | AA18: =IF($A18="","",X18+Y18+Z18+SUMIFS('09_CF_원금'!$E$6:$E$92,'09_CF_원금'!$D$6:$D$92,"중국",'09_CF_원금'!$A$6:$A$92,"<="&$A18)-SUMIFS('09_CF_원금'!$E$6:$E$92,'09_CF_원금'!$C$6:$C$92,"중국",'09_CF_원금'!$A$6:$A$92,"<="&$A18)+SUMIFS('09_CF_원금'!$E$6:$E$92,'09_CF_원금'!$D$6:$D$92,"업비트",'09_CF_원금'!$A$6:$A$92,"<="&$A18)-SUMIFS('09_CF_원금'!$E$6:$E$92,'09_CF_원금'!$C$6:$C$92,"업비트",'09_CF_원금'!$A$6:$A$92,"<="&$A18)) | AB18: =IF(OR(U18="",V18=""),"",U18-(V18-IF(S18="",0,S18))) | AC18: =IF(AB18="","",T18+AB18) | AD18: =IF(B18="","",MAX($B$5:B18)) | AJ18: =IF($A18="","",YEAR($A18)*100+MONTH($A18)) | AK18: =IF($A18="","",IF($N18="",0,1))
A19: 46028 | B19: =IF(V19<>"",V19-T19,IF(AF19<>"",AA19+AF19,"")) | C19: =IF(OR(B19="",B18=""),"",B19-B18) | D19: =IF(OR(B19="",AA19=""),"",B19-AA19) | E19: =IF(OR(B19="",AD19=0),"",MIN(0,B19/AD19-1)) | F19: =IF(OR(U19="",T19=0,T19=""),"",(P19-T19*1.4)/U19) | G19: =IF(OR(AC19="",'09_CF_원금'!$B$108=0),"",AC19/'09_CF_원금'!$B$108) | H19: =IF(OR(U19="",U19=0,AC19=""),"",AC19/U19) | I19: =IF(OR(S19="",U19=""),"",S19/(U19+S19)) | J19: =IF(W19<>"",W19-X19,IF(AG19<>"",AG19,"")) | K19: =IF(Q19<>"",Q19-Y19,IF(AH19<>"",AH19,"")) | L19: =IF(R19<>"",R19-Z19,IF(AI19<>"",AI19,"")) | Q19: =IF($A19="","",IF(Q18="","",Q18)) | R19: =IF($A19="","",IF(R18="","",R18)) | S19: =IF($A19="","",IF(S18="","",S18)) | T19: =IF(OR(P19="",W19=""),"",P19-W19) | U19: =IF($A19="","",IF(U18="","",U18)) | V19: =IF(P19="","",P19+IF(Q19="",0,Q19)+IF(R19="",0,R19)) | X19: =SUMIFS('09_CF_원금'!$E$6:$E$92,'09_CF_원금'!$D$6:$D$92,"국장",'09_CF_원금'!$A$6:$A$92,"<="&$A19)-SUMIFS('09_CF_원금'!$E$6:$E$92,'09_CF_원금'!$C$6:$C$92,"국장",'09_CF_원금'!$A$6:$A$92,"<="&$A19) | Y19: =SUMIFS('09_CF_원금'!$E$6:$E$92,'09_CF_원금'!$D$6:$D$92,"미장",'09_CF_원금'!$A$6:$A$92,"<="&$A19)-SUMIFS('09_CF_원금'!$E$6:$E$92,'09_CF_원금'!$C$6:$C$92,"미장",'09_CF_원금'!$A$6:$A$92,"<="&$A19) | Z19: =SUMIFS('09_CF_원금'!$E$6:$E$92,'09_CF_원금'!$D$6:$D$92,"ISA",'09_CF_원금'!$A$6:$A$92,"<="&$A19)-SUMIFS('09_CF_원금'!$E$6:$E$92,'09_CF_원금'!$C$6:$C$92,"ISA",'09_CF_원금'!$A$6:$A$92,"<="&$A19) | AA19: =IF($A19="","",X19+Y19+Z19+SUMIFS('09_CF_원금'!$E$6:$E$92,'09_CF_원금'!$D$6:$D$92,"중국",'09_CF_원금'!$A$6:$A$92,"<="&$A19)-SUMIFS('09_CF_원금'!$E$6:$E$92,'09_CF_원금'!$C$6:$C$92,"중국",'09_CF_원금'!$A$6:$A$92,"<="&$A19)+SUMIFS('09_CF_원금'!$E$6:$E$92,'09_CF_원금'!$D$6:$D$92,"업비트",'09_CF_원금'!$A$6:$A$92,"<="&$A19)-SUMIFS('09_CF_원금'!$E$6:$E$92,'09_CF_원금'!$C$6:$C$92,"업비트",'09_CF_원금'!$A$6:$A$92,"<="&$A19)) | AB19: =IF(OR(U19="",V19=""),"",U19-(V19-IF(S19="",0,S19))) | AC19: =IF(AB19="","",T19+AB19) | AD19: =IF(B19="","",MAX($B$5:B19)) | AE19: 25830 | AF19: 178746935 | AG19: 133878053 | AH19: 37408859 | AI19: 6973590 | AJ19: =IF($A19="","",YEAR($A19)*100+MONTH($A19)) | AK19: =IF($A19="","",IF($N19="",0,1))
A20: 46029 | B20: =IF(V20<>"",V20-T20,IF(AF20<>"",AA20+AF20,"")) | C20: =IF(OR(B20="",B19=""),"",B20-B19) | D20: =IF(OR(B20="",AA20=""),"",B20-AA20) | E20: =IF(OR(B20="",AD20=0),"",MIN(0,B20/AD20-1)) | F20: =IF(OR(U20="",T20=0,T20=""),"",(P20-T20*1.4)/U20) | G20: =IF(OR(AC20="",'09_CF_원금'!$B$108=0),"",AC20/'09_CF_원금'!$B$108) | H20: =IF(OR(U20="",U20=0,AC20=""),"",AC20/U20) | I20: =IF(OR(S20="",U20=""),"",S20/(U20+S20)) | J20: =IF(W20<>"",W20-X20,IF(AG20<>"",AG20,"")) | K20: =IF(Q20<>"",Q20-Y20,IF(AH20<>"",AH20,"")) | L20: =IF(R20<>"",R20-Z20,IF(AI20<>"",AI20,"")) | Q20: =IF($A20="","",IF(Q19="","",Q19)) | R20: =IF($A20="","",IF(R19="","",R19)) | S20: =IF($A20="","",IF(S19="","",S19)) | T20: =IF(OR(P20="",W20=""),"",P20-W20) | U20: =IF($A20="","",IF(U19="","",U19)) | V20: =IF(P20="","",P20+IF(Q20="",0,Q20)+IF(R20="",0,R20)) | X20: =SUMIFS('09_CF_원금'!$E$6:$E$92,'09_CF_원금'!$D$6:$D$92,"국장",'09_CF_원금'!$A$6:$A$92,"<="&$A20)-SUMIFS('09_CF_원금'!$E$6:$E$92,'09_CF_원금'!$C$6:$C$92,"국장",'09_CF_원금'!$A$6:$A$92,"<="&$A20) | Y20: =SUMIFS('09_CF_원금'!$E$6:$E$92,'09_CF_원금'!$D$6:$D$92,"미장",'09_CF_원금'!$A$6:$A$92,"<="&$A20)-SUMIFS('09_CF_원금'!$E$6:$E$92,'09_CF_원금'!$C$6:$C$92,"미장",'09_CF_원금'!$A$6:$A$92,"<="&$A20) | Z20: =SUMIFS('09_CF_원금'!$E$6:$E$92,'09_CF_원금'!$D$6:$D$92,"ISA",'09_CF_원금'!$A$6:$A$92,"<="&$A20)-SUMIFS('09_CF_원금'!$E$6:$E$92,'09_CF_원금'!$C$6:$C$92,"ISA",'09_CF_원금'!$A$6:$A$92,"<="&$A20) | AA20: =IF($A20="","",X20+Y20+Z20+SUMIFS('09_CF_원금'!$E$6:$E$92,'09_CF_원금'!$D$6:$D$92,"중국",'09_CF_원금'!$A$6:$A$92,"<="&$A20)-SUMIFS('09_CF_원금'!$E$6:$E$92,'09_CF_원금'!$C$6:$C$92,"중국",'09_CF_원금'!$A$6:$A$92,"<="&$A20)+SUMIFS('09_CF_원금'!$E$6:$E$92,'09_CF_원금'!$D$6:$D$92,"업비트",'09_CF_원금'!$A$6:$A$92,"<="&$A20)-SUMIFS('09_CF_원금'!$E$6:$E$92,'09_CF_원금'!$C$6:$C$92,"업비트",'09_CF_원금'!$A$6:$A$92,"<="&$A20)) | AB20: =IF(OR(U20="",V20=""),"",U20-(V20-IF(S20="",0,S20))) | AC20: =IF(AB20="","",T20+AB20) | AD20: =IF(B20="","",MAX($B$5:B20)) | AJ20: =IF($A20="","",YEAR($A20)*100+MONTH($A20)) | AK20: =IF($A20="","",IF($N20="",0,1))
A21: 46030 | B21: =IF(V21<>"",V21-T21,IF(AF21<>"",AA21+AF21,"")) | C21: =IF(OR(B21="",B20=""),"",B21-B20) | D21: =IF(OR(B21="",AA21=""),"",B21-AA21) | E21: =IF(OR(B21="",AD21=0),"",MIN(0,B21/AD21-1)) | F21: =IF(OR(U21="",T21=0,T21=""),"",(P21-T21*1.4)/U21) | G21: =IF(OR(AC21="",'09_CF_원금'!$B$108=0),"",AC21/'09_CF_원금'!$B$108) | H21: =IF(OR(U21="",U21=0,AC21=""),"",AC21/U21) | I21: =IF(OR(S21="",U21=""),"",S21/(U21+S21)) | J21: =IF(W21<>"",W21-X21,IF(AG21<>"",AG21,"")) | K21: =IF(Q21<>"",Q21-Y21,IF(AH21<>"",AH21,"")) | L21: =IF(R21<>"",R21-Z21,IF(AI21<>"",AI21,"")) | Q21: =IF($A21="","",IF(Q20="","",Q20)) | R21: =IF($A21="","",IF(R20="","",R20)) | S21: =IF($A21="","",IF(S20="","",S20)) | T21: =IF(OR(P21="",W21=""),"",P21-W21) | U21: =IF($A21="","",IF(U20="","",U20)) | V21: =IF(P21="","",P21+IF(Q21="",0,Q21)+IF(R21="",0,R21)) | X21: =SUMIFS('09_CF_원금'!$E$6:$E$92,'09_CF_원금'!$D$6:$D$92,"국장",'09_CF_원금'!$A$6:$A$92,"<="&$A21)-SUMIFS('09_CF_원금'!$E$6:$E$92,'09_CF_원금'!$C$6:$C$92,"국장",'09_CF_원금'!$A$6:$A$92,"<="&$A21) | Y21: =SUMIFS('09_CF_원금'!$E$6:$E$92,'09_CF_원금'!$D$6:$D$92,"미장",'09_CF_원금'!$A$6:$A$92,"<="&$A21)-SUMIFS('09_CF_원금'!$E$6:$E$92,'09_CF_원금'!$C$6:$C$92,"미장",'09_CF_원금'!$A$6:$A$92,"<="&$A21) | Z21: =SUMIFS('09_CF_원금'!$E$6:$E$92,'09_CF_원금'!$D$6:$D$92,"ISA",'09_CF_원금'!$A$6:$A$92,"<="&$A21)-SUMIFS('09_CF_원금'!$E$6:$E$92,'09_CF_원금'!$C$6:$C$92,"ISA",'09_CF_원금'!$A$6:$A$92,"<="&$A21) | AA21: =IF($A21="","",X21+Y21+Z21+SUMIFS('09_CF_원금'!$E$6:$E$92,'09_CF_원금'!$D$6:$D$92,"중국",'09_CF_원금'!$A$6:$A$92,"<="&$A21)-SUMIFS('09_CF_원금'!$E$6:$E$92,'09_CF_원금'!$C$6:$C$92,"중국",'09_CF_원금'!$A$6:$A$92,"<="&$A21)+SUMIFS('09_CF_원금'!$E$6:$E$92,'09_CF_원금'!$D$6:$D$92,"업비트",'09_CF_원금'!$A$6:$A$92,"<="&$A21)-SUMIFS('09_CF_원금'!$E$6:$E$92,'09_CF_원금'!$C$6:$C$92,"업비트",'09_CF_원금'!$A$6:$A$92,"<="&$A21)) | AB21: =IF(OR(U21="",V21=""),"",U21-(V21-IF(S21="",0,S21))) | AC21: =IF(AB21="","",T21+AB21) | AD21: =IF(B21="","",MAX($B$5:B21)) | AJ21: =IF($A21="","",YEAR($A21)*100+MONTH($A21)) | AK21: =IF($A21="","",IF($N21="",0,1))
A22: 46031 | B22: =IF(V22<>"",V22-T22,IF(AF22<>"",AA22+AF22,"")) | C22: =IF(OR(B22="",B21=""),"",B22-B21) | D22: =IF(OR(B22="",AA22=""),"",B22-AA22) | E22: =IF(OR(B22="",AD22=0),"",MIN(0,B22/AD22-1)) | F22: =IF(OR(U22="",T22=0,T22=""),"",(P22-T22*1.4)/U22) | G22: =IF(OR(AC22="",'09_CF_원금'!$B$108=0),"",AC22/'09_CF_원금'!$B$108) | H22: =IF(OR(U22="",U22=0,AC22=""),"",AC22/U22) | I22: =IF(OR(S22="",U22=""),"",S22/(U22+S22)) | J22: =IF(W22<>"",W22-X22,IF(AG22<>"",AG22,"")) | K22: =IF(Q22<>"",Q22-Y22,IF(AH22<>"",AH22,"")) | L22: =IF(R22<>"",R22-Z22,IF(AI22<>"",AI22,"")) | Q22: =IF($A22="","",IF(Q21="","",Q21)) | R22: =IF($A22="","",IF(R21="","",R21)) | S22: =IF($A22="","",IF(S21="","",S21)) | T22: =IF(OR(P22="",W22=""),"",P22-W22) | U22: =IF($A22="","",IF(U21="","",U21)) | V22: =IF(P22="","",P22+IF(Q22="",0,Q22)+IF(R22="",0,R22)) | X22: =SUMIFS('09_CF_원금'!$E$6:$E$92,'09_CF_원금'!$D$6:$D$92,"국장",'09_CF_원금'!$A$6:$A$92,"<="&$A22)-SUMIFS('09_CF_원금'!$E$6:$E$92,'09_CF_원금'!$C$6:$C$92,"국장",'09_CF_원금'!$A$6:$A$92,"<="&$A22) | Y22: =SUMIFS('09_CF_원금'!$E$6:$E$92,'09_CF_원금'!$D$6:$D$92,"미장",'09_CF_원금'!$A$6:$A$92,"<="&$A22)-SUMIFS('09_CF_원금'!$E$6:$E$92,'09_CF_원금'!$C$6:$C$92,"미장",'09_CF_원금'!$A$6:$A$92,"<="&$A22) | Z22: =SUMIFS('09_CF_원금'!$E$6:$E$92,'09_CF_원금'!$D$6:$D$92,"ISA",'09_CF_원금'!$A$6:$A$92,"<="&$A22)-SUMIFS('09_CF_원금'!$E$6:$E$92,'09_CF_원금'!$C$6:$C$92,"ISA",'09_CF_원금'!$A$6:$A$92,"<="&$A22) | AA22: =IF($A22="","",X22+Y22+Z22+SUMIFS('09_CF_원금'!$E$6:$E$92,'09_CF_원금'!$D$6:$D$92,"중국",'09_CF_원금'!$A$6:$A$92,"<="&$A22)-SUMIFS('09_CF_원금'!$E$6:$E$92,'09_CF_원금'!$C$6:$C$92,"중국",'09_CF_원금'!$A$6:$A$92,"<="&$A22)+SUMIFS('09_CF_원금'!$E$6:$E$92,'09_CF_원금'!$D$6:$D$92,"업비트",'09_CF_원금'!$A$6:$A$92,"<="&$A22)-SUMIFS('09_CF_원금'!$E$6:$E$92,'09_CF_원금'!$C$6:$C$92,"업비트",'09_CF_원금'!$A$6:$A$92,"<="&$A22)) | AB22: =IF(OR(U22="",V22=""),"",U22-(V22-IF(S22="",0,S22))) | AC22: =IF(AB22="","",T22+AB22) | AD22: =IF(B22="","",MAX($B$5:B22)) | AE22: 25938.25 | AF22: 200031674 | AG22: 153648785 | AH22: 38710402 | AI22: 7450286 | AJ22: =IF($A22="","",YEAR($A22)*100+MONTH($A22)) | AK22: =IF($A22="","",IF($N22="",0,1))
A23: 46034 | B23: =IF(V23<>"",V23-T23,IF(AF23<>"",AA23+AF23,"")) | C23: =IF(OR(B23="",B22=""),"",B23-B22) | D23: =IF(OR(B23="",AA23=""),"",B23-AA23) | E23: =IF(OR(B23="",AD23=0),"",MIN(0,B23/AD23-1)) | F23: =IF(OR(U23="",T23=0,T23=""),"",(P23-T23*1.4)/U23) | G23: =IF(OR(AC23="",'09_CF_원금'!$B$108=0),"",AC23/'09_CF_원금'!$B$108) | H23: =IF(OR(U23="",U23=0,AC23=""),"",AC23/U23) | I23: =IF(OR(S23="",U23=""),"",S23/(U23+S23)) | J23: =IF(W23<>"",W23-X23,IF(AG23<>"",AG23,"")) | K23: =IF(Q23<>"",Q23-Y23,IF(AH23<>"",AH23,"")) | L23: =IF(R23<>"",R23-Z23,IF(AI23<>"",AI23,"")) | Q23: =IF($A23="","",IF(Q22="","",Q22)) | R23: =IF($A23="","",IF(R22="","",R22)) | S23: =IF($A23="","",IF(S22="","",S22)) | T23: =IF(OR(P23="",W23=""),"",P23-W23) | U23: =IF($A23="","",IF(U22="","",U22)) | V23: =IF(P23="","",P23+IF(Q23="",0,Q23)+IF(R23="",0,R23)) | X23: =SUMIFS('09_CF_원금'!$E$6:$E$92,'09_CF_원금'!$D$6:$D$92,"국장",'09_CF_원금'!$A$6:$A$92,"<="&$A23)-SUMIFS('09_CF_원금'!$E$6:$E$92,'09_CF_원금'!$C$6:$C$92,"국장",'09_CF_원금'!$A$6:$A$92,"<="&$A23) | Y23: =SUMIFS('09_CF_원금'!$E$6:$E$92,'09_CF_원금'!$D$6:$D$92,"미장",'09_CF_원금'!$A$6:$A$92,"<="&$A23)-SUMIFS('09_CF_원금'!$E$6:$E$92,'09_CF_원금'!$C$6:$C$92,"미장",'09_CF_원금'!$A$6:$A$92,"<="&$A23) | Z23: =SUMIFS('09_CF_원금'!$E$6:$E$92,'09_CF_원금'!$D$6:$D$92,"ISA",'09_CF_원금'!$A$6:$A$92,"<="&$A23)-SUMIFS('09_CF_원금'!$E$6:$E$92,'09_CF_원금'!$C$6:$C$92,"ISA",'09_CF_원금'!$A$6:$A$92,"<="&$A23) | AA23: =IF($A23="","",X23+Y23+Z23+SUMIFS('09_CF_원금'!$E$6:$E$92,'09_CF_원금'!$D$6:$D$92,"중국",'09_CF_원금'!$A$6:$A$92,"<="&$A23)-SUMIFS('09_CF_원금'!$E$6:$E$92,'09_CF_원금'!$C$6:$C$92,"중국",'09_CF_원금'!$A$6:$A$92,"<="&$A23)+SUMIFS('09_CF_원금'!$E$6:$E$92,'09_CF_원금'!$D$6:$D$92,"업비트",'09_CF_원금'!$A$6:$A$92,"<="&$A23)-SUMIFS('09_CF_원금'!$E$6:$E$92,'09_CF_원금'!$C$6:$C$92,"업비트",'09_CF_원금'!$A$6:$A$92,"<="&$A23)) | AB23: =IF(OR(U23="",V23=""),"",U23-(V23-IF(S23="",0,S23))) | AC23: =IF(AB23="","",T23+AB23) | AD23: =IF(B23="","",MAX($B$5:B23)) | AJ23: =IF($A23="","",YEAR($A23)*100+MONTH($A23)) | AK23: =IF($A23="","",IF($N23="",0,1))
A24: 46035 | B24: =IF(V24<>"",V24-T24,IF(AF24<>"",AA24+AF24,"")) | C24: =IF(OR(B24="",B23=""),"",B24-B23) | D24: =IF(OR(B24="",AA24=""),"",B24-AA24) | E24: =IF(OR(B24="",AD24=0),"",MIN(0,B24/AD24-1)) | F24: =IF(OR(U24="",T24=0,T24=""),"",(P24-T24*1.4)/U24) | G24: =IF(OR(AC24="",'09_CF_원금'!$B$108=0),"",AC24/'09_CF_원금'!$B$108) | H24: =IF(OR(U24="",U24=0,AC24=""),"",AC24/U24) | I24: =IF(OR(S24="",U24=""),"",S24/(U24+S24)) | J24: =IF(W24<>"",W24-X24,IF(AG24<>"",AG24,"")) | K24: =IF(Q24<>"",Q24-Y24,IF(AH24<>"",AH24,"")) | L24: =IF(R24<>"",R24-Z24,IF(AI24<>"",AI24,"")) | Q24: =IF($A24="","",IF(Q23="","",Q23)) | R24: =IF($A24="","",IF(R23="","",R23)) | S24: =IF($A24="","",IF(S23="","",S23)) | T24: =IF(OR(P24="",W24=""),"",P24-W24) | U24: =IF($A24="","",IF(U23="","",U23)) | V24: =IF(P24="","",P24+IF(Q24="",0,Q24)+IF(R24="",0,R24)) | X24: =SUMIFS('09_CF_원금'!$E$6:$E$92,'09_CF_원금'!$D$6:$D$92,"국장",'09_CF_원금'!$A$6:$A$92,"<="&$A24)-SUMIFS('09_CF_원금'!$E$6:$E$92,'09_CF_원금'!$C$6:$C$92,"국장",'09_CF_원금'!$A$6:$A$92,"<="&$A24) | Y24: =SUMIFS('09_CF_원금'!$E$6:$E$92,'09_CF_원금'!$D$6:$D$92,"미장",'09_CF_원금'!$A$6:$A$92,"<="&$A24)-SUMIFS('09_CF_원금'!$E$6:$E$92,'09_CF_원금'!$C$6:$C$92,"미장",'09_CF_원금'!$A$6:$A$92,"<="&$A24) | Z24: =SUMIFS('09_CF_원금'!$E$6:$E$92,'09_CF_원금'!$D$6:$D$92,"ISA",'09_CF_원금'!$A$6:$A$92,"<="&$A24)-SUMIFS('09_CF_원금'!$E$6:$E$92,'09_CF_원금'!$C$6:$C$92,"ISA",'09_CF_원금'!$A$6:$A$92,"<="&$A24) | AA24: =IF($A24="","",X24+Y24+Z24+SUMIFS('09_CF_원금'!$E$6:$E$92,'09_CF_원금'!$D$6:$D$92,"중국",'09_CF_원금'!$A$6:$A$92,"<="&$A24)-SUMIFS('09_CF_원금'!$E$6:$E$92,'09_CF_원금'!$C$6:$C$92,"중국",'09_CF_원금'!$A$6:$A$92,"<="&$A24)+SUMIFS('09_CF_원금'!$E$6:$E$92,'09_CF_원금'!$D$6:$D$92,"업비트",'09_CF_원금'!$A$6:$A$92,"<="&$A24)-SUMIFS('09_CF_원금'!$E$6:$E$92,'09_CF_원금'!$C$6:$C$92,"업비트",'09_CF_원금'!$A$6:$A$92,"<="&$A24)) | AB24: =IF(OR(U24="",V24=""),"",U24-(V24-IF(S24="",0,S24))) | AC24: =IF(AB24="","",T24+AB24) | AD24: =IF(B24="","",MAX($B$5:B24)) | AE24: 25896.75 | AF24: 187489663 | AG24: 133885826 | AH24: 45222364 | AI24: 8381473 | AJ24: =IF($A24="","",YEAR($A24)*100+MONTH($A24)) | AK24: =IF($A24="","",IF($N24="",0,1))
A25: 46036 | B25: =IF(V25<>"",V25-T25,IF(AF25<>"",AA25+AF25,"")) | C25: =IF(OR(B25="",B24=""),"",B25-B24) | D25: =IF(OR(B25="",AA25=""),"",B25-AA25) | E25: =IF(OR(B25="",AD25=0),"",MIN(0,B25/AD25-1)) | F25: =IF(OR(U25="",T25=0,T25=""),"",(P25-T25*1.4)/U25) | G25: =IF(OR(AC25="",'09_CF_원금'!$B$108=0),"",AC25/'09_CF_원금'!$B$108) | H25: =IF(OR(U25="",U25=0,AC25=""),"",AC25/U25) | I25: =IF(OR(S25="",U25=""),"",S25/(U25+S25)) | J25: =IF(W25<>"",W25-X25,IF(AG25<>"",AG25,"")) | K25: =IF(Q25<>"",Q25-Y25,IF(AH25<>"",AH25,"")) | L25: =IF(R25<>"",R25-Z25,IF(AI25<>"",AI25,"")) | Q25: =IF($A25="","",IF(Q24="","",Q24)) | R25: =IF($A25="","",IF(R24="","",R24)) | S25: =IF($A25="","",IF(S24="","",S24)) | T25: =IF(OR(P25="",W25=""),"",P25-W25) | U25: =IF($A25="","",IF(U24="","",U24)) | V25: =IF(P25="","",P25+IF(Q25="",0,Q25)+IF(R25="",0,R25)) | X25: =SUMIFS('09_CF_원금'!$E$6:$E$92,'09_CF_원금'!$D$6:$D$92,"국장",'09_CF_원금'!$A$6:$A$92,"<="&$A25)-SUMIFS('09_CF_원금'!$E$6:$E$92,'09_CF_원금'!$C$6:$C$92,"국장",'09_CF_원금'!$A$6:$A$92,"<="&$A25) | Y25: =SUMIFS('09_CF_원금'!$E$6:$E$92,'09_CF_원금'!$D$6:$D$92,"미장",'09_CF_원금'!$A$6:$A$92,"<="&$A25)-SUMIFS('09_CF_원금'!$E$6:$E$92,'09_CF_원금'!$C$6:$C$92,"미장",'09_CF_원금'!$A$6:$A$92,"<="&$A25) | Z25: =SUMIFS('09_CF_원금'!$E$6:$E$92,'09_CF_원금'!$D$6:$D$92,"ISA",'09_CF_원금'!$A$6:$A$92,"<="&$A25)-SUMIFS('09_CF_원금'!$E$6:$E$92,'09_CF_원금'!$C$6:$C$92,"ISA",'09_CF_원금'!$A$6:$A$92,"<="&$A25) | AA25: =IF($A25="","",X25+Y25+Z25+SUMIFS('09_CF_원금'!$E$6:$E$92,'09_CF_원금'!$D$6:$D$92,"중국",'09_CF_원금'!$A$6:$A$92,"<="&$A25)-SUMIFS('09_CF_원금'!$E$6:$E$92,'09_CF_원금'!$C$6:$C$92,"중국",'09_CF_원금'!$A$6:$A$92,"<="&$A25)+SUMIFS('09_CF_원금'!$E$6:$E$92,'09_CF_원금'!$D$6:$D$92,"업비트",'09_CF_원금'!$A$6:$A$92,"<="&$A25)-SUMIFS('09_CF_원금'!$E$6:$E$92,'09_CF_원금'!$C$6:$C$92,"업비트",'09_CF_원금'!$A$6:$A$92,"<="&$A25)) | AB25: =IF(OR(U25="",V25=""),"",U25-(V25-IF(S25="",0,S25))) | AC25: =IF(AB25="","",T25+AB25) | AD25: =IF(B25="","",MAX($B$5:B25)) | AJ25: =IF($A25="","",YEAR($A25)*100+MONTH($A25)) | AK25: =IF($A25="","",IF($N25="",0,1))
A26: 46037 | B26: =IF(V26<>"",V26-T26,IF(AF26<>"",AA26+AF26,"")) | C26: =IF(OR(B26="",B25=""),"",B26-B25) | D26: =IF(OR(B26="",AA26=""),"",B26-AA26) | E26: =IF(OR(B26="",AD26=0),"",MIN(0,B26/AD26-1)) | F26: =IF(OR(U26="",T26=0,T26=""),"",(P26-T26*1.4)/U26) | G26: =IF(OR(AC26="",'09_CF_원금'!$B$108=0),"",AC26/'09_CF_원금'!$B$108) | H26: =IF(OR(U26="",U26=0,AC26=""),"",AC26/U26) | I26: =IF(OR(S26="",U26=""),"",S26/(U26+S26)) | J26: =IF(W26<>"",W26-X26,IF(AG26<>"",AG26,"")) | K26: =IF(Q26<>"",Q26-Y26,IF(AH26<>"",AH26,"")) | L26: =IF(R26<>"",R26-Z26,IF(AI26<>"",AI26,"")) | Q26: =IF($A26="","",IF(Q25="","",Q25)) | R26: =IF($A26="","",IF(R25="","",R25)) | S26: =IF($A26="","",IF(S25="","",S25)) | T26: =IF(OR(P26="",W26=""),"",P26-W26) | U26: =IF($A26="","",IF(U25="","",U25)) | V26: =IF(P26="","",P26+IF(Q26="",0,Q26)+IF(R26="",0,R26)) | X26: =SUMIFS('09_CF_원금'!$E$6:$E$92,'09_CF_원금'!$D$6:$D$92,"국장",'09_CF_원금'!$A$6:$A$92,"<="&$A26)-SUMIFS('09_CF_원금'!$E$6:$E$92,'09_CF_원금'!$C$6:$C$92,"국장",'09_CF_원금'!$A$6:$A$92,"<="&$A26) | Y26: =SUMIFS('09_CF_원금'!$E$6:$E$92,'09_CF_원금'!$D$6:$D$92,"미장",'09_CF_원금'!$A$6:$A$92,"<="&$A26)-SUMIFS('09_CF_원금'!$E$6:$E$92,'09_CF_원금'!$C$6:$C$92,"미장",'09_CF_원금'!$A$6:$A$92,"<="&$A26) | Z26: =SUMIFS('09_CF_원금'!$E$6:$E$92,'09_CF_원금'!$D$6:$D$92,"ISA",'09_CF_원금'!$A$6:$A$92,"<="&$A26)-SUMIFS('09_CF_원금'!$E$6:$E$92,'09_CF_원금'!$C$6:$C$92,"ISA",'09_CF_원금'!$A$6:$A$92,"<="&$A26) | AA26: =IF($A26="","",X26+Y26+Z26+SUMIFS('09_CF_원금'!$E$6:$E$92,'09_CF_원금'!$D$6:$D$92,"중국",'09_CF_원금'!$A$6:$A$92,"<="&$A26)-SUMIFS('09_CF_원금'!$E$6:$E$92,'09_CF_원금'!$C$6:$C$92,"중국",'09_CF_원금'!$A$6:$A$92,"<="&$A26)+SUMIFS('09_CF_원금'!$E$6:$E$92,'09_CF_원금'!$D$6:$D$92,"업비트",'09_CF_원금'!$A$6:$A$92,"<="&$A26)-SUMIFS('09_CF_원금'!$E$6:$E$92,'09_CF_원금'!$C$6:$C$92,"업비트",'09_CF_원금'!$A$6:$A$92,"<="&$A26)) | AB26: =IF(OR(U26="",V26=""),"",U26-(V26-IF(S26="",0,S26))) | AC26: =IF(AB26="","",T26+AB26) | AD26: =IF(B26="","",MAX($B$5:B26)) | AJ26: =IF($A26="","",YEAR($A26)*100+MONTH($A26)) | AK26: =IF($A26="","",IF($N26="",0,1))
A27: 46038 | B27: =IF(V27<>"",V27-T27,IF(AF27<>"",AA27+AF27,"")) | C27: =IF(OR(B27="",B26=""),"",B27-B26) | D27: =IF(OR(B27="",AA27=""),"",B27-AA27) | E27: =IF(OR(B27="",AD27=0),"",MIN(0,B27/AD27-1)) | F27: =IF(OR(U27="",T27=0,T27=""),"",(P27-T27*1.4)/U27) | G27: =IF(OR(AC27="",'09_CF_원금'!$B$108=0),"",AC27/'09_CF_원금'!$B$108) | H27: =IF(OR(U27="",U27=0,AC27=""),"",AC27/U27) | I27: =IF(OR(S27="",U27=""),"",S27/(U27+S27)) | J27: =IF(W27<>"",W27-X27,IF(AG27<>"",AG27,"")) | K27: =IF(Q27<>"",Q27-Y27,IF(AH27<>"",AH27,"")) | L27: =IF(R27<>"",R27-Z27,IF(AI27<>"",AI27,"")) | Q27: =IF($A27="","",IF(Q26="","",Q26)) | R27: =IF($A27="","",IF(R26="","",R26)) | S27: =IF($A27="","",IF(S26="","",S26)) | T27: =IF(OR(P27="",W27=""),"",P27-W27) | U27: =IF($A27="","",IF(U26="","",U26)) | V27: =IF(P27="","",P27+IF(Q27="",0,Q27)+IF(R27="",0,R27)) | X27: =SUMIFS('09_CF_원금'!$E$6:$E$92,'09_CF_원금'!$D$6:$D$92,"국장",'09_CF_원금'!$A$6:$A$92,"<="&$A27)-SUMIFS('09_CF_원금'!$E$6:$E$92,'09_CF_원금'!$C$6:$C$92,"국장",'09_CF_원금'!$A$6:$A$92,"<="&$A27) | Y27: =SUMIFS('09_CF_원금'!$E$6:$E$92,'09_CF_원금'!$D$6:$D$92,"미장",'09_CF_원금'!$A$6:$A$92,"<="&$A27)-SUMIFS('09_CF_원금'!$E$6:$E$92,'09_CF_원금'!$C$6:$C$92,"미장",'09_CF_원금'!$A$6:$A$92,"<="&$A27) | Z27: =SUMIFS('09_CF_원금'!$E$6:$E$92,'09_CF_원금'!$D$6:$D$92,"ISA",'09_CF_원금'!$A$6:$A$92,"<="&$A27)-SUMIFS('09_CF_원금'!$E$6:$E$92,'09_CF_원금'!$C$6:$C$92,"ISA",'09_CF_원금'!$A$6:$A$92,"<="&$A27) | AA27: =IF($A27="","",X27+Y27+Z27+SUMIFS('09_CF_원금'!$E$6:$E$92,'09_CF_원금'!$D$6:$D$92,"중국",'09_CF_원금'!$A$6:$A$92,"<="&$A27)-SUMIFS('09_CF_원금'!$E$6:$E$92,'09_CF_원금'!$C$6:$C$92,"중국",'09_CF_원금'!$A$6:$A$92,"<="&$A27)+SUMIFS('09_CF_원금'!$E$6:$E$92,'09_CF_원금'!$D$6:$D$92,"업비트",'09_CF_원금'!$A$6:$A$92,"<="&$A27)-SUMIFS('09_CF_원금'!$E$6:$E$92,'09_CF_원금'!$C$6:$C$92,"업비트",'09_CF_원금'!$A$6:$A$92,"<="&$A27)) | AB27: =IF(OR(U27="",V27=""),"",U27-(V27-IF(S27="",0,S27))) | AC27: =IF(AB27="","",T27+AB27) | AD27: =IF(B27="","",MAX($B$5:B27)) | AJ27: =IF($A27="","",YEAR($A27)*100+MONTH($A27)) | AK27: =IF($A27="","",IF($N27="",0,1))
A28: 46041 | B28: =IF(V28<>"",V28-T28,IF(AF28<>"",AA28+AF28,"")) | C28: =IF(OR(B28="",B27=""),"",B28-B27) | D28: =IF(OR(B28="",AA28=""),"",B28-AA28) | E28: =IF(OR(B28="",AD28=0),"",MIN(0,B28/AD28-1)) | F28: =IF(OR(U28="",T28=0,T28=""),"",(P28-T28*1.4)/U28) | G28: =IF(OR(AC28="",'09_CF_원금'!$B$108=0),"",AC28/'09_CF_원금'!$B$108) | H28: =IF(OR(U28="",U28=0,AC28=""),"",AC28/U28) | I28: =IF(OR(S28="",U28=""),"",S28/(U28+S28)) | J28: =IF(W28<>"",W28-X28,IF(AG28<>"",AG28,"")) | K28: =IF(Q28<>"",Q28-Y28,IF(AH28<>"",AH28,"")) | L28: =IF(R28<>"",R28-Z28,IF(AI28<>"",AI28,"")) | Q28: =IF($A28="","",IF(Q27="","",Q27)) | R28: =IF($A28="","",IF(R27="","",R27)) | S28: =IF($A28="","",IF(S27="","",S27)) | T28: =IF(OR(P28="",W28=""),"",P28-W28) | U28: =IF($A28="","",IF(U27="","",U27)) | V28: =IF(P28="","",P28+IF(Q28="",0,Q28)+IF(R28="",0,R28)) | X28: =SUMIFS('09_CF_원금'!$E$6:$E$92,'09_CF_원금'!$D$6:$D$92,"국장",'09_CF_원금'!$A$6:$A$92,"<="&$A28)-SUMIFS('09_CF_원금'!$E$6:$E$92,'09_CF_원금'!$C$6:$C$92,"국장",'09_CF_원금'!$A$6:$A$92,"<="&$A28) | Y28: =SUMIFS('09_CF_원금'!$E$6:$E$92,'09_CF_원금'!$D$6:$D$92,"미장",'09_CF_원금'!$A$6:$A$92,"<="&$A28)-SUMIFS('09_CF_원금'!$E$6:$E$92,'09_CF_원금'!$C$6:$C$92,"미장",'09_CF_원금'!$A$6:$A$92,"<="&$A28) | Z28: =SUMIFS('09_CF_원금'!$E$6:$E$92,'09_CF_원금'!$D$6:$D$92,"ISA",'09_CF_원금'!$A$6:$A$92,"<="&$A28)-SUMIFS('09_CF_원금'!$E$6:$E$92,'09_CF_원금'!$C$6:$C$92,"ISA",'09_CF_원금'!$A$6:$A$92,"<="&$A28) | AA28: =IF($A28="","",X28+Y28+Z28+SUMIFS('09_CF_원금'!$E$6:$E$92,'09_CF_원금'!$D$6:$D$92,"중국",'09_CF_원금'!$A$6:$A$92,"<="&$A28)-SUMIFS('09_CF_원금'!$E$6:$E$92,'09_CF_원금'!$C$6:$C$92,"중국",'09_CF_원금'!$A$6:$A$92,"<="&$A28)+SUMIFS('09_CF_원금'!$E$6:$E$92,'09_CF_원금'!$D$6:$D$92,"업비트",'09_CF_원금'!$A$6:$A$92,"<="&$A28)-SUMIFS('09_CF_원금'!$E$6:$E$92,'09_CF_원금'!$C$6:$C$92,"업비트",'09_CF_원금'!$A$6:$A$92,"<="&$A28)) | AB28: =IF(OR(U28="",V28=""),"",U28-(V28-IF(S28="",0,S28))) | AC28: =IF(AB28="","",T28+AB28) | AD28: =IF(B28="","",MAX($B$5:B28)) | AJ28: =IF($A28="","",YEAR($A28)*100+MONTH($A28)) | AK28: =IF($A28="","",IF($N28="",0,1))
A29: 46042 | B29: =IF(V29<>"",V29-T29,IF(AF29<>"",AA29+AF29,"")) | C29: =IF(OR(B29="",B28=""),"",B29-B28) | D29: =IF(OR(B29="",AA29=""),"",B29-AA29) | E29: =IF(OR(B29="",AD29=0),"",MIN(0,B29/AD29-1)) | F29: =IF(OR(U29="",T29=0,T29=""),"",(P29-T29*1.4)/U29) | G29: =IF(OR(AC29="",'09_CF_원금'!$B$108=0),"",AC29/'09_CF_원금'!$B$108) | H29: =IF(OR(U29="",U29=0,AC29=""),"",AC29/U29) | I29: =IF(OR(S29="",U29=""),"",S29/(U29+S29)) | J29: =IF(W29<>"",W29-X29,IF(AG29<>"",AG29,"")) | K29: =IF(Q29<>"",Q29-Y29,IF(AH29<>"",AH29,"")) | L29: =IF(R29<>"",R29-Z29,IF(AI29<>"",AI29,"")) | Q29: =IF($A29="","",IF(Q28="","",Q28)) | R29: =IF($A29="","",IF(R28="","",R28)) | S29: =IF($A29="","",IF(S28="","",S28)) | T29: =IF(OR(P29="",W29=""),"",P29-W29) | U29: =IF($A29="","",IF(U28="","",U28)) | V29: =IF(P29="","",P29+IF(Q29="",0,Q29)+IF(R29="",0,R29)) | X29: =SUMIFS('09_CF_원금'!$E$6:$E$92,'09_CF_원금'!$D$6:$D$92,"국장",'09_CF_원금'!$A$6:$A$92,"<="&$A29)-SUMIFS('09_CF_원금'!$E$6:$E$92,'09_CF_원금'!$C$6:$C$92,"국장",'09_CF_원금'!$A$6:$A$92,"<="&$A29) | Y29: =SUMIFS('09_CF_원금'!$E$6:$E$92,'09_CF_원금'!$D$6:$D$92,"미장",'09_CF_원금'!$A$6:$A$92,"<="&$A29)-SUMIFS('09_CF_원금'!$E$6:$E$92,'09_CF_원금'!$C$6:$C$92,"미장",'09_CF_원금'!$A$6:$A$92,"<="&$A29) | Z29: =SUMIFS('09_CF_원금'!$E$6:$E$92,'09_CF_원금'!$D$6:$D$92,"ISA",'09_CF_원금'!$A$6:$A$92,"<="&$A29)-SUMIFS('09_CF_원금'!$E$6:$E$92,'09_CF_원금'!$C$6:$C$92,"ISA",'09_CF_원금'!$A$6:$A$92,"<="&$A29) | AA29: =IF($A29="","",X29+Y29+Z29+SUMIFS('09_CF_원금'!$E$6:$E$92,'09_CF_원금'!$D$6:$D$92,"중국",'09_CF_원금'!$A$6:$A$92,"<="&$A29)-SUMIFS('09_CF_원금'!$E$6:$E$92,'09_CF_원금'!$C$6:$C$92,"중국",'09_CF_원금'!$A$6:$A$92,"<="&$A29)+SUMIFS('09_CF_원금'!$E$6:$E$92,'09_CF_원금'!$D$6:$D$92,"업비트",'09_CF_원금'!$A$6:$A$92,"<="&$A29)-SUMIFS('09_CF_원금'!$E$6:$E$92,'09_CF_원금'!$C$6:$C$92,"업비트",'09_CF_원금'!$A$6:$A$92,"<="&$A29)) | AB29: =IF(OR(U29="",V29=""),"",U29-(V29-IF(S29="",0,S29))) | AC29: =IF(AB29="","",T29+AB29) | AD29: =IF(B29="","",MAX($B$5:B29)) | AJ29: =IF($A29="","",YEAR($A29)*100+MONTH($A29)) | AK29: =IF($A29="","",IF($N29="",0,1))
A30: 46043 | B30: =IF(V30<>"",V30-T30,IF(AF30<>"",AA30+AF30,"")) | C30: =IF(OR(B30="",B29=""),"",B30-B29) | D30: =IF(OR(B30="",AA30=""),"",B30-AA30) | E30: =IF(OR(B30="",AD30=0),"",MIN(0,B30/AD30-1)) | F30: =IF(OR(U30="",T30=0,T30=""),"",(P30-T30*1.4)/U30) | G30: =IF(OR(AC30="",'09_CF_원금'!$B$108=0),"",AC30/'09_CF_원금'!$B$108) | H30: =IF(OR(U30="",U30=0,AC30=""),"",AC30/U30) | I30: =IF(OR(S30="",U30=""),"",S30/(U30+S30)) | J30: =IF(W30<>"",W30-X30,IF(AG30<>"",AG30,"")) | K30: =IF(Q30<>"",Q30-Y30,IF(AH30<>"",AH30,"")) | L30: =IF(R30<>"",R30-Z30,IF(AI30<>"",AI30,"")) | Q30: =IF($A30="","",IF(Q29="","",Q29)) | R30: =IF($A30="","",IF(R29="","",R29)) | S30: =IF($A30="","",IF(S29="","",S29)) | T30: =IF(OR(P30="",W30=""),"",P30-W30) | U30: =IF($A30="","",IF(U29="","",U29)) | V30: =IF(P30="","",P30+IF(Q30="",0,Q30)+IF(R30="",0,R30)) | X30: =SUMIFS('09_CF_원금'!$E$6:$E$92,'09_CF_원금'!$D$6:$D$92,"국장",'09_CF_원금'!$A$6:$A$92,"<="&$A30)-SUMIFS('09_CF_원금'!$E$6:$E$92,'09_CF_원금'!$C$6:$C$92,"국장",'09_CF_원금'!$A$6:$A$92,"<="&$A30) | Y30: =SUMIFS('09_CF_원금'!$E$6:$E$92,'09_CF_원금'!$D$6:$D$92,"미장",'09_CF_원금'!$A$6:$A$92,"<="&$A30)-SUMIFS('09_CF_원금'!$E$6:$E$92,'09_CF_원금'!$C$6:$C$92,"미장",'09_CF_원금'!$A$6:$A$92,"<="&$A30) | Z30: =SUMIFS('09_CF_원금'!$E$6:$E$92,'09_CF_원금'!$D$6:$D$92,"ISA",'09_CF_원금'!$A$6:$A$92,"<="&$A30)-SUMIFS('09_CF_원금'!$E$6:$E$92,'09_CF_원금'!$C$6:$C$92,"ISA",'09_CF_원금'!$A$6:$A$92,"<="&$A30) | AA30: =IF($A30="","",X30+Y30+Z30+SUMIFS('09_CF_원금'!$E$6:$E$92,'09_CF_원금'!$D$6:$D$92,"중국",'09_CF_원금'!$A$6:$A$92,"<="&$A30)-SUMIFS('09_CF_원금'!$E$6:$E$92,'09_CF_원금'!$C$6:$C$92,"중국",'09_CF_원금'!$A$6:$A$92,"<="&$A30)+SUMIFS('09_CF_원금'!$E$6:$E$92,'09_CF_원금'!$D$6:$D$92,"업비트",'09_CF_원금'!$A$6:$A$92,"<="&$A30)-SUMIFS('09_CF_원금'!$E$6:$E$92,'09_CF_원금'!$C$6:$C$92,"업비트",'09_CF_원금'!$A$6:$A$92,"<="&$A30)) | AB30: =IF(OR(U30="",V30=""),"",U30-(V30-IF(S30="",0,S30))) | AC30: =IF(AB30="","",T30+AB30) | AD30: =IF(B30="","",MAX($B$5:B30)) | AJ30: =IF($A30="","",YEAR($A30)*100+MONTH($A30)) | AK30: =IF($A30="","",IF($N30="",0,1))
A31: 46044 | B31: =IF(V31<>"",V31-T31,IF(AF31<>"",AA31+AF31,"")) | C31: =IF(OR(B31="",B30=""),"",B31-B30) | D31: =IF(OR(B31="",AA31=""),"",B31-AA31) | E31: =IF(OR(B31="",AD31=0),"",MIN(0,B31/AD31-1)) | F31: =IF(OR(U31="",T31=0,T31=""),"",(P31-T31*1.4)/U31) | G31: =IF(OR(AC31="",'09_CF_원금'!$B$108=0),"",AC31/'09_CF_원금'!$B$108) | H31: =IF(OR(U31="",U31=0,AC31=""),"",AC31/U31) | I31: =IF(OR(S31="",U31=""),"",S31/(U31+S31)) | J31: =IF(W31<>"",W31-X31,IF(AG31<>"",AG31,"")) | K31: =IF(Q31<>"",Q31-Y31,IF(AH31<>"",AH31,"")) | L31: =IF(R31<>"",R31-Z31,IF(AI31<>"",AI31,"")) | Q31: =IF($A31="","",IF(Q30="","",Q30)) | R31: =IF($A31="","",IF(R30="","",R30)) | S31: =IF($A31="","",IF(S30="","",S30)) | T31: =IF(OR(P31="",W31=""),"",P31-W31) | U31: =IF($A31="","",IF(U30="","",U30)) | V31: =IF(P31="","",P31+IF(Q31="",0,Q31)+IF(R31="",0,R31)) | X31: =SUMIFS('09_CF_원금'!$E$6:$E$92,'09_CF_원금'!$D$6:$D$92,"국장",'09_CF_원금'!$A$6:$A$92,"<="&$A31)-SUMIFS('09_CF_원금'!$E$6:$E$92,'09_CF_원금'!$C$6:$C$92,"국장",'09_CF_원금'!$A$6:$A$92,"<="&$A31) | Y31: =SUMIFS('09_CF_원금'!$E$6:$E$92,'09_CF_원금'!$D$6:$D$92,"미장",'09_CF_원금'!$A$6:$A$92,"<="&$A31)-SUMIFS('09_CF_원금'!$E$6:$E$92,'09_CF_원금'!$C$6:$C$92,"미장",'09_CF_원금'!$A$6:$A$92,"<="&$A31) | Z31: =SUMIFS('09_CF_원금'!$E$6:$E$92,'09_CF_원금'!$D$6:$D$92,"ISA",'09_CF_원금'!$A$6:$A$92,"<="&$A31)-SUMIFS('09_CF_원금'!$E$6:$E$92,'09_CF_원금'!$C$6:$C$92,"ISA",'09_CF_원금'!$A$6:$A$92,"<="&$A31) | AA31: =IF($A31="","",X31+Y31+Z31+SUMIFS('09_CF_원금'!$E$6:$E$92,'09_CF_원금'!$D$6:$D$92,"중국",'09_CF_원금'!$A$6:$A$92,"<="&$A31)-SUMIFS('09_CF_원금'!$E$6:$E$92,'09_CF_원금'!$C$6:$C$92,"중국",'09_CF_원금'!$A$6:$A$92,"<="&$A31)+SUMIFS('09_CF_원금'!$E$6:$E$92,'09_CF_원금'!$D$6:$D$92,"업비트",'09_CF_원금'!$A$6:$A$92,"<="&$A31)-SUMIFS('09_CF_원금'!$E$6:$E$92,'09_CF_원금'!$C$6:$C$92,"업비트",'09_CF_원금'!$A$6:$A$92,"<="&$A31)) | AB31: =IF(OR(U31="",V31=""),"",U31-(V31-IF(S31="",0,S31))) | AC31: =IF(AB31="","",T31+AB31) | AD31: =IF(B31="","",MAX($B$5:B31)) | AJ31: =IF($A31="","",YEAR($A31)*100+MONTH($A31)) | AK31: =IF($A31="","",IF($N31="",0,1))
