Workbook

Sheet 00_대시보드
A1: ① 오늘의 리스크 대시보드
A2: =TEXT(TODAY(),"yyyy-mm-dd (aaa)")&" | 손익보다 리스크를 먼저 본다. 🔴가 하나라도 있으면 신규 매수 금지." -> 2026-08-11 (화) | 손익보다 리스크를 먼저 본다. 🔴가 하나라도 있으면 신규 매수 금지.
A4: Ⅰ. 한눈에 보는 상태 | I4: Ⅸ. 리스크 추이 (01_일별로그 자동)
A5: 계좌 순자산 (Asset, 대출포함) | B5: ★ 실질 누적 순손익 | C5: 실질 주식 Exposure | D5: 실질 레버리지 | E5: 담보비율 | F5: 청산까지 여력 | G5: 위반 | H5: 기한초과 체크
A6: ='03_포지션'!$B$41 -> 361082576 | B6: =$E$22 -> -2224732.1 | C6: ='03_포지션'!$B$37 -> 1079147857 | D6: ='03_포지션'!$B$54 -> 8.912495 | E6: ='03_포지션'!$B$51 -> 1.5892889 | F6: ='03_포지션'!$B$52 -> 0.092613175 | G6: ='02_룰북'!$G$22 -> 7 | H6: ='02_룰북'!$H$47 -> 4
A7: 총평가 − 신용 | B7: 표면손익 − 강의비 − 세금 (Ⅳ와 동일) | C7: 레버ETF 배수 반영 | D7: Expo ÷ 순수 자기자본 | E7: 국장 기준 | F7: 몇 % 더 빠지면 청산 | G7: 룰북 🔴 | H7: 룰북 체크리스트
A9: Ⅱ. 계좌별 현황
A10: 계좌 | B10: 평가금액(명목) | C10: 신용 | D10: 순자산 (Equity) | E10: 누적 원금 | F10: 누적 손익 | G10: 수익률 | H10: 비고
A11: 국장 | B11: =SUMIFS('03_포지션'!$I$17:$I$31,'03_포지션'!$C$17:$C$31,"국장")+'03_포지션'!$B$6 -> 760373938 | C11: ='03_포지션'!$C$6 -> 478436585 | D11: =B11-C11 -> 281937353 | E11: ='09_CF_원금'!$B$97 -> 365000000 | F11: =D11-E11 -> -83062647 | G11: =IF(E11<=0,"산출불가",F11/E11) -> -0.2275689 | H11: =IF(E11<=0,"⚠️ 계좌간 이체로 원금 0 이하 → %는 무의미","")
A12: 미장 | B12: =SUMIFS('03_포지션'!$I$17:$I$31,'03_포지션'!$C$17:$C$31,"미장")+'03_포지션'!$B$7 -> 47167857 | C12: ='03_포지션'!$C$7 -> 0 | D12: =B12-C12 -> 47167857 | E12: ='09_CF_원금'!$B$98 -> -65000000 | F12: =D12-E12 -> 112167857 | G12: =IF(E12<=0,"산출불가",F12/E12) -> 산출불가 | H12: =IF(E12<=0,"⚠️ 계좌간 이체로 원금 0 이하 → %는 무의미","") -> ⚠️ 계좌간 이체로 원금 0 이하 → %는 무의미
A13: ISA | B13: =SUMIFS('03_포지션'!$I$17:$I$31,'03_포지션'!$C$17:$C$31,"ISA")+'03_포지션'!$B$8 -> 31977366 | C13: ='03_포지션'!$C$8 -> 0 | D13: =B13-C13 -> 31977366 | E13: ='09_CF_원금'!$B$99 -> 40000000 | F13: =D13-E13 -> -8022634 | G13: =IF(E13<=0,"산출불가",F13/E13) -> -0.20056585 | H13: =IF(E13<=0,"⚠️ 계좌간 이체로 원금 0 이하 → %는 무의미","")
A14: 합계 | B14: =SUM(B11:B13) -> 839519161 | C14: =SUM(C11:C13) -> 478436585 | D14: =SUM(D11:D13) -> 361082576 | E14: =SUM(E11:E13) -> 340000000 | F14: =SUM(F11:F13) -> 21082576 | G14: =IFERROR(F14/E14,"") -> 0.062007576
A16: Ⅲ. 차입 현황 — 배율이 먼저, 금액은 그 다음
A17: ★ 총차입 ÷ 연봉 | B17: ★ 증권차입 ÷ 연봉 | C17: 총 차입 | D17: 증권사 신용 | E17: 내재 레버리지 | F17: 증권 차입 | G17: 회사대출 | H17: 연봉(세전)
A18: =IFERROR(C18/H18,"") -> 12.006707 | B18: =IFERROR(F18/H18,"") -> 9.0067073 | C18: =F18+G18 -> 960536585 | D18: ='03_포지션'!$B$40 -> 478436585 | E18: ='03_포지션'!$B$44 -> 242100000 | F18: ='03_포지션'!$B$45 -> 720536585 | G18: ='03_포지션'!$B$42 -> 240000000 | H18: ='09_CF_원금'!$B$108 -> 80000000
A20: Ⅳ. 비용 차감 후 실질 손익 — 신용이자는 이미 예수금에서 빠져나가 손익에 반영되어 있으므로 여기서 또 빼지 않습니다
A21: 표면 누적손익 | B21: (참고) 누적 지급이자 | C21: (−) 누적 강의·구독비 | D21: (−) 해외주식 예상 세액 | E21: ★ 실질 누적 순손익 | F21: 실질 수익률
A22: =$F$14 -> 21082576 | B22: ='09_CF_원금'!$E$127 -> 19838868 | C22: ='09_CF_원금'!$B$179 -> 3554000 | D22: ='09_CF_원금'!$F$135 -> 19753308 | E22: =A22-C22-D22 -> -2224732.1 | F22: =IFERROR(E22/'09_CF_원금'!$B$100,"") -> -0.0065433296
A23: 표면 손익에 이미 반영 (차감 X) | B23: ↑ 차감하지 않음. 규모만 인지 | C23: 실제 지출 | D23: 미실현 부채 — 차감함 | E23: 표면 − 강의비 − 세금
A25: Ⅴ. 이번 주 투자 기조 (05_뷰트래커 Ⅰ에서 갱신)
A26: 내 기조 | B26: 레버ETF 상한 | C26: 현재 레버ETF | D26: 상한 대비 | E26: 전문가 컨센서스 | F26: 컨센서스 갭 | G26: 뷰 변화 | H26: 기조 갱신
A27: ='05_뷰트래커'!$C$5 | B27: ='05_뷰트래커'!$D$5 | C27: ='05_뷰트래커'!$E$5 -> 0.67048375 | D27: ='05_뷰트래커'!$F$5 -> ⚪ 기조 미설정 | E27: ='05_뷰트래커'!$E$15 -> ⚪ 기록 없음 | F27: ='05_뷰트래커'!$H$15 -> ⚪ 표본 부족 | G27: ='05_뷰트래커'!$G$15 -> — 이번 주 뷰 변화 없음 | H27: ='05_뷰트래커'!$B$5 -> ⚪ 미설정
A29: Ⅵ. 리스크 신호등 — 규칙 전문과 '위반 시 행동'은 02_룰북에 있습니다
A30: ID | B30: 측정지표 | C30: 내 기준 | D30: 현재값 | E30: 신호 | F30: 키워드
A31: ='02_룰북'!A6 -> R01 | B31: ='02_룰북'!C6 -> 실질 레버리지 배수 (Equity 대비) | C31: ='02_룰북'!D6 -> 8 | D31: ='02_룰북'!F6 -> 8.912495 | E31: ='02_룰북'!G6 -> 🔴 위반 | F31: ='02_룰북'!J6 -> 과레버리지
A32: ='02_룰북'!A7 -> R02 | B32: ='02_룰북'!C7 -> 청산까지 하락여력 | C32: ='02_룰북'!D7 -> 0.1 | D32: ='02_룰북'!F7 -> 0.092613175 | E32: ='02_룰북'!G7 -> 🔴 위반 | F32: ='02_룰북'!J7 -> 청산임박
A33: ='02_룰북'!A8 -> R03 | B33: ='02_룰북'!C8 -> 현금 비중 | C33: ='02_룰북'!D8 -> 0.05 | D33: ='02_룰북'!F8 -> 0.002284819 | E33: ='02_룰북'!G8 -> 🔴 위반 | F33: ='02_룰북'!J8 -> 현금고갈
A34: ='02_룰북'!A9 -> R04 | B34: ='02_룰북'!C9 -> 손절 관리 위반 종목 수 (미입력+하회) | C34: ='02_룰북'!D9 -> 0 | D34: ='02_룰북'!F9 -> 7 | E34: ='02_룰북'!G9 -> 🔴 위반 | F34: ='02_룰북'!J9 -> 손절방치
A35: ='02_룰북'!A10 -> R05 | B35: ='02_룰북'!C10 -> 전종목 손절 시 총손실 ÷ 순수 자기자본 | C35: ='02_룰북'!D10 -> 0.1 | D35: ='02_룰북'!F10 -> 0.1229101 | E35: ='02_룰북'!G10 -> 🔴 손절선 하회 7종목 | F35: ='02_룰북'!J10 -> 한방리스크
A36: ='02_룰북'!A11 -> R06 | B36: ='02_룰북'!C11 -> 단일 섹터 최대비중 | C36: ='02_룰북'!D11 -> 0.5 | D36: ='02_룰북'!F11 -> 0.94510483 | E36: ='02_룰북'!G11 -> 🔴 위반 | F36: ='02_룰북'!J11 -> 섹터쏠림
A37: ='02_룰북'!A12 -> R07 | B37: ='02_룰북'!C12 -> 레버ETF 명목 ÷ 계좌 순자산 | C37: ='02_룰북'!D12 | D37: ='02_룰북'!F12 -> 0.67048375 | E37: ='02_룰북'!G12 -> 🟢 준수 | F37: ='02_룰북'!J12 -> 레버ETF과다
A38: ='02_룰북'!A13 -> R08 | B38: ='02_룰북'!C13 -> 총차입 ÷ 연봉 | C38: ='02_룰북'!D13 -> 8 | D38: ='02_룰북'!F13 -> 9.0067073 | E38: ='02_룰북'!G13 -> 🔴 위반 | F38: ='02_룰북'!J13 -> 빚과다
A39: ='02_룰북'!A14 -> R09 | B39: ='02_룰북'!C14 -> 컨센서스 − 포지션 기조 갭 (p) | C39: ='02_룰북'!D14 -> 1 | D39: ='02_룰북'!F14 | E39: ='02_룰북'!G14 -> ⚪ 측정불가 | F39: ='02_룰북'!J14 -> 컨센서스역행
A40: ='02_룰북'!A15 | B40: ='02_룰북'!C15 | C40: ='02_룰북'!D15 | D40: ='02_룰북'!F15 | E40: ='02_룰북'!G15 | F40: ='02_룰북'!J15
A42: Ⅶ. 03_포지션을 갱신한 날 — 아래 7칸을 01_일별로그 오늘 행 S~Y열에 '값 붙여넣기' (한 번에 연속 붙여넣기 가능)
A43: 국장 총평가 → S열 | B43: 국장 순자산 → T열 | C43: 미장 순자산 → U열 | D43: ISA 순자산 → V열 | E43: 예수금 합계 → W열 | F43: 실질 주식Expo → X열 | G43: 국장 실질Expo → Y열
A44: ='03_포지션'!$B$46 -> 760373938 | B44: ='03_포지션'!$B$46-'03_포지션'!$C$6 -> 281937353 | C44: =SUMIFS('03_포지션'!$I$17:$I$31,'03_포지션'!$C$17:$C$31,"미장")+'03_포지션'!$B$7 -> 47167857 | D44: =SUMIFS('03_포지션'!$I$17:$I$31,'03_포지션'!$C$17:$C$31,"ISA")+'03_포지션'!$B$8 -> 31977366 | E44: ='03_포지션'!$B$9 -> 2471304 | F44: ='03_포지션'!$B$37 -> 1079147857 | G44: ='03_포지션'!$B$47 -> 977860000
A45: → 7칸이 S~Y열 순서와 그대로 맞습니다. 신용잔고(G열)는 S−T로 자동 계산되니 덮어쓰지 마세요. 평일에는 S~V 네 칸만 증권사 앱에서 직접 입력하면 됩니다.
A47: Ⅷ. 매수 버튼을 누르기 전 1분 — 하나라도 '아니오'면 오늘은 사지 않는다
A48: ☐ | B48: 1. 어제 이전에 계획된 매수이고, 이번 주 기조(Ⅴ)와 맞는가?
...

Sheet 01_일별로그
A1: ① 일별 로그 — 왼쪽이 볼 것, 가운데가 넣을 것, 오른쪽이 계산용
A2: 매일 넣는 건 S~V(국장 총평가·국장/미장/ISA 순자산) 4칸 + 감정뿐입니다. W~Y(예수금·실질Expo)는 비워두면 전일 값을 이어받고, 실질Expo는 명목 변동에 레버ETF 2배를 반영해 자동 보정됩니다.
A4: 날짜 | B4: 순자산 (Asset) | C4: 직전 기록 대비 손익 | D4: 누적손익 | E4: 순자산 MDD | F4: 청산까지 여력 | G4: 신용잔고 | H4: 내재 레버리지 | I4: 총차입 | J4: ★차입÷연봉 | K4: 차입비중 | L4: 현금비중 | M4: 국장 손익 | N4: 미장 손익 | O4: ISA 손익 | P4: 감정 (Fear↔Greed) | Q4: 위반 키워드 | R4: 메모 | S4: 국장 총평가 (입력) | T4: 국장 순자산 (입력) | U4: 미장 순자산 (입력) | V4: ISA 순자산 (입력) | W4: 예수금 합계 (이월) | X4: 실질 주식Expo (이월·스케일) | Y4: 국장 실질Expo (이월·스케일) | Z4: 총평가(명목) | AA4: 국장 원금 | AB4: 미장 원금 | AC4: ISA 원금 | AD4: 외부투입원금 | AE4: 순자산 전고점 | AF4: NQ100 | AG4: 누적손익(과거) | AH4: 국장손익(과거) | AI4: 미장손익(과거) | AJ4: ISA손익(과거) | AK4: 월키 | AL4: 감정점수
A5: 45957 | B5: =IF($A5="","",IF(AND($T5<>"",$U5<>"",$V5<>""),$T5+$U5+$V5,IF(AND($Z5<>"",$G5<>""),$Z5-$G5,IF($AG5<>"",$AD5+$AG5,"")))) | D5: =IF(OR($B5="",$AD5=""),"",$B5-$AD5) | E5: =IF(OR($B5="",$AE5=0,$AE5=""),"",MIN(0,$B5/$AE5-1)) | F5: =IF(OR($Y5="",$Y5=0,$G5="",$G5=0),"",($S5-$G5*'03_포지션'!$B$13)/$Y5) | G5: =IF(OR($S5="",$T5=""),"",$S5-$T5) | H5: =IF(OR($X5="",$Z5=""),"",$X5-($Z5-IF($W5="",0,$W5))) | I5: =IF(OR($G5="",$H5=""),"",$G5+$H5) | J5: =IF(OR($I5="",'09_CF_원금'!$B$108=0),"",$I5/'09_CF_원금'!$B$108) | K5: =IF(OR($X5="",$X5=0,$I5=""),"",$I5/$X5) | L5: =IF(OR($W5="",$X5=""),"",$W5/($X5+$W5)) | M5: =IF($T5<>"",$T5-$AA5,IF($AH5<>"",$AH5,"")) -> 48440000 | N5: =IF($U5<>"",$U5-$AB5,IF($AI5<>"",$AI5,"")) -> 32256167 | O5: =IF($V5<>"",$V5-$AC5,IF($AJ5<>"",$AJ5,"")) | Z5: =IF($S5="","",$S5+IF($U5="",0,$U5)+IF($V5="",0,$V5)) | AA5: =SUMIFS('09_CF_원금'!$E$6:$E$92,'09_CF_원금'!$D$6:$D$92,"국장",'09_CF_원금'!$A$6:$A$92,"<="&$A5)-SUMIFS('09_CF_원금'!$E$6:$E$92,'09_CF_원금'!$C$6:$C$92,"국장",'09_CF_원금'!$A$6:$A$92,"<="&$A5) -> 0 | AB5: =SUMIFS('09_CF_원금'!$E$6:$E$92,'09_CF_원금'!$D$6:$D$92,"미장",'09_CF_원금'!$A$6:$A$92,"<="&$A5)-SUMIFS('09_CF_원금'!$E$6:$E$92,'09_CF_원금'!$C$6:$C$92,"미장",'09_CF_원금'!$A$6:$A$92,"<="&$A5) -> 0 | AC5: =SUMIFS('09_CF_원금'!$E$6:$E$92,'09_CF_원금'!$D$6:$D$92,"ISA",'09_CF_원금'!$A$6:$A$92,"<="&$A5)-SUMIFS('09_CF_원금'!$E$6:$E$92,'09_CF_원금'!$C$6:$C$92,"ISA",'09_CF_원금'!$A$6:$A$92,"<="&$A5) -> 0 | AD5: =IF($A5="","",$AA5+$AB5+$AC5+SUMIFS('09_CF_원금'!$E$6:$E$92,'09_CF_원금'!$D$6:$D$92,"중국",'09_CF_원금'!$A$6:$A$92,"<="&$A5)-SUMIFS('09_CF_원금'!$E$6:$E$92,'09_CF_원금'!$C$6:$C$92,"중국",'09_CF_원금'!$A$6:$A$92,"<="&$A5)) -> 0 | AE5: =IF($B5="","",MAX($B$5:$B5)) | AF5: 25936 | AH5: 48440000 | AI5: 32256167 | AK5: =IF($A5="","",YEAR($A5)*100+MONTH($A5)) -> 202510 | AL5: =IF($P5="","",IF($P5="😱 극도의 공포",-2,IF($P5="😨 공포",-1,IF($P5="😐 평온",0,IF($P5="😃 탐욕",1,IF($P5="🤑 극도의 탐욕",2,""))))))
A6: 45961 | B6: =IF($A6="","",IF(AND($T6<>"",$U6<>"",$V6<>""),$T6+$U6+$V6,IF(AND($Z6<>"",$G6<>""),$Z6-$G6,IF($AG6<>"",$AD6+$AG6,"")))) | C6: =IF($B6="","",IFERROR($B6-LOOKUP(2,1/($B$5:$B5<>""),$B$5:$B5),"")) | D6: =IF(OR($B6="",$AD6=""),"",$B6-$AD6) | E6: =IF(OR($B6="",$AE6=0,$AE6=""),"",MIN(0,$B6/$AE6-1)) | F6: =IF(OR($Y6="",$Y6=0,$G6="",$G6=0),"",($S6-$G6*'03_포지션'!$B$13)/$Y6) | G6: =IF(OR($S6="",$T6=""),"",$S6-$T6) | H6: =IF(OR($X6="",$Z6=""),"",$X6-($Z6-IF($W6="",0,$W6))) | I6: =IF(OR($G6="",$H6=""),"",$G6+$H6) | J6: =IF(OR($I6="",'09_CF_원금'!$B$108=0),"",$I6/'09_CF_원금'!$B$108) | K6: =IF(OR($X6="",$X6=0,$I6=""),"",$I6/$X6) | L6: =IF(OR($W6="",$X6=""),"",$W6/($X6+$W6)) | M6: =IF($T6<>"",$T6-$AA6,IF($AH6<>"",$AH6,"")) -> 57742218 | N6: =IF($U6<>"",$U6-$AB6,IF($AI6<>"",$AI6,"")) -> 33266033 | O6: =IF($V6<>"",$V6-$AC6,IF($AJ6<>"",$AJ6,"")) | W6: =IF($A6="","",IF($W5="","",$W5)) | X6: =IF($A6="","",IFERROR(IF(OR($Z6="",$Z5="",$X5="",($Z5-IF($W5="",0,$W5))=0),IF($X5="","",$X5),($Z6-IF($W6="",0,$W6))+($X5-($Z5-IF($W5="",0,$W5)))*(1+2*(($Z6-IF($W6="",0,$W6))/($Z5-IF($W5="",0,$W5))-1))),IF($X5="","",$X5))) | Y6: =IF($A6="","",IFERROR(IF(OR($S6="",$S5="",$Y5="",$S5=0),IF($Y5="","",$Y5),$S6+($Y5-$S5)*(1+2*($S6/$S5-1))),IF($Y5="","",$Y5))) | Z6: =IF($S6="","",$S6+IF($U6="",0,$U6)+IF($V6="",0,$V6)) | AA6: =SUMIFS('09_CF_원금'!$E$6:$E$92,'09_CF_원금'!$D$6:$D$92,"국장",'09_CF_원금'!$A$6:$A$92,"<="&$A6)-SUMIFS('09_CF_원금'!$E$6:$E$92,'09_CF_원금'!$C$6:$C$92,"국장",'09_CF_원금'!$A$6:$A$92,"<="&$A6) -> 0 | AB6: =SUMIFS('09_CF_원금'!$E$6:$E$92,'09_CF_원금'!$D$6:$D$92,"미장",'09_CF_원금'!$A$6:$A$92,"<="&$A6)-SUMIFS('09_CF_원금'!$E$6:$E$92,'09_CF_원금'!$C$6:$C$92,"미장",'09_CF_원금'!$A$6:$A$92,"<="&$A6) -> 0 | AC6: =SUMIFS('09_CF_원금'!$E$6:$E$92,'09_CF_원금'!$D$6:$D$92,"ISA",'09_CF_원금'!$A$6:$A$92,"<="&$A6)-SUMIFS('09_CF_원금'!$E$6:$E$92,'09_CF_원금'!$C$6:$C$92,"ISA",'09_CF_원금'!$A$6:$A$92,"<="&$A6) -> 0 | AD6: =IF($A6="","",$AA6+$AB6+$AC6+SUMIFS('09_CF_원금'!$E$6:$E$92,'09_CF_원금'!$D$6:$D$92,"중국",'09_CF_원금'!$A$6:$A$92,"<="&$A6)-SUMIFS('09_CF_원금'!$E$6:$E$92,'09_CF_원금'!$C$6:$C$92,"중국",'09_CF_원금'!$A$6:$A$92,"<="&$A6)) -> 0 | AE6: =IF($B6="","",MAX($B$5:$B6)) | AF6: 26004 | AH6: 57742218 | AI6: 33266033 | AK6: =IF($A6="","",YEAR($A6)*100+MONTH($A6)) -> 202510 | AL6: =IF($P6="","",IF($P6="😱 극도의 공포",-2,IF($P6="😨 공포",-1,IF($P6="😐 평온",0,IF($P6="😃 탐욕",1,IF($P6="🤑 극도의 탐욕",2,""))))))
A7: 45968 | B7: =IF($A7="","",IF(AND($T7<>"",$U7<>"",$V7<>""),$T7+$U7+$V7,IF(AND($Z7<>"",$G7<>""),$Z7-$G7,IF($AG7<>"",$AD7+$AG7,"")))) | C7: =IF($B7="","",IFERROR($B7-LOOKUP(2,1/($B$5:$B6<>""),$B$5:$B6),"")) | D7: =IF(OR($B7="",$AD7=""),"",$B7-$AD7) | E7: =IF(OR($B7="",$AE7=0,$AE7=""),"",MIN(0,$B7/$AE7-1)) | F7: =IF(OR($Y7="",$Y7=0,$G7="",$G7=0),"",($S7-$G7*'03_포지션'!$B$13)/$Y7) | G7: =IF(OR($S7="",$T7=""),"",$S7-$T7) | H7: =IF(OR($X7="",$Z7=""),"",$X7-($Z7-IF($W7="",0,$W7))) | I7: =IF(OR($G7="",$H7=""),"",$G7+$H7) | J7: =IF(OR($I7="",'09_CF_원금'!$B$108=0),"",$I7/'09_CF_원금'!$B$108) | K7: =IF(OR($X7="",$X7=0,$I7=""),"",$I7/$X7) | L7: =IF(OR($W7="",$X7=""),"",$W7/($X7+$W7)) | M7: =IF($T7<>"",$T7-$AA7,IF($AH7<>"",$AH7,"")) -> 61665070 | N7: =IF($U7<>"",$U7-$AB7,IF($AI7<>"",$AI7,"")) -> 22042149 | O7: =IF($V7<>"",$V7-$AC7,IF($AJ7<>"",$AJ7,"")) | W7: =IF($A7="","",IF($W6="","",$W6)) | X7: =IF($A7="","",IFERROR(IF(OR($Z7="",$Z6="",$X6="",($Z6-IF($W6="",0,$W6))=0),IF($X6="","",$X6),($Z7-IF($W7="",0,$W7))+($X6-($Z6-IF($W6="",0,$W6)))*(1+2*(($Z7-IF($W7="",0,$W7))/($Z6-IF($W6="",0,$W6))-1))),IF($X6="","",$X6))) | Y7: =IF($A7="","",IFERROR(IF(OR($S7="",$S6="",$Y6="",$S6=0),IF($Y6="","",$Y6),$S7+($Y6-$S6)*(1+2*($S7/$S6-1))),IF($Y6="","",$Y6))) | Z7: =IF($S7="","",$S7+IF($U7="",0,$U7)+IF($V7="",0,$V7)) | AA7: =SUMIFS('09_CF_원금'!$E$6:$E$92,'09_CF_원금'!$D$6:$D$92,"국장",'09_CF_원금'!$A$6:$A$92,"<="&$A7)-SUMIFS('09_CF_원금'!$E$6:$E$92,'09_CF_원금'!$C$6:$C$92,"국장",'09_CF_원금'!$A$6:$A$92,"<="&$A7) -> 0 | AB7: =SUMIFS('09_CF_원금'!$E$6:$E$92,'09_CF_원금'!$D$6:$D$92,"미장",'09_CF_원금'!$A$6:$A$92,"<="&$A7)-SUMIFS('09_CF_원금'!$E$6:$E$92,'09_CF_원금'!$C$6:$C$92,"미장",'09_CF_원금'!$A$6:$A$92,"<="&$A7) -> 0 | AC7: =SUMIFS('09_CF_원금'!$E$6:$E$92,'09_CF_원금'!$D$6:$D$92,"ISA",'09_CF_원금'!$A$6:$A$92,"<="&$A7)-SUMIFS('09_CF_원금'!$E$6:$E$92,'09_CF_원금'!$C$6:$C$92,"ISA",'09_CF_원금'!$A$6:$A$92,"<="&$A7) -> 0 | AD7: =IF($A7="","",$AA7+$AB7+$AC7+SUMIFS('09_CF_원금'!$E$6:$E$92,'09_CF_원금'!$D$6:$D$92,"중국",'09_CF_원금'!$A$6:$A$92,"<="&$A7)-SUMIFS('09_CF_원금'!$E$6:$E$92,'09_CF_원금'!$C$6:$C$92,"중국",'09_CF_원금'!$A$6:$A$92,"<="&$A7)) -> 0 | AE7: =IF($B7="","",MAX($B$5:$B7)) | AF7: 25166.25 | AH7: 61665070 | AI7: 22042149 | AK7: =IF($A7="","",YEAR($A7)*100+MONTH($A7)) -> 202511 | AL7: =IF($P7="","",IF($P7="😱 극도의 공포",-2,IF($P7="😨 공포",-1,IF($P7="😐 평온",0,IF($P7="😃 탐욕",1,IF($P7="🤑 극도의 탐욕",2,""))))))
A8: 45975 | B8: =IF($A8="","",IF(AND($T8<>"",$U8<>"",$V8<>""),$T8+$U8+$V8,IF(AND($Z8<>"",$G8<>""),$Z8-$G8,IF($AG8<>"",$AD8+$AG8,"")))) | C8: =IF($B8="","",IFERROR($B8-LOOKUP(2,1/($B$5:$B7<>""),$B$5:$B7),"")) | D8: =IF(OR($B8="",$AD8=""),"",$B8-$AD8) | E8: =IF(OR($B8="",$AE8=0,$AE8=""),"",MIN(0,$B8/$AE8-1)) | F8: =IF(OR($Y8="",$Y8=0,$G8="",$G8=0),"",($S8-$G8*'03_포지션'!$B$13)/$Y8) | G8: =IF(OR($S8="",$T8=""),"",$S8-$T8) | H8: =IF(OR($X8="",$Z8=""),"",$X8-($Z8-IF($W8="",0,$W8))) | I8: =IF(OR($G8="",$H8=""),"",$G8+$H8) | J8: =IF(OR($I8="",'09_CF_원금'!$B$108=0),"",$I8/'09_CF_원금'!$B$108) | K8: =IF(OR($X8="",$X8=0,$I8=""),"",$I8/$X8) | L8: =IF(OR($W8="",$X8=""),"",$W8/($X8+$W8)) | M8: =IF($T8<>"",$T8-$AA8,IF($AH8<>"",$AH8,"")) -> 115959119 | N8: =IF($U8<>"",$U8-$AB8,IF($AI8<>"",$AI8,"")) -> 20504921 | O8: =IF($V8<>"",$V8-$AC8,IF($AJ8<>"",$AJ8,"")) | R8: 국장 조정세, 미국 AI 반등 기대 | W8: =IF($A8="","",IF($W7="","",$W7)) | X8: =IF($A8="","",IFERROR(IF(OR($Z8="",$Z7="",$X7="",($Z7-IF($W7="",0,$W7))=0),IF($X7="","",$X7),($Z8-IF($W8="",0,$W8))+($X7-($Z7-IF($W7="",0,$W7)))*(1+2*(($Z8-IF($W8="",0,$W8))/($Z7-IF($W7="",0,$W7))-1))),IF($X7="","",$X7))) | Y8: =IF($A8="","",IFERROR(IF(OR($S8="",$S7="",$Y7="",$S7=0),IF($Y7="","",$Y7),$S8+($Y7-$S7)*(1+2*($S8/$S7-1))),IF($Y7="","",$Y7))) | Z8: =IF($S8="","",$S8+IF($U8="",0,$U8)+IF($V8="",0,$V8)) | AA8: =SUMIFS('09_CF_원금'!$E$6:$E$92,'09_CF_원금'!$D$6:$D$92,"국장",'09_CF_원금'!$A$6:$A$92,"<="&$A8)-SUMIFS('09_CF_원금'!$E$6:$E$92,'09_CF_원금'!$C$6:$C$92,"국장",'09_CF_원금'!$A$6:$A$92,"<="&$A8) -> 0 | AB8: =SUMIFS('09_CF_원금'!$E$6:$E$92,'09_CF_원금'!$D$6:$D$92,"미장",'09_CF_원금'!$A$6:$A$92,"<="&$A8)-SUMIFS('09_CF_원금'!$E$6:$E$92,'09_CF_원금'!$C$6:$C$92,"미장",'09_CF_원금'!$A$6:$A$92,"<="&$A8) -> 0 | AC8: =SUMIFS('09_CF_원금'!$E$6:$E$92,'09_CF_원금'!$D$6:$D$92,"ISA",'09_CF_원금'!$A$6:$A$92,"<="&$A8)-SUMIFS('09_CF_원금'!$E$6:$E$92,'09_CF_원금'!$C$6:$C$92,"ISA",'09_CF_원금'!$A$6:$A$92,"<="&$A8) -> 0 | AD8: =IF($A8="","",$AA8+$AB8+$AC8+SUMIFS('09_CF_원금'!$E$6:$E$92,'09_CF_원금'!$D$6:$D$92,"중국",'09_CF_원금'!$A$6:$A$92,"<="&$A8)-SUMIFS('09_CF_원금'!$E$6:$E$92,'09_CF_원금'!$C$6:$C$92,"중국",'09_CF_원금'!$A$6:$A$92,"<="&$A8)) -> 0 | AE8: =IF($B8="","",MAX($B$5:$B8)) | AF8: 25094 | AH8: 115959119 | AI8: 20504921 | AK8: =IF($A8="","",YEAR($A8)*100+MONTH($A8)) -> 202511 | AL8: =IF($P8="","",IF($P8="😱 극도의 공포",-2,IF($P8="😨 공포",-1,IF($P8="😐 평온",0,IF($P8="😃 탐욕",1,IF($P8="🤑 극도의 탐욕",2,""))))))
A9: 45982 | B9: =IF($A9="","",IF(AND($T9<>"",$U9<>"",$V9<>""),$T9+$U9+$V9,IF(AND($Z9<>"",$G9<>""),$Z9-$G9,IF($AG9<>"",$AD9+$AG9,"")))) | C9: =IF($B9="","",IFERROR($B9-LOOKUP(2,1/($B$5:$B8<>""),$B$5:$B8),"")) | D9: =IF(OR($B9="",$AD9=""),"",$B9-$AD9) | E9: =IF(OR($B9="",$AE9=0,$AE9=""),"",MIN(0,$B9/$AE9-1)) | F9: =IF(OR($Y9="",$Y9=0,$G9="",$G9=0),"",($S9-$G9*'03_포지션'!$B$13)/$Y9) | G9: =IF(OR($S9="",$T9=""),"",$S9-$T9) | H9: =IF(OR($X9="",$Z9=""),"",$X9-($Z9-IF($W9="",0,$W9))) | I9: =IF(OR($G9="",$H9=""),"",$G9+$H9) | J9: =IF(OR($I9="",'09_CF_원금'!$B$108=0),"",$I9/'09_CF_원금'!$B$108) | K9: =IF(OR($X9="",$X9=0,$I9=""),"",$I9/$X9) | L9: =IF(OR($W9="",$X9=""),"",$W9/($X9+$W9)) | M9: =IF($T9<>"",$T9-$AA9,IF($AH9<>"",$AH9,"")) -> 106186052 | N9: =IF($U9<>"",$U9-$AB9,IF($AI9<>"",$AI9,"")) -> 8500000 | O9: =IF($V9<>"",$V9-$AC9,IF($AJ9<>"",$AJ9,"")) | R9: 폭락장 속 포트 파괴 & 패닉바잉 (하이닉스) | W9: =IF($A9="","",IF($W8="","",$W8)) | X9: =IF($A9="","",IFERROR(IF(OR($Z9="",$Z8="",$X8="",($Z8-IF($W8="",0,$W8))=0),IF($X8="","",$X8),($Z9-IF($W9="",0,$W9))+($X8-($Z8-IF($W8="",0,$W8)))*(1+2*(($Z9-IF($W9="",0,$W9))/($Z8-IF($W8="",0,$W8))-1))),IF($X8="","",$X8))) | Y9: =IF($A9="","",IFERROR(IF(OR($S9="",$S8="",$Y8="",$S8=0),IF($Y8="","",$Y8),$S9+($Y8-$S8)*(1+2*($S9/$S8-1))),IF($Y8="","",$Y8))) | Z9: =IF($S9="","",$S9+IF($U9="",0,$U9)+IF($V9="",0,$V9)) | AA9: =SUMIFS('09_CF_원금'!$E$6:$E$92,'09_CF_원금'!$D$6:$D$92,"국장",'09_CF_원금'!$A$6:$A$92,"<="&$A9)-SUMIFS('09_CF_원금'!$E$6:$E$92,'09_CF_원금'!$C$6:$C$92,"국장",'09_CF_원금'!$A$6:$A$92,"<="&$A9) -> 80000000 | AB9: =SUMIFS('09_CF_원금'!$E$6:$E$92,'09_CF_원금'!$D$6:$D$92,"미장",'09_CF_원금'!$A$6:$A$92,"<="&$A9)-SUMIFS('09_CF_원금'!$E$6:$E$92,'09_CF_원금'!$C$6:$C$92,"미장",'09_CF_원금'!$A$6:$A$92,"<="&$A9) -> 150000000 | AC9: =SUMIFS('09_CF_원금'!$E$6:$E$92,'09_CF_원금'!$D$6:$D$92,"ISA",'09_CF_원금'!$A$6:$A$92,"<="&$A9)-SUMIFS('09_CF_원금'!$E$6:$E$92,'09_CF_원금'!$C$6:$C$92,"ISA",'09_CF_원금'!$A$6:$A$92,"<="&$A9) -> 40000000 | AD9: =IF($A9="","",$AA9+$AB9+$AC9+SUMIFS('09_CF_원금'!$E$6:$E$92,'09_CF_원금'!$D$6:$D$92,"중국",'09_CF_원금'!$A$6:$A$92,"<="&$A9)-SUMIFS('09_CF_원금'!$E$6:$E$92,'09_CF_원금'!$C$6:$C$92,"중국",'09_CF_원금'!$A$6:$A$92,"<="&$A9)) -> 303000000 | AE9: =IF($B9="","",MAX($B$5:$B9)) | AF9: 24131 | AH9: 106186052 | AI9: 8500000 | AK9: =IF($A9="","",YEAR($A9)*100+MONTH($A9)) -> 202511 | AL9: =IF($P9="","",IF($P9="😱 극도의 공포",-2,IF($P9="😨 공포",-1,IF($P9="😐 평온",0,IF($P9="😃 탐욕",1,IF($P9="🤑 극도의 탐욕",2,""))))))
A10: 45986 | B10: =IF($A10="","",IF(AND($T10<>"",$U10<>"",$V10<>""),$T10+$U10+$V10,IF(AND($Z10<>"",$G10<>""),$Z10-$G10,IF($AG10<>"",$AD10+$AG10,"")))) | C10: =IF($B10="","",IFERROR($B10-LOOKUP(2,1/($B$5:$B9<>""),$B$5:$B9),"")) | D10: =IF(OR($B10="",$AD10=""),"",$B10-$AD10) | E10: =IF(OR($B10="",$AE10=0,$AE10=""),"",MIN(0,$B10/$AE10-1)) | F10: =IF(OR($Y10="",$Y10=0,$G10="",$G10=0),"",($S10-$G10*'03_포지션'!$B$13)/$Y10) | G10: =IF(OR($S10="",$T10=""),"",$S10-$T10) | H10: =IF(OR($X10="",$Z10=""),"",$X10-($Z10-IF($W10="",0,$W10))) | I10: =IF(OR($G10="",$H10=""),"",$G10+$H10) | J10: =IF(OR($I10="",'09_CF_원금'!$B$108=0),"",$I10/'09_CF_원금'!$B$108) | K10: =IF(OR($X10="",$X10=0,$I10=""),"",$I10/$X10) | L10: =IF(OR($W10="",$X10=""),"",$W10/($X10+$W10)) | M10: =IF($T10<>"",$T10-$AA10,IF($AH10<>"",$AH10,"")) -> 99571864 | N10: =IF($U10<>"",$U10-$AB10,IF($AI10<>"",$AI10,"")) -> 17917003 | O10: =IF($V10<>"",$V10-$AC10,IF($AJ10<>"",$AJ10,"")) | R10: 반등세 속 무지성 포모 바잉 | W10: =IF($A10="","",IF($W9="","",$W9)) | X10: =IF($A10="","",IFERROR(IF(OR($Z10="",$Z9="",$X9="",($Z9-IF($W9="",0,$W9))=0),IF($X9="","",$X9),($Z10-IF($W10="",0,$W10))+($X9-($Z9-IF($W9="",0,$W9)))*(1+2*(($Z10-IF($W10="",0,$W10))/($Z9-IF($W9="",0,$W9))-1))),IF($X9="","",$X9))) | Y10: =IF($A10="","",IFERROR(IF(OR($S10="",$S9="",$Y9="",$S9=0),IF($Y9="","",$Y9),$S10+($Y9-$S9)*(1+2*($S10/$S9-1))),IF($Y9="","",$Y9))) | Z10: =IF($S10="","",$S10+IF($U10="",0,$U10)+IF($V10="",0,$V10)) | AA10: =SUMIFS('09_CF_원금'!$E$6:$E$92,'09_CF_원금'!$D$6:$D$92,"국장",'09_CF_원금'!$A$6:$A$92,"<="&$A10)-SUMIFS('09_CF_원금'!$E$6:$E$92,'09_CF_원금'!$C$6:$C$92,"국장",'09_CF_원금'!$A$6:$A$92,"<="&$A10) -> 80000000 | AB10: =SUMIFS('09_CF_원금'!$E$6:$E$92,'09_CF_원금'!$D$6:$D$92,"미장",'09_CF_원금'!$A$6:$A$92,"<="&$A10)-SUMIFS('09_CF_원금'!$E$6:$E$92,'09_CF_원금'!$C$6:$C$92,"미장",'09_CF_원금'!$A$6:$A$92,"<="&$A10) -> 150000000 | AC10: =SUMIFS('09_CF_원금'!$E$6:$E$92,'09_CF_원금'!$D$6:$D$92,"ISA",'09_CF_원금'!$A$6:$A$92,"<="&$A10)-SUMIFS('09_CF_원금'!$E$6:$E$92,'09_CF_원금'!$C$6:$C$92,"ISA",'09_CF_원금'!$A$6:$A$92,"<="&$A10) -> 40000000 | AD10: =IF($A10="","",$AA10+$AB10+$AC10+SUMIFS('09_CF_원금'!$E$6:$E$92,'09_CF_원금'!$D$6:$D$92,"중국",'09_CF_원금'!$A$6:$A$92,"<="&$A10)-SUMIFS('09_CF_원금'!$E$6:$E$92,'09_CF_원금'!$C$6:$C$92,"중국",'09_CF_원금'!$A$6:$A$92,"<="&$A10)) -> 303000000 | AE10: =IF($B10="","",MAX($B$5:$B10)) | AF10: 25085.5 | AH10: 99571864 | AI10: 17917003 | AK10: =IF($A10="","",YEAR($A10)*100+MONTH($A10)) -> 202511 | AL10: =IF($P10="","",IF($P10="😱 극도의 공포",-2,IF($P10="😨 공포",-1,IF($P10="😐 평온",0,IF($P10="😃 탐욕",1,IF($P10="🤑 극도의 탐욕",2,""))))))
A11: 45996 | B11: =IF($A11="","",IF(AND($T11<>"",$U11<>"",$V11<>""),$T11+$U11+$V11,IF(AND($Z11<>"",$G11<>""),$Z11-$G11,IF($AG11<>"",$AD11+$AG11,"")))) | C11: =IF($B11="","",IFERROR($B11-LOOKUP(2,1/($B$5:$B10<>""),$B$5:$B10),"")) | D11: =IF(OR($B11="",$AD11=""),"",$B11-$AD11) | E11: =IF(OR($B11="",$AE11=0,$AE11=""),"",MIN(0,$B11/$AE11-1)) | F11: =IF(OR($Y11="",$Y11=0,$G11="",$G11=0),"",($S11-$G11*'03_포지션'!$B$13)/$Y11) | G11: =IF(OR($S11="",$T11=""),"",$S11-$T11) | H11: =IF(OR($X11="",$Z11=""),"",$X11-($Z11-IF($W11="",0,$W11))) | I11: =IF(OR($G11="",$H11=""),"",$G11+$H11) | J11: =IF(OR($I11="",'09_CF_원금'!$B$108=0),"",$I11/'09_CF_원금'!$B$108) | K11: =IF(OR($X11="",$X11=0,$I11=""),"",$I11/$X11) | L11: =IF(OR($W11="",$X11=""),"",$W11/($X11+$W11)) | M11: =IF($T11<>"",$T11-$AA11,IF($AH11<>"",$AH11,"")) -> 100497353 | N11: =IF($U11<>"",$U11-$AB11,IF($AI11<>"",$AI11,"")) -> 24928701 | O11: =IF($V11<>"",$V11-$AC11,IF($AJ11<>"",$AJ11,"")) | R11: 과잉확신 속 신용투자 & 패닉바잉 물타기 (알테오젠) | W11: =IF($A11="","",IF($W10="","",$W10)) | X11: =IF($A11="","",IFERROR(IF(OR($Z11="",$Z10="",$X10="",($Z10-IF($W10="",0,$W10))=0),IF($X10="","",$X10),($Z11-IF($W11="",0,$W11))+($X10-($Z10-IF($W10="",0,$W10)))*(1+2*(($Z11-IF($W11="",0,$W11))/($Z10-IF($W10="",0,$W10))-1))),IF($X10="","",$X10))) | Y11: =IF($A11="","",IFERROR(IF(OR($S11="",$S10="",$Y10="",$S10=0),IF($Y10="","",$Y10),$S11+($Y10-$S10)*(1+2*($S11/$S10-1))),IF($Y10="","",$Y10))) | Z11: =IF($S11="","",$S11+IF($U11="",0,$U11)+IF($V11="",0,$V11)) | AA11: =SUMIFS('09_CF_원금'!$E$6:$E$92,'09_CF_원금'!$D$6:$D$92,"국장",'09_CF_원금'!$A$6:$A$92,"<="&$A11)-SUMIFS('09_CF_원금'!$E$6:$E$92,'09_CF_원금'!$C$6:$C$92,"국장",'09_CF_원금'!$A$6:$A$92,"<="&$A11) -> 105000000 | AB11: =SUMIFS('09_CF_원금'!$E$6:$E$92,'09_CF_원금'!$D$6:$D$92,"미장",'09_CF_원금'!$A$6:$A$92,"<="&$A11)-SUMIFS('09_CF_원금'!$E$6:$E$92,'09_CF_원금'!$C$6:$C$92,"미장",'09_CF_원금'!$A$6:$A$92,"<="&$A11) -> 150000000 | AC11: =SUMIFS('09_CF_원금'!$E$6:$E$92,'09_CF_원금'!$D$6:$D$92,"ISA",'09_CF_원금'!$A$6:$A$92,"<="&$A11)-SUMIFS('09_CF_원금'!$E$6:$E$92,'09_CF_원금'!$C$6:$C$92,"ISA",'09_CF_원금'!$A$6:$A$92,"<="&$A11) -> 40000000 | AD11: =IF($A11="","",$AA11+$AB11+$AC11+SUMIFS('09_CF_원금'!$E$6:$E$92,'09_CF_원금'!$D$6:$D$92,"중국",'09_CF_원금'!$A$6:$A$92,"<="&$A11)-SUMIFS('09_CF_원금'!$E$6:$E$92,'09_CF_원금'!$C$6:$C$92,"중국",'09_CF_원금'!$A$6:$A$92,"<="&$A11)) -> 328000000 | AE11: =IF($B11="","",MAX($B$5:$B11)) | AF11: 25732 | AH11: 100497353 | AI11: 24928701 | AK11: =IF($A11="","",YEAR($A11)*100+MONTH($A11)) -> 202512 | AL11: =IF($P11="","",IF($P11="😱 극도의 공포",-2,IF($P11="😨 공포",-1,IF($P11="😐 평온",0,IF($P11="😃 탐욕",1,IF($P11="🤑 극도의 탐욕",2,""))))))
A12: 45999 | B12: =IF($A12="","",IF(AND($T12<>"",$U12<>"",$V12<>""),$T12+$U12+$V12,IF(AND($Z12<>"",$G12<>""),$Z12-$G12,IF($AG12<>"",$AD12+$AG12,"")))) | C12: =IF($B12="","",IFERROR($B12-LOOKUP(2,1/($B$5:$B11<>""),$B$5:$B11),"")) | D12: =IF(OR($B12="",$AD12=""),"",$B12-$AD12) | E12: =IF(OR($B12="",$AE12=0,$AE12=""),"",MIN(0,$B12/$AE12-1)) | F12: =IF(OR($Y12="",$Y12=0,$G12="",$G12=0),"",($S12-$G12*'03_포지션'!$B$13)/$Y12) | G12: =IF(OR($S12="",$T12=""),"",$S12-$T12) | H12: =IF(OR($X12="",$Z12=""),"",$X12-($Z12-IF($W12="",0,$W12))) | I12: =IF(OR($G12="",$H12=""),"",$G12+$H12) | J12: =IF(OR($I12="",'09_CF_원금'!$B$108=0),"",$I12/'09_CF_원금'!$B$108) | K12: =IF(OR($X12="",$X12=0,$I12=""),"",$I12/$X12) | L12: =IF(OR($W12="",$X12=""),"",$W12/($X12+$W12)) | M12: =IF($T12<>"",$T12-$AA12,IF($AH12<>"",$AH12,"")) -> 101730146 | N12: =IF($U12<>"",$U12-$AB12,IF($AI12<>"",$AI12,"")) -> 26543123 | O12: =IF($V12<>"",$V12-$AC12,IF($AJ12<>"",$AJ12,"")) | W12: =IF($A12="","",IF($W11="","",$W11)) | X12: =IF($A12="","",IFERROR(IF(OR($Z12="",$Z11="",$X11="",($Z11-IF($W11="",0,$W11))=0),IF($X11="","",$X11),($Z12-IF($W12="",0,$W12))+($X11-($Z11-IF($W11="",0,$W11)))*(1+2*(($Z12-IF($W12="",0,$W12))/($Z11-IF($W11="",0,$W11))-1))),IF($X11="","",$X11))) | Y12: =IF($A12="","",IFERROR(IF(OR($S12="",$S11="",$Y11="",$S11=0),IF($Y11="","",$Y11),$S12+($Y11-$S11)*(1+2*($S12/$S11-1))),IF($Y11="","",$Y11))) | Z12: =IF($S12="","",$S12+IF($U12="",0,$U12)+IF($V12="",0,$V12)) | AA12: =SUMIFS('09_CF_원금'!$E$6:$E$92,'09_CF_원금'!$D$6:$D$92,"국장",'09_CF_원금'!$A$6:$A$92,"<="&$A12)-SUMIFS('09_CF_원금'!$E$6:$E$92,'09_CF_원금'!$C$6:$C$92,"국장",'09_CF_원금'!$A$6:$A$92,"<="&$A12) -> 110000000 | AB12: =SUMIFS('09_CF_원금'!$E$6:$E$92,'09_CF_원금'!$D$6:$D$92,"미장",'09_CF_원금'!$A$6:$A$92,"<="&$A12)-SUMIFS('09_CF_원금'!$E$6:$E$92,'09_CF_원금'!$C$6:$C$92,"미장",'09_CF_원금'!$A$6:$A$92,"<="&$A12) -> 150000000 | AC12: =SUMIFS('09_CF_원금'!$E$6:$E$92,'09_CF_원금'!$D$6:$D$92,"ISA",'09_CF_원금'!$A$6:$A$92,"<="&$A12)-SUMIFS('09_CF_원금'!$E$6:$E$92,'09_CF_원금'!$C$6:$C$92,"ISA",'09_CF_원금'!$A$6:$A$92,"<="&$A12) -> 40000000 | AD12: =IF($A12="","",$AA12+$AB12+$AC12+SUMIFS('09_CF_원금'!$E$6:$E$92,'09_CF_원금'!$D$6:$D$92,"중국",'09_CF_원금'!$A$6:$A$92,"<="&$A12)-SUMIFS('09_CF_원금'!$E$6:$E$92,'09_CF_원금'!$C$6:$C$92,"중국",'09_CF_원금'!$A$6:$A$92,"<="&$A12)) -> 333000000 | AE12: =IF($B12="","",MAX($B$5:$B12)) | AF12: 25723 | AH12: 101730146 | AI12: 26543123 | AK12: =IF($A12="","",YEAR($A12)*100+MONTH($A12)) -> 202512 | AL12: =IF($P12="","",IF($P12="😱 극도의 공포",-2,IF($P12="😨 공포",-1,IF($P12="😐 평온",0,IF($P12="😃 탐욕",1,IF($P12="🤑 극도의 탐욕",2,""))))))
A13: 46010 | B13: =IF($A13="","",IF(AND($T13<>"",$U13<>"",$V13<>""),$T13+$U13+$V13,IF(AND($Z13<>"",$G13<>""),$Z13-$G13,IF($AG13<>"",$AD13+$AG13,"")))) | C13: =IF($B13="","",IFERROR($B13-LOOKUP(2,1/($B$5:$B12<>""),$B$5:$B12),"")) | D13: =IF(OR($B13="",$AD13=""),"",$B13-$AD13) | E13: =IF(OR($B13="",$AE13=0,$AE13=""),"",MIN(0,$B13/$AE13-1)) | F13: =IF(OR($Y13="",$Y13=0,$G13="",$G13=0),"",($S13-$G13*'03_포지션'!$B$13)/$Y13) | G13: =IF(OR($S13="",$T13=""),"",$S13-$T13) | H13: =IF(OR($X13="",$Z13=""),"",$X13-($Z13-IF($W13="",0,$W13))) | I13: =IF(OR($G13="",$H13=""),"",$G13+$H13) | J13: =IF(OR($I13="",'09_CF_원금'!$B$108=0),"",$I13/'09_CF_원금'!$B$108) | K13: =IF(OR($X13="",$X13=0,$I13=""),"",$I13/$X13) | L13: =IF(OR($W13="",$X13=""),"",$W13/($X13+$W13)) | M13: =IF($T13<>"",$T13-$AA13,IF($AH13<>"",$AH13,"")) -> 100089765 | N13: =IF($U13<>"",$U13-$AB13,IF($AI13<>"",$AI13,"")) -> 23580388 | O13: =IF($V13<>"",$V13-$AC13,IF($AJ13<>"",$AJ13,"")) | R13: 무리한 현금소진/레버리지로 계좌 악화 | W13: =IF($A13="","",IF($W12="","",$W12)) | X13: =IF($A13="","",IFERROR(IF(OR($Z13="",$Z12="",$X12="",($Z12-IF($W12="",0,$W12))=0),IF($X12="","",$X12),($Z13-IF($W13="",0,$W13))+($X12-($Z12-IF($W12="",0,$W12)))*(1+2*(($Z13-IF($W13="",0,$W13))/($Z12-IF($W12="",0,$W12))-1))),IF($X12="","",$X12))) | Y13: =IF($A13="","",IFERROR(IF(OR($S13="",$S12="",$Y12="",$S12=0),IF($Y12="","",$Y12),$S13+($Y12-$S12)*(1+2*($S13/$S12-1))),IF($Y12="","",$Y12))) | Z13: =IF($S13="","",$S13+IF($U13="",0,$U13)+IF($V13="",0,$V13)) | AA13: =SUMIFS('09_CF_원금'!$E$6:$E$92,'09_CF_원금'!$D$6:$D$92,"국장",'09_CF_원금'!$A$6:$A$92,"<="&$A13)-SUMIFS('09_CF_원금'!$E$6:$E$92,'09_CF_원금'!$C$6:$C$92,"국장",'09_CF_원금'!$A$6:$A$92,"<="&$A13) -> 130000000 | AB13: =SUMIFS('09_CF_원금'!$E$6:$E$92,'09_CF_원금'!$D$6:$D$92,"미장",'09_CF_원금'!$A$6:$A$92,"<="&$A13)-SUMIFS('09_CF_원금'!$E$6:$E$92,'09_CF_원금'!$C$6:$C$92,"미장",'09_CF_원금'!$A$6:$A$92,"<="&$A13) -> 150000000 | AC13: =SUMIFS('09_CF_원금'!$E$6:$E$92,'09_CF_원금'!$D$6:$D$92,"ISA",'09_CF_원금'!$A$6:$A$92,"<="&$A13)-SUMIFS('09_CF_원금'!$E$6:$E$92,'09_CF_원금'!$C$6:$C$92,"ISA",'09_CF_원금'!$A$6:$A$92,"<="&$A13) -> 40000000 | AD13: =IF($A13="","",$AA13+$AB13+$AC13+SUMIFS('09_CF_원금'!$E$6:$E$92,'09_CF_원금'!$D$6:$D$92,"중국",'09_CF_원금'!$A$6:$A$92,"<="&$A13)-SUMIFS('09_CF_원금'!$E$6:$E$92,'09_CF_원금'!$C$6:$C$92,"중국",'09_CF_원금'!$A$6:$A$92,"<="&$A13)) -> 343000000 | AE13: =IF($B13="","",MAX($B$5:$B13)) | AF13: 25574.75 | AH13: 100089765 | AI13: 23580388 | AK13: =IF($A13="","",YEAR($A13)*100+MONTH($A13)) -> 202512 | AL13: =IF($P13="","",IF($P13="😱 극도의 공포",-2,IF($P13="😨 공포",-1,IF($P13="😐 평온",0,IF($P13="😃 탐욕",1,IF($P13="🤑 극도의 탐욕",2,""))))))
A14: 46017 | B14: =IF($A14="","",IF(AND($T14<>"",$U14<>"",$V14<>""),$T14+$U14+$V14,IF(AND($Z14<>"",$G14<>""),$Z14-$G14,IF($AG14<>"",$AD14+$AG14,"")))) | C14: =IF($B14="","",IFERROR($B14-LOOKUP(2,1/($B$5:$B13<>""),$B$5:$B13),"")) | D14: =IF(OR($B14="",$AD14=""),"",$B14-$AD14) | E14: =IF(OR($B14="",$AE14=0,$AE14=""),"",MIN(0,$B14/$AE14-1)) | F14: =IF(OR($Y14="",$Y14=0,$G14="",$G14=0),"",($S14-$G14*'03_포지션'!$B$13)/$Y14) | G14: =IF(OR($S14="",$T14=""),"",$S14-$T14) | H14: =IF(OR($X14="",$Z14=""),"",$X14-($Z14-IF($W14="",0,$W14))) | I14: =IF(OR($G14="",$H14=""),"",$G14+$H14) | J14: =IF(OR($I14="",'09_CF_원금'!$B$108=0),"",$I14/'09_CF_원금'!$B$108) | K14: =IF(OR($X14="",$X14=0,$I14=""),"",$I14/$X14) | L14: =IF(OR($W14="",$X14=""),"",$W14/($X14+$W14)) | M14: =IF($T14<>"",$T14-$AA14,IF($AH14<>"",$AH14,"")) -> 104193269 | N14: =IF($U14<>"",$U14-$AB14,IF($AI14<>"",$AI14,"")) -> 31850948 | O14: =IF($V14<>"",$V14-$AC14,IF($AJ14<>"",$AJ14,"")) | W14: =IF($A14="","",IF($W13="","",$W13)) | X14: =IF($A14="","",IFERROR(IF(OR($Z14="",$Z13="",$X13="",($Z13-IF($W13="",0,$W13))=0),IF($X13="","",$X13),($Z14-IF($W14="",0,$W14))+($X13-($Z13-IF($W13="",0,$W13)))*(1+2*(($Z14-IF($W14="",0,$W14))/($Z13-IF($W13="",0,$W13))-1))),IF($X13="","",$X13))) | Y14: =IF($A14="","",IFERROR(IF(OR($S14="",$S13="",$Y13="",$S13=0),IF($Y13="","",$Y13),$S14+($Y13-$S13)*(1+2*($S14/$S13-1))),IF($Y13="","",$Y13))) | Z14: =IF($S14="","",$S14+IF($U14="",0,$U14)+IF($V14="",0,$V14)) | AA14: =SUMIFS('09_CF_원금'!$E$6:$E$92,'09_CF_원금'!$D$6:$D$92,"국장",'09_CF_원금'!$A$6:$A$92,"<="&$A14)-SUMIFS('09_CF_원금'!$E$6:$E$92,'09_CF_원금'!$C$6:$C$92,"국장",'09_CF_원금'!$A$6:$A$92,"<="&$A14) -> 130000000 | AB14: =SUMIFS('09_CF_원금'!$E$6:$E$92,'09_CF_원금'!$D$6:$D$92,"미장",'09_CF_원금'!$A$6:$A$92,"<="&$A14)-SUMIFS('09_CF_원금'!$E$6:$E$92,'09_CF_원금'!$C$6:$C$92,"미장",'09_CF_원금'!$A$6:$A$92,"<="&$A14) -> 150000000 | AC14: =SUMIFS('09_CF_원금'!$E$6:$E$92,'09_CF_원금'!$D$6:$D$92,"ISA",'09_CF_원금'!$A$6:$A$92,"<="&$A14)-SUMIFS('09_CF_원금'!$E$6:$E$92,'09_CF_원금'!$C$6:$C$92,"ISA",'09_CF_원금'!$A$6:$A$92,"<="&$A14) -> 40000000 | AD14: =IF($A14="","",$AA14+$AB14+$AC14+SUMIFS('09_CF_원금'!$E$6:$E$92,'09_CF_원금'!$D$6:$D$92,"중국",'09_CF_원금'!$A$6:$A$92,"<="&$A14)-SUMIFS('09_CF_원금'!$E$6:$E$92,'09_CF_원금'!$C$6:$C$92,"중국",'09_CF_원금'!$A$6:$A$92,"<="&$A14)) -> 340000000 | AE14: =IF($B14="","",MAX($B$5:$B14)) | AF14: 25863 | AH14: 104193269 | AI14: 31850948 | AK14: =IF($A14="","",YEAR($A14)*100+MONTH($A14)) -> 202512 | AL14: =IF($P14="","",IF($P14="😱 극도의 공포",-2,IF($P14="😨 공포",-1,IF($P14="😐 평온",0,IF($P14="😃 탐욕",1,IF($P14="🤑 극도의 탐욕",2,""))))))
A15: 46022 | B15: =IF($A15="","",IF(AND($T15<>"",$U15<>"",$V15<>""),$T15+$U15+$V15,IF(AND($Z15<>"",$G15<>""),$Z15-$G15,IF($AG15<>"",$AD15+$AG15,"")))) -> 482830222 | C15: =IF($B15="","",IFERROR($B15-LOOKUP(2,1/($B$5:$B14<>""),$B$5:$B14),"")) | D15: =IF(OR($B15="",$AD15=""),"",$B15-$AD15) -> 142830222 | E15: =IF(OR($B15="",$AE15=0,$AE15=""),"",MIN(0,$B15/$AE15-1)) -> 0 | F15: =IF(OR($Y15="",$Y15=0,$G15="",$G15=0),"",($S15-$G15*'03_포지션'!$B$13)/$Y15) | G15: =IF(OR($S15="",$T15=""),"",$S15-$T15) | H15: =IF(OR($X15="",$Z15=""),"",$X15-($Z15-IF($W15="",0,$W15))) | I15: =IF(OR($G15="",$H15=""),"",$G15+$H15) | J15: =IF(OR($I15="",'09_CF_원금'!$B$108=0),"",$I15/'09_CF_원금'!$B$108) | K15: =IF(OR($X15="",$X15=0,$I15=""),"",$I15/$X15) | L15: =IF(OR($W15="",$X15=""),"",$W15/($X15+$W15)) | M15: =IF($T15<>"",$T15-$AA15,IF($AH15<>"",$AH15,"")) -> 110805230 | N15: =IF($U15<>"",$U15-$AB15,IF($AI15<>"",$AI15,"")) -> 27430808 | O15: =IF($V15<>"",$V15-$AC15,IF($AJ15<>"",$AJ15,"")) -> 4594184 | R15: '25년 마감 | W15: =IF($A15="","",IF($W14="","",$W14)) | X15: =IF($A15="","",IFERROR(IF(OR($Z15="",$Z14="",$X14="",($Z14-IF($W14="",0,$W14))=0),IF($X14="","",$X14),($Z15-IF($W15="",0,$W15))+($X14-($Z14-IF($W14="",0,$W14)))*(1+2*(($Z15-IF($W15="",0,$W15))/($Z14-IF($W14="",0,$W14))-1))),IF($X14="","",$X14))) | Y15: =IF($A15="","",IFERROR(IF(OR($S15="",$S14="",$Y14="",$S14=0),IF($Y14="","",$Y14),$S15+($Y14-$S14)*(1+2*($S15/$S14-1))),IF($Y14="","",$Y14))) | Z15: =IF($S15="","",$S15+IF($U15="",0,$U15)+IF($V15="",0,$V15)) | AA15: =SUMIFS('09_CF_원금'!$E$6:$E$92,'09_CF_원금'!$D$6:$D$92,"국장",'09_CF_원금'!$A$6:$A$92,"<="&$A15)-SUMIFS('09_CF_원금'!$E$6:$E$92,'09_CF_원금'!$C$6:$C$92,"국장",'09_CF_원금'!$A$6:$A$92,"<="&$A15) -> 130000000 | AB15: =SUMIFS('09_CF_원금'!$E$6:$E$92,'09_CF_원금'!$D$6:$D$92,"미장",'09_CF_원금'!$A$6:$A$92,"<="&$A15)-SUMIFS('09_CF_원금'!$E$6:$E$92,'09_CF_원금'!$C$6:$C$92,"미장",'09_CF_원금'!$A$6:$A$92,"<="&$A15) -> 150000000 | AC15: =SUMIFS('09_CF_원금'!$E$6:$E$92,'09_CF_원금'!$D$6:$D$92,"ISA",'09_CF_원금'!$A$6:$A$92,"<="&$A15)-SUMIFS('09_CF_원금'!$E$6:$E$92,'09_CF_원금'!$C$6:$C$92,"ISA",'09_CF_원금'!$A$6:$A$92,"<="&$A15) -> 40000000 | AD15: =IF($A15="","",$AA15+$AB15+$AC15+SUMIFS('09_CF_원금'!$E$6:$E$92,'09_CF_원금'!$D$6:$D$92,"중국",'09_CF_원금'!$A$6:$A$92,"<="&$A15)-SUMIFS('09_CF_원금'!$E$6:$E$92,'09_CF_원금'!$C$6:$C$92,"중국",'09_CF_원금'!$A$6:$A$92,"<="&$A15)) -> 340000000 | AE15: =IF($B15="","",MAX($B$5:$B15)) -> 482830222 | AF15: 25456.75 | AG15: 142830222 | AH15: 110805230 | AI15: 27430808 | AJ15: 4594184 | AK15: =IF($A15="","",YEAR($A15)*100+MONTH($A15)) -> 202512 | AL15: =IF($P15="","",IF($P15="😱 극도의 공포",-2,IF($P15="😨 공포",-1,IF($P15="😐 평온",0,IF($P15="😃 탐욕",1,IF($P15="🤑 극도의 탐욕",2,""))))))
A16: 46023 | B16: =IF($A16="","",IF(AND($T16<>"",$U16<>"",$V16<>""),$T16+$U16+$V16,IF(AND($Z16<>"",$G16<>""),$Z16-$G16,IF($AG16<>"",$AD16+$AG16,"")))) | C16: =IF($B16="","",IFERROR($B16-LOOKUP(2,1/($B$5:$B15<>""),$B$5:$B15),"")) | D16: =IF(OR($B16="",$AD16=""),"",$B16-$AD16) | E16: =IF(OR($B16="",$AE16=0,$AE16=""),"",MIN(0,$B16/$AE16-1)) | F16: =IF(OR($Y16="",$Y16=0,$G16="",$G16=0),"",($S16-$G16*'03_포지션'!$B$13)/$Y16) | G16: =IF(OR($S16="",$T16=""),"",$S16-$T16) | H16: =IF(OR($X16="",$Z16=""),"",$X16-($Z16-IF($W16="",0,$W16))) | I16: =IF(OR($G16="",$H16=""),"",$G16+$H16) | J16: =IF(OR($I16="",'09_CF_원금'!$B$108=0),"",$I16/'09_CF_원금'!$B$108) | K16: =IF(OR($X16="",$X16=0,$I16=""),"",$I16/$X16) | L16: =IF(OR($W16="",$X16=""),"",$W16/($X16+$W16)) | M16: =IF($T16<>"",$T16-$AA16,IF($AH16<>"",$AH16,"")) | N16: =IF($U16<>"",$U16-$AB16,IF($AI16<>"",$AI16,"")) | O16: =IF($V16<>"",$V16-$AC16,IF($AJ16<>"",$AJ16,"")) | W16: =IF($A16="","",IF($W15="","",$W15)) | X16: =IF($A16="","",IFERROR(IF(OR($Z16="",$Z15="",$X15="",($Z15-IF($W15="",0,$W15))=0),IF($X15="","",$X15),($Z16-IF($W16="",0,$W16))+($X15-($Z15-IF($W15="",0,$W15)))*(1+2*(($Z16-IF($W16="",0,$W16))/($Z15-IF($W15="",0,$W15))-1))),IF($X15="","",$X15))) | Y16: =IF($A16="","",IFERROR(IF(OR($S16="",$S15="",$Y15="",$S15=0),IF($Y15="","",$Y15),$S16+($Y15-$S15)*(1+2*($S16/$S15-1))),IF($Y15="","",$Y15))) | Z16: =IF($S16="","",$S16+IF($U16="",0,$U16)+IF($V16="",0,$V16)) | AA16: =SUMIFS('09_CF_원금'!$E$6:$E$92,'09_CF_원금'!$D$6:$D$92,"국장",'09_CF_원금'!$A$6:$A$92,"<="&$A16)-SUMIFS('09_CF_원금'!$E$6:$E$92,'09_CF_원금'!$C$6:$C$92,"국장",'09_CF_원금'!$A$6:$A$92,"<="&$A16) -> 130000000 | AB16: =SUMIFS('09_CF_원금'!$E$6:$E$92,'09_CF_원금'!$D$6:$D$92,"미장",'09_CF_원금'!$A$6:$A$92,"<="&$A16)-SUMIFS('09_CF_원금'!$E$6:$E$92,'09_CF_원금'!$C$6:$C$92,"미장",'09_CF_원금'!$A$6:$A$92,"<="&$A16) -> 150000000 | AC16: =SUMIFS('09_CF_원금'!$E$6:$E$92,'09_CF_원금'!$D$6:$D$92,"ISA",'09_CF_원금'!$A$6:$A$92,"<="&$A16)-SUMIFS('09_CF_원금'!$E$6:$E$92,'09_CF_원금'!$C$6:$C$92,"ISA",'09_CF_원금'!$A$6:$A$92,"<="&$A16) -> 40000000 | AD16: =IF($A16="","",$AA16+$AB16+$AC16+SUMIFS('09_CF_원금'!$E$6:$E$92,'09_CF_원금'!$D$6:$D$92,"중국",'09_CF_원금'!$A$6:$A$92,"<="&$A16)-SUMIFS('09_CF_원금'!$E$6:$E$92,'09_CF_원금'!$C$6:$C$92,"중국",'09_CF_원금'!$A$6:$A$92,"<="&$A16)) -> 340000000 | AE16: =IF($B16="","",MAX($B$5:$B16)) | AK16: =IF($A16="","",YEAR($A16)*100+MONTH($A16)) -> 202601 | AL16: =IF($P16="","",IF($P16="😱 극도의 공포",-2,IF($P16="😨 공포",-1,IF($P16="😐 평온",0,IF($P16="😃 탐욕",1,IF($P16="🤑 극도의 탐욕",2,""))))))
A17: 46024 | B17: =IF($A17="","",IF(AND($T17<>"",$U17<>"",$V17<>""),$T17+$U17+$V17,IF(AND($Z17<>"",$G17<>""),$Z17-$G17,IF($AG17<>"",$AD17+$AG17,"")))) -> 491585850 | C17: =IF($B17="","",IFERROR($B17-LOOKUP(2,1/($B$5:$B16<>""),$B$5:$B16),"")) | D17: =IF(OR($B17="",$AD17=""),"",$B17-$AD17) -> 151585850 | E17: =IF(OR($B17="",$AE17=0,$AE17=""),"",MIN(0,$B17/$AE17-1)) -> 0 | F17: =IF(OR($Y17="",$Y17=0,$G17="",$G17=0),"",($S17-$G17*'03_포지션'!$B$13)/$Y17) | G17: =IF(OR($S17="",$T17=""),"",$S17-$T17) | H17: =IF(OR($X17="",$Z17=""),"",$X17-($Z17-IF($W17="",0,$W17))) | I17: =IF(OR($G17="",$H17=""),"",$G17+$H17) | J17: =IF(OR($I17="",'09_CF_원금'!$B$108=0),"",$I17/'09_CF_원금'!$B$108) | K17: =IF(OR($X17="",$X17=0,$I17=""),"",$I17/$X17) | L17: =IF(OR($W17="",$X17=""),"",$W17/($X17+$W17)) | M17: =IF($T17<>"",$T17-$AA17,IF($AH17<>"",$AH17,"")) -> 113696755 | N17: =IF($U17<>"",$U17-$AB17,IF($AI17<>"",$AI17,"")) -> 31925364 | O17: =IF($V17<>"",$V17-$AC17,IF($AJ17<>"",$AJ17,"")) -> 5280829 | W17: =IF($A17="","",IF($W16="","",$W16)) | X17: =IF($A17="","",IFERROR(IF(OR($Z17="",$Z16="",$X16="",($Z16-IF($W16="",0,$W16))=0),IF($X16="","",$X16),($Z17-IF($W17="",0,$W17))+($X16-($Z16-IF($W16="",0,$W16)))*(1+2*(($Z17-IF($W17="",0,$W17))/($Z16-IF($W16="",0,$W16))-1))),IF($X16="","",$X16))) | Y17: =IF($A17="","",IFERROR(IF(OR($S17="",$S16="",$Y16="",$S16=0),IF($Y16="","",$Y16),$S17+($Y16-$S16)*(1+2*($S17/$S16-1))),IF($Y16="","",$Y16))) | Z17: =IF($S17="","",$S17+IF($U17="",0,$U17)+IF($V17="",0,$V17)) | AA17: =SUMIFS('09_CF_원금'!$E$6:$E$92,'09_CF_원금'!$D$6:$D$92,"국장",'09_CF_원금'!$A$6:$A$92,"<="&$A17)-SUMIFS('09_CF_원금'!$E$6:$E$92,'09_CF_원금'!$C$6:$C$92,"국장",'09_CF_원금'!$A$6:$A$92,"<="&$A17) -> 130000000 | AB17: =SUMIFS('09_CF_원금'!$E$6:$E$92,'09_CF_원금'!$D$6:$D$92,"미장",'09_CF_원금'!$A$6:$A$92,"<="&$A17)-SUMIFS('09_CF_원금'!$E$6:$E$92,'09_CF_원금'!$C$6:$C$92,"미장",'09_CF_원금'!$A$6:$A$92,"<="&$A17) -> 150000000 | AC17: =SUMIFS('09_CF_원금'!$E$6:$E$92,'09_CF_원금'!$D$6:$D$92,"ISA",'09_CF_원금'!$A$6:$A$92,"<="&$A17)-SUMIFS('09_CF_원금'!$E$6:$E$92,'09_CF_원금'!$C$6:$C$92,"ISA",'09_CF_원금'!$A$6:$A$92,"<="&$A17) -> 40000000 | AD17: =IF($A17="","",$AA17+$AB17+$AC17+SUMIFS('09_CF_원금'!$E$6:$E$92,'09_CF_원금'!$D$6:$D$92,"중국",'09_CF_원금'!$A$6:$A$92,"<="&$A17)-SUMIFS('09_CF_원금'!$E$6:$E$92,'09_CF_원금'!$C$6:$C$92,"중국",'09_CF_원금'!$A$6:$A$92,"<="&$A17)) -> 340000000 | AE17: =IF($B17="","",MAX($B$5:$B17)) -> 491585850 | AF17: 25385.25 | AG17: 151585850 | AH17: 113696755 | AI17: 31925364 | AJ17: 5280829 | AK17: =IF($A17="","",YEAR($A17)*100+MONTH($A17)) -> 202601 | AL17: =IF($P17="","",IF($P17="😱 극도의 공포",-2,IF($P17="😨 공포",-1,IF($P17="😐 평온",0,IF($P17="😃 탐욕",1,IF($P17="🤑 극도의 탐욕",2,""))))))
A18: 46027 | B18: =IF($A18="","",IF(AND($T18<>"",$U18<>"",$V18<>""),$T18+$U18+$V18,IF(AND($Z18<>"",$G18<>""),$Z18-$G18,IF($AG18<>"",$AD18+$AG18,"")))) | C18: =IF($B18="","",IFERROR($B18-LOOKUP(2,1/($B$5:$B17<>""),$B$5:$B17),"")) | D18: =IF(OR($B18="",$AD18=""),"",$B18-$AD18) | E18: =IF(OR($B18="",$AE18=0,$AE18=""),"",MIN(0,$B18/$AE18-1)) | F18: =IF(OR($Y18="",$Y18=0,$G18="",$G18=0),"",($S18-$G18*'03_포지션'!$B$13)/$Y18) | G18: =IF(OR($S18="",$T18=""),"",$S18-$T18) | H18: =IF(OR($X18="",$Z18=""),"",$X18-($Z18-IF($W18="",0,$W18))) | I18: =IF(OR($G18="",$H18=""),"",$G18+$H18) | J18: =IF(OR($I18="",'09_CF_원금'!$B$108=0),"",$I18/'09_CF_원금'!$B$108) | K18: =IF(OR($X18="",$X18=0,$I18=""),"",$I18/$X18) | L18: =IF(OR($W18="",$X18=""),"",$W18/($X18+$W18)) | M18: =IF($T18<>"",$T18-$AA18,IF($AH18<>"",$AH18,"")) | N18: =IF($U18<>"",$U18-$AB18,IF($AI18<>"",$AI18,"")) | O18: =IF($V18<>"",$V18-$AC18,IF($AJ18<>"",$AJ18,"")) | W18: =IF($A18="","",IF($W17="","",$W17)) | X18: =IF($A18="","",IFERROR(IF(OR($Z18="",$Z17="",$X17="",($Z17-IF($W17="",0,$W17))=0),IF($X17="","",$X17),($Z18-IF($W18="",0,$W18))+($X17-($Z17-IF($W17="",0,$W17)))*(1+2*(($Z18-IF($W18="",0,$W18))/($Z17-IF($W17="",0,$W17))-1))),IF($X17="","",$X17))) | Y18: =IF($A18="","",IFERROR(IF(OR($S18="",$S17="",$Y17="",$S17=0),IF($Y17="","",$Y17),$S18+($Y17-$S17)*(1+2*($S18/$S17-1))),IF($Y17="","",$Y17))) | Z18: =IF($S18="","",$S18+IF($U18="",0,$U18)+IF($V18="",0,$V18)) | AA18: =SUMIFS('09_CF_원금'!$E$6:$E$92,'09_CF_원금'!$D$6:$D$92,"국장",'09_CF_원금'!$A$6:$A$92,"<="&$A18)-SUMIFS('09_CF_원금'!$E$6:$E$92,'09_CF_원금'!$C$6:$C$92,"국장",'09_CF_원금'!$A$6:$A$92,"<="&$A18) -> 130000000 | AB18: =SUMIFS('09_CF_원금'!$E$6:$E$92,'09_CF_원금'!$D$6:$D$92,"미장",'09_CF_원금'!$A$6:$A$92,"<="&$A18)-SUMIFS('09_CF_원금'!$E$6:$E$92,'09_CF_원금'!$C$6:$C$92,"미장",'09_CF_원금'!$A$6:$A$92,"<="&$A18) -> 150000000 | AC18: =SUMIFS('09_CF_원금'!$E$6:$E$92,'09_CF_원금'!$D$6:$D$92,"ISA",'09_CF_원금'!$A$6:$A$92,"<="&$A18)-SUMIFS('09_CF_원금'!$E$6:$E$92,'09_CF_원금'!$C$6:$C$92,"ISA",'09_CF_원금'!$A$6:$A$92,"<="&$A18) -> 40000000 | AD18: =IF($A18="","",$AA18+$AB18+$AC18+SUMIFS('09_CF_원금'!$E$6:$E$92,'09_CF_원금'!$D$6:$D$92,"중국",'09_CF_원금'!$A$6:$A$92,"<="&$A18)-SUMIFS('09_CF_원금'!$E$6:$E$92,'09_CF_원금'!$C$6:$C$92,"중국",'09_CF_원금'!$A$6:$A$92,"<="&$A18)) -> 340000000 | AE18: =IF($B18="","",MAX($B$5:$B18)) | AK18: =IF($A18="","",YEAR($A18)*100+MONTH($A18)) -> 202601 | AL18: =IF($P18="","",IF($P18="😱 극도의 공포",-2,IF($P18="😨 공포",-1,IF($P18="😐 평온",0,IF($P18="😃 탐욕",1,IF($P18="🤑 극도의 탐욕",2,""))))))
A19: 46028 | B19: =IF($A19="","",IF(AND($T19<>"",$U19<>"",$V19<>""),$T19+$U19+$V19,IF(AND($Z19<>"",$G19<>""),$Z19-$G19,IF($AG19<>"",$AD19+$AG19,"")))) -> 518746935 | C19: =IF($B19="","",IFERROR($B19-LOOKUP(2,1/($B$5:$B18<>""),$B$5:$B18),"")) | D19: =IF(OR($B19="",$AD19=""),"",$B19-$AD19) -> 178746935 | E19: =IF(OR($B19="",$AE19=0,$AE19=""),"",MIN(0,$B19/$AE19-1)) -> 0 | F19: =IF(OR($Y19="",$Y19=0,$G19="",$G19=0),"",($S19-$G19*'03_포지션'!$B$13)/$Y19) | G19: =IF(OR($S19="",$T19=""),"",$S19-$T19) | H19: =IF(OR($X19="",$Z19=""),"",$X19-($Z19-IF($W19="",0,$W19))) | I19: =IF(OR($G19="",$H19=""),"",$G19+$H19) | J19: =IF(OR($I19="",'09_CF_원금'!$B$108=0),"",$I19/'09_CF_원금'!$B$108) | K19: =IF(OR($X19="",$X19=0,$I19=""),"",$I19/$X19) | L19: =IF(OR($W19="",$X19=""),"",$W19/($X19+$W19)) | M19: =IF($T19<>"",$T19-$AA19,IF($AH19<>"",$AH19,"")) -> 133878053 | N19: =IF($U19<>"",$U19-$AB19,IF($AI19<>"",$AI19,"")) -> 37408859 | O19: =IF($V19<>"",$V19-$AC19,IF($AJ19<>"",$AJ19,"")) -> 6973590 | W19: =IF($A19="","",IF($W18="","",$W18)) | X19: =IF($A19="","",IFERROR(IF(OR($Z19="",$Z18="",$X18="",($Z18-IF($W18="",0,$W18))=0),IF($X18="","",$X18),($Z19-IF($W19="",0,$W19))+($X18-($Z18-IF($W18="",0,$W18)))*(1+2*(($Z19-IF($W19="",0,$W19))/($Z18-IF($W18="",0,$W18))-1))),IF($X18="","",$X18))) | Y19: =IF($A19="","",IFERROR(IF(OR($S19="",$S18="",$Y18="",$S18=0),IF($Y18="","",$Y18),$S19+($Y18-$S18)*(1+2*($S19/$S18-1))),IF($Y18="","",$Y18))) | Z19: =IF($S19="","",$S19+IF($U19="",0,$U19)+IF($V19="",0,$V19)) | AA19: =SUMIFS('09_CF_원금'!$E$6:$E$92,'09_CF_원금'!$D$6:$D$92,"국장",'09_CF_원금'!$A$6:$A$92,"<="&$A19)-SUMIFS('09_CF_원금'!$E$6:$E$92,'09_CF_원금'!$C$6:$C$92,"국장",'09_CF_원금'!$A$6:$A$92,"<="&$A19) -> 130000000 | AB19: =SUMIFS('09_CF_원금'!$E$6:$E$92,'09_CF_원금'!$D$6:$D$92,"미장",'09_CF_원금'!$A$6:$A$92,"<="&$A19)-SUMIFS('09_CF_원금'!$E$6:$E$92,'09_CF_원금'!$C$6:$C$92,"미장",'09_CF_원금'!$A$6:$A$92,"<="&$A19) -> 150000000 | AC19: =SUMIFS('09_CF_원금'!$E$6:$E$92,'09_CF_원금'!$D$6:$D$92,"ISA",'09_CF_원금'!$A$6:$A$92,"<="&$A19)-SUMIFS('09_CF_원금'!$E$6:$E$92,'09_CF_원금'!$C$6:$C$92,"ISA",'09_CF_원금'!$A$6:$A$92,"<="&$A19) -> 40000000 | AD19: =IF($A19="","",$AA19+$AB19+$AC19+SUMIFS('09_CF_원금'!$E$6:$E$92,'09_CF_원금'!$D$6:$D$92,"중국",'09_CF_원금'!$A$6:$A$92,"<="&$A19)-SUMIFS('09_CF_원금'!$E$6:$E$92,'09_CF_원금'!$C$6:$C$92,"중국",'09_CF_원금'!$A$6:$A$92,"<="&$A19)) -> 340000000 | AE19: =IF($B19="","",MAX($B$5:$B19)) -> 518746935 | AF19: 25830 | AG19: 178746935 | AH19: 133878053 | AI19: 37408859 | AJ19: 6973590 | AK19: =IF($A19="","",YEAR($A19)*100+MONTH($A19)) -> 202601 | AL19: =IF($P19="","",IF($P19="😱 극도의 공포",-2,IF($P19="😨 공포",-1,IF($P19="😐 평온",0,IF($P19="😃 탐욕",1,IF($P19="🤑 극도의 탐욕",2,""))))))
A20: 46029 | B20: =IF($A20="","",IF(AND($T20<>"",$U20<>"",$V20<>""),$T20+$U20+$V20,IF(AND($Z20<>"",$G20<>""),$Z20-$G20,IF($AG20<>"",$AD20+$AG20,"")))) | C20: =IF($B20="","",IFERROR($B20-LOOKUP(2,1/($B$5:$B19<>""),$B$5:$B19),"")) | D20: =IF(OR($B20="",$AD20=""),"",$B20-$AD20) | E20: =IF(OR($B20="",$AE20=0,$AE20=""),"",MIN(0,$B20/$AE20-1)) | F20: =IF(OR($Y20="",$Y20=0,$G20="",$G20=0),"",($S20-$G20*'03_포지션'!$B$13)/$Y20) | G20: =IF(OR($S20="",$T20=""),"",$S20-$T20) | H20: =IF(OR($X20="",$Z20=""),"",$X20-($Z20-IF($W20="",0,$W20))) | I20: =IF(OR($G20="",$H20=""),"",$G20+$H20) | J20: =IF(OR($I20="",'09_CF_원금'!$B$108=0),"",$I20/'09_CF_원금'!$B$108) | K20: =IF(OR($X20="",$X20=0,$I20=""),"",$I20/$X20) | L20: =IF(OR($W20="",$X20=""),"",$W20/($X20+$W20)) | M20: =IF($T20<>"",$T20-$AA20,IF($AH20<>"",$AH20,"")) | N20: =IF($U20<>"",$U20-$AB20,IF($AI20<>"",$AI20,"")) | O20: =IF($V20<>"",$V20-$AC20,IF($AJ20<>"",$AJ20,"")) | W20: =IF($A20="","",IF($W19="","",$W19)) | X20: =IF($A20="","",IFERROR(IF(OR($Z20="",$Z19="",$X19="",($Z19-IF($W19="",0,$W19))=0),IF($X19="","",$X19),($Z20-IF($W20="",0,$W20))+($X19-($Z19-IF($W19="",0,$W19)))*(1+2*(($Z20-IF($W20="",0,$W20))/($Z19-IF($W19="",0,$W19))-1))),IF($X19="","",$X19))) | Y20: =IF($A20="","",IFERROR(IF(OR($S20="",$S19="",$Y19="",$S19=0),IF($Y19="","",$Y19),$S20+($Y19-$S19)*(1+2*($S20/$S19-1))),IF($Y19="","",$Y19))) | Z20: =IF($S20="","",$S20+IF($U20="",0,$U20)+IF($V20="",0,$V20)) | AA20: =SUMIFS('09_CF_원금'!$E$6:$E$92,'09_CF_원금'!$D$6:$D$92,"국장",'09_CF_원금'!$A$6:$A$92,"<="&$A20)-SUMIFS('09_CF_원금'!$E$6:$E$92,'09_CF_원금'!$C$6:$C$92,"국장",'09_CF_원금'!$A$6:$A$92,"<="&$A20) -> 130000000 | AB20: =SUMIFS('09_CF_원금'!$E$6:$E$92,'09_CF_원금'!$D$6:$D$92,"미장",'09_CF_원금'!$A$6:$A$92,"<="&$A20)-SUMIFS('09_CF_원금'!$E$6:$E$92,'09_CF_원금'!$C$6:$C$92,"미장",'09_CF_원금'!$A$6:$A$92,"<="&$A20) -> 150000000 | AC20: =SUMIFS('09_CF_원금'!$E$6:$E$92,'09_CF_원금'!$D$6:$D$92,"ISA",'09_CF_원금'!$A$6:$A$92,"<="&$A20)-SUMIFS('09_CF_원금'!$E$6:$E$92,'09_CF_원금'!$C$6:$C$92,"ISA",'09_CF_원금'!$A$6:$A$92,"<="&$A20) -> 40000000 | AD20: =IF($A20="","",$AA20+$AB20+$AC20+SUMIFS('09_CF_원금'!$E$6:$E$92,'09_CF_원금'!$D$6:$D$92,"중국",'09_CF_원금'!$A$6:$A$92,"<="&$A20)-SUMIFS('09_CF_원금'!$E$6:$E$92,'09_CF_원금'!$C$6:$C$92,"중국",'09_CF_원금'!$A$6:$A$92,"<="&$A20)) -> 340000000 | AE20: =IF($B20="","",MAX($B$5:$B20)) | AK20: =IF($A20="","",YEAR($A20)*100+MONTH($A20)) -> 202601 | AL20: =IF($P20="","",IF($P20="😱 극도의 공포",-2,IF($P20="😨 공포",-1,IF($P20="😐 평온",0,IF($P20="😃 탐욕",1,IF($P20="🤑 극도의 탐욕",2,""))))))
A21: 46030 | B21: =IF($A21="","",IF(AND($T21<>"",$U21<>"",$V21<>""),$T21+$U21+$V21,IF(AND($Z21<>"",$G21<>""),$Z21-$G21,IF($AG21<>"",$AD21+$AG21,"")))) | C21: =IF($B21="","",IFERROR($B21-LOOKUP(2,1/($B$5:$B20<>""),$B$5:$B20),"")) | D21: =IF(OR($B21="",$AD21=""),"",$B21-$AD21) | E21: =IF(OR($B21="",$AE21=0,$AE21=""),"",MIN(0,$B21/$AE21-1)) | F21: =IF(OR($Y21="",$Y21=0,$G21="",$G21=0),"",($S21-$G21*'03_포지션'!$B$13)/$Y21) | G21: =IF(OR($S21="",$T21=""),"",$S21-$T21) | H21: =IF(OR($X21="",$Z21=""),"",$X21-($Z21-IF($W21="",0,$W21))) | I21: =IF(OR($G21="",$H21=""),"",$G21+$H21) | J21: =IF(OR($I21="",'09_CF_원금'!$B$108=0),"",$I21/'09_CF_원금'!$B$108) | K21: =IF(OR($X21="",$X21=0,$I21=""),"",$I21/$X21) | L21: =IF(OR($W21="",$X21=""),"",$W21/($X21+$W21)) | M21: =IF($T21<>"",$T21-$AA21,IF($AH21<>"",$AH21,"")) | N21: =IF($U21<>"",$U21-$AB21,IF($AI21<>"",$AI21,"")) | O21: =IF($V21<>"",$V21-$AC21,IF($AJ21<>"",$AJ21,"")) | W21: =IF($A21="","",IF($W20="","",$W20)) | X21: =IF($A21="","",IFERROR(IF(OR($Z21="",$Z20="",$X20="",($Z20-IF($W20="",0,$W20))=0),IF($X20="","",$X20),($Z21-IF($W21="",0,$W21))+($X20-($Z20-IF($W20="",0,$W20)))*(1+2*(($Z21-IF($W21="",0,$W21))/($Z20-IF($W20="",0,$W20))-1))),IF($X20="","",$X20))) | Y21: =IF($A21="","",IFERROR(IF(OR($S21="",$S20="",$Y20="",$S20=0),IF($Y20="","",$Y20),$S21+($Y20-$S20)*(1+2*($S21/$S20-1))),IF($Y20="","",$Y20))) | Z21: =IF($S21="","",$S21+IF($U21="",0,$U21)+IF($V21="",0,$V21)) | AA21: =SUMIFS('09_CF_원금'!$E$6:$E$92,'09_CF_원금'!$D$6:$D$92,"국장",'09_CF_원금'!$A$6:$A$92,"<="&$A21)-SUMIFS('09_CF_원금'!$E$6:$E$92,'09_CF_원금'!$C$6:$C$92,"국장",'09_CF_원금'!$A$6:$A$92,"<="&$A21) -> 130000000 | AB21: =SUMIFS('09_CF_원금'!$E$6:$E$92,'09_CF_원금'!$D$6:$D$92,"미장",'09_CF_원금'!$A$6:$A$92,"<="&$A21)-SUMIFS('09_CF_원금'!$E$6:$E$92,'09_CF_원금'!$C$6:$C$92,"미장",'09_CF_원금'!$A$6:$A$92,"<="&$A21) -> 150000000 | AC21: =SUMIFS('09_CF_원금'!$E$6:$E$92,'09_CF_원금'!$D$6:$D$92,"ISA",'09_CF_원금'!$A$6:$A$92,"<="&$A21)-SUMIFS('09_CF_원금'!$E$6:$E$92,'09_CF_원금'!$C$6:$C$92,"ISA",'09_CF_원금'!$A$6:$A$92,"<="&$A21) -> 40000000 | AD21: =IF($A21="","",$AA21+$AB21+$AC21+SUMIFS('09_CF_원금'!$E$6:$E$92,'09_CF_원금'!$D$6:$D$92,"중국",'09_CF_원금'!$A$6:$A$92,"<="&$A21)-SUMIFS('09_CF_원금'!$E$6:$E$92,'09_CF_원금'!$C$6:$C$92,"중국",'09_CF_원금'!$A$6:$A$92,"<="&$A21)) -> 340000000 | AE21: =IF($B21="","",MAX($B$5:$B21)) | AK21: =IF($A21="","",YEAR($A21)*100+MONTH($A21)) -> 202601 | AL21: =IF($P21="","",IF($P21="😱 극도의 공포",-2,IF($P21="😨 공포",-1,IF($P21="😐 평온",0,IF($P21="😃 탐욕",1,IF($P21="🤑 극도의 탐욕",2,""))))))
A22: 46031 | B22: =IF($A22="","",IF(AND($T22<>"",$U22<>"",$V22<>""),$T22+$U22+$V22,IF(AND($Z22<>"",$G22<>""),$Z22-$G22,IF($AG22<>"",$AD22+$AG22,"")))) -> 540031674 | C22: =IF($B22="","",IFERROR($B22-LOOKUP(2,1/($B$5:$B21<>""),$B$5:$B21),"")) | D22: =IF(OR($B22="",$AD22=""),"",$B22-$AD22) -> 200031674 | E22: =IF(OR($B22="",$AE22=0,$AE22=""),"",MIN(0,$B22/$AE22-1)) -> 0 | F22: =IF(OR($Y22="",$Y22=0,$G22="",$G22=0),"",($S22-$G22*'03_포지션'!$B$13)/$Y22) | G22: =IF(OR($S22="",$T22=""),"",$S22-$T22) | H22: =IF(OR($X22="",$Z22=""),"",$X22-($Z22-IF($W22="",0,$W22))) | I22: =IF(OR($G22="",$H22=""),"",$G22+$H22) | J22: =IF(OR($I22="",'09_CF_원금'!$B$108=0),"",$I22/'09_CF_원금'!$B$108) | K22: =IF(OR($X22="",$X22=0,$I22=""),"",$I22/$X22) | L22: =IF(OR($W22="",$X22=""),"",$W22/($X22+$W22)) | M22: =IF($T22<>"",$T22-$AA22,IF($AH22<>"",$AH22,"")) -> 153648785 | N22: =IF($U22<>"",$U22-$AB22,IF($AI22<>"",$AI22,"")) -> 38710402 | O22: =IF($V22<>"",$V22-$AC22,IF($AJ22<>"",$AJ22,"")) -> 7450286 | W22: =IF($A22="","",IF($W21="","",$W21)) | X22: =IF($A22="","",IFERROR(IF(OR($Z22="",$Z21="",$X21="",($Z21-IF($W21="",0,$W21))=0),IF($X21="","",$X21),($Z22-IF($W22="",0,$W22))+($X21-($Z21-IF($W21="",0,$W21)))*(1+2*(($Z22-IF($W22="",0,$W22))/($Z21-IF($W21="",0,$W21))-1))),IF($X21="","",$X21))) | Y22: =IF($A22="","",IFERROR(IF(OR($S22="",$S21="",$Y21="",$S21=0),IF($Y21="","",$Y21),$S22+($Y21-$S21)*(1+2*($S22/$S21-1))),IF($Y21="","",$Y21))) | Z22: =IF($S22="","",$S22+IF($U22="",0,$U22)+IF($V22="",0,$V22)) | AA22: =SUMIFS('09_CF_원금'!$E$6:$E$92,'09_CF_원금'!$D$6:$D$92,"국장",'09_CF_원금'!$A$6:$A$92,"<="&$A22)-SUMIFS('09_CF_원금'!$E$6:$E$92,'09_CF_원금'!$C$6:$C$92,"국장",'09_CF_원금'!$A$6:$A$92,"<="&$A22) -> 130000000 | AB22: =SUMIFS('09_CF_원금'!$E$6:$E$92,'09_CF_원금'!$D$6:$D$92,"미장",'09_CF_원금'!$A$6:$A$92,"<="&$A22)-SUMIFS('09_CF_원금'!$E$6:$E$92,'09_CF_원금'!$C$6:$C$92,"미장",'09_CF_원금'!$A$6:$A$92,"<="&$A22) -> 150000000 | AC22: =SUMIFS('09_CF_원금'!$E$6:$E$92,'09_CF_원금'!$D$6:$D$92,"ISA",'09_CF_원금'!$A$6:$A$92,"<="&$A22)-SUMIFS('09_CF_원금'!$E$6:$E$92,'09_CF_원금'!$C$6:$C$92,"ISA",'09_CF_원금'!$A$6:$A$92,"<="&$A22) -> 40000000 | AD22: =IF($A22="","",$AA22+$AB22+$AC22+SUMIFS('09_CF_원금'!$E$6:$E$92,'09_CF_원금'!$D$6:$D$92,"중국",'09_CF_원금'!$A$6:$A$92,"<="&$A22)-SUMIFS('09_CF_원금'!$E$6:$E$92,'09_CF_원금'!$C$6:$C$92,"중국",'09_CF_원금'!$A$6:$A$92,"<="&$A22)) -> 340000000 | AE22: =IF($B22="","",MAX($B$5:$B22)) -> 540031674 | AF22: 25938.25 | AG22: 200031674 | AH22: 153648785 | AI22: 38710402 | AJ22: 7450286 | AK22: =IF($A22="","",YEAR($A22)*100+MONTH($A22)) -> 202601 | AL22: =IF($P22="","",IF($P22="😱 극도의 공포",-2,IF($P22="😨 공포",-1,IF($P22="😐 평온",0,IF($P22="😃 탐욕",1,IF($P22="🤑 극도의 탐욕",2,""))))))
A23: 46034 | B23: =IF($A23="","",IF(AND($T23<>"",$U23<>"",$V23<>""),$T23+$U23+$V23,IF(AND($Z23<>"",$G23<>""),$Z23-$G23,IF($AG23<>"",$AD23+$AG23,"")))) | C23: =IF($B23="","",IFERROR($B23-LOOKUP(2,1/($B$5:$B22<>""),$B$5:$B22),"")) | D23: =IF(OR($B23="",$AD23=""),"",$B23-$AD23) | E23: =IF(OR($B23="",$AE23=0,$AE23=""),"",MIN(0,$B23/$AE23-1)) | F23: =IF(OR($Y23="",$Y23=0,$G23="",$G23=0),"",($S23-$G23*'03_포지션'!$B$13)/$Y23) | G23: =IF(OR($S23="",$T23=""),"",$S23-$T23) | H23: =IF(OR($X23="",$Z23=""),"",$X23-($Z23-IF($W23="",0,$W23))) | I23: =IF(OR($G23="",$H23=""),"",$G23+$H23) | J23: =IF(OR($I23="",'09_CF_원금'!$B$108=0),"",$I23/'09_CF_원금'!$B$108) | K23: =IF(OR($X23="",$X23=0,$I23=""),"",$I23/$X23) | L23: =IF(OR($W23="",$X23=""),"",$W23/($X23+$W23)) | M23: =IF($T23<>"",$T23-$AA23,IF($AH23<>"",$AH23,"")) | N23: =IF($U23<>"",$U23-$AB23,IF($AI23<>"",$AI23,"")) | O23: =IF($V23<>"",$V23-$AC23,IF($AJ23<>"",$AJ23,"")) | W23: =IF($A23="","",IF($W22="","",$W22)) | X23: =IF($A23="","",IFERROR(IF(OR($Z23="",$Z22="",$X22="",($Z22-IF($W22="",0,$W22))=0),IF($X22="","",$X22),($Z23-IF($W23="",0,$W23))+($X22-($Z22-IF($W22="",0,$W22)))*(1+2*(($Z23-IF($W23="",0,$W23))/($Z22-IF($W22="",0,$W22))-1))),IF($X22="","",$X22))) | Y23: =IF($A23="","",IFERROR(IF(OR($S23="",$S22="",$Y22="",$S22=0),IF($Y22="","",$Y22),$S23+($Y22-$S22)*(1+2*($S23/$S22-1))),IF($Y22="","",$Y22))) | Z23: =IF($S23="","",$S23+IF($U23="",0,$U23)+IF($V23="",0,$V23)) | AA23: =SUMIFS('09_CF_원금'!$E$6:$E$92,'09_CF_원금'!$D$6:$D$92,"국장",'09_CF_원금'!$A$6:$A$92,"<="&$A23)-SUMIFS('09_CF_원금'!$E$6:$E$92,'09_CF_원금'!$C$6:$C$92,"국장",'09_CF_원금'!$A$6:$A$92,"<="&$A23) -> 130000000 | AB23: =SUMIFS('09_CF_원금'!$E$6:$E$92,'09_CF_원금'!$D$6:$D$92,"미장",'09_CF_원금'!$A$6:$A$92,"<="&$A23)-SUMIFS('09_CF_원금'!$E$6:$E$92,'09_CF_원금'!$C$6:$C$92,"미장",'09_CF_원금'!$A$6:$A$92,"<="&$A23) -> 150000000 | AC23: =SUMIFS('09_CF_원금'!$E$6:$E$92,'09_CF_원금'!$D$6:$D$92,"ISA",'09_CF_원금'!$A$6:$A$92,"<="&$A23)-SUMIFS('09_CF_원금'!$E$6:$E$92,'09_CF_원금'!$C$6:$C$92,"ISA",'09_CF_원금'!$A$6:$A$92,"<="&$A23) -> 40000000 | AD23: =IF($A23="","",$AA23+$AB23+$AC23+SUMIFS('09_CF_원금'!$E$6:$E$92,'09_CF_원금'!$D$6:$D$92,"중국",'09_CF_원금'!$A$6:$A$92,"<="&$A23)-SUMIFS('09_CF_원금'!$E$6:$E$92,'09_CF_원금'!$C$6:$C$92,"중국",'09_CF_원금'!$A$6:$A$92,"<="&$A23)) -> 340000000 | AE23: =IF($B23="","",MAX($B$5:$B23)) | AK23: =IF($A23="","",YEAR($A23)*100+MONTH($A23)) -> 202601 | AL23: =IF($P23="","",IF($P23="😱 극도의 공포",-2,IF($P23="😨 공포",-1,IF($P23="😐 평온",0,IF($P23="😃 탐욕",1,IF($P23="🤑 극도의 탐욕",2,""))))))
A24: 46035 | B24: =IF($A24="","",IF(AND($T24<>"",$U24<>"",$V24<>""),$T24+$U24+$V24,IF(AND($Z24<>"",$G24<>""),$Z24-$G24,IF($AG24<>"",$AD24+$AG24,"")))) -> 527489663 | C24: =IF($B24="","",IFERROR($B24-LOOKUP(2,1/($B$5:$B23<>""),$B$5:$B23),"")) | D24: =IF(OR($B24="",$AD24=""),"",$B24-$AD24) -> 187489663 | E24: =IF(OR($B24="",$AE24=0,$AE24=""),"",MIN(0,$B24/$AE24-1)) -> -0.023224584 | F24: =IF(OR($Y24="",$Y24=0,$G24="",$G24=0),"",($S24-$G24*'03_포지션'!$B$13)/$Y24) | G24: =IF(OR($S24="",$T24=""),"",$S24-$T24) | H24: =IF(OR($X24="",$Z24=""),"",$X24-($Z24-IF($W24="",0,$W24))) | I24: =IF(OR($G24="",$H24=""),"",$G24+$H24) | J24: =IF(OR($I24="",'09_CF_원금'!$B$108=0),"",$I24/'09_CF_원금'!$B$108) | K24: =IF(OR($X24="",$X24=0,$I24=""),"",$I24/$X24) | L24: =IF(OR($W24="",$X24=""),"",$W24/($X24+$W24)) | M24: =IF($T24<>"",$T24-$AA24,IF($AH24<>"",$AH24,"")) -> 133885826 | N24: =IF($U24<>"",$U24-$AB24,IF($AI24<>"",$AI24,"")) -> 45222364 | O24: =IF($V24<>"",$V24-$AC24,IF($AJ24<>"",$AJ24,"")) -> 8381473 | W24: =IF($A24="","",IF($W23="","",$W23)) | X24: =IF($A24="","",IFERROR(IF(OR($Z24="",$Z23="",$X23="",($Z23-IF($W23="",0,$W23))=0),IF($X23="","",$X23),($Z24-IF($W24="",0,$W24))+($X23-($Z23-IF($W23="",0,$W23)))*(1+2*(($Z24-IF($W24="",0,$W24))/($Z23-IF($W23="",0,$W23))-1))),IF($X23="","",$X23))) | Y24: =IF($A24="","",IFERROR(IF(OR($S24="",$S23="",$Y23="",$S23=0),IF($Y23="","",$Y23),$S24+($Y23-$S23)*(1+2*($S24/$S23-1))),IF($Y23="","",$Y23))) | Z24: =IF($S24="","",$S24+IF($U24="",0,$U24)+IF($V24="",0,$V24)) | AA24: =SUMIFS('09_CF_원금'!$E$6:$E$92,'09_CF_원금'!$D$6:$D$92,"국장",'09_CF_원금'!$A$6:$A$92,"<="&$A24)-SUMIFS('09_CF_원금'!$E$6:$E$92,'09_CF_원금'!$C$6:$C$92,"국장",'09_CF_원금'!$A$6:$A$92,"<="&$A24) -> 150000000 | AB24: =SUMIFS('09_CF_원금'!$E$6:$E$92,'09_CF_원금'!$D$6:$D$92,"미장",'09_CF_원금'!$A$6:$A$92,"<="&$A24)-SUMIFS('09_CF_원금'!$E$6:$E$92,'09_CF_원금'!$C$6:$C$92,"미장",'09_CF_원금'!$A$6:$A$92,"<="&$A24) -> 150000000 | AC24: =SUMIFS('09_CF_원금'!$E$6:$E$92,'09_CF_원금'!$D$6:$D$92,"ISA",'09_CF_원금'!$A$6:$A$92,"<="&$A24)-SUMIFS('09_CF_원금'!$E$6:$E$92,'09_CF_원금'!$C$6:$C$92,"ISA",'09_CF_원금'!$A$6:$A$92,"<="&$A24) -> 40000000 | AD24: =IF($A24="","",$AA24+$AB24+$AC24+SUMIFS('09_CF_원금'!$E$6:$E$92,'09_CF_원금'!$D$6:$D$92,"중국",'09_CF_원금'!$A$6:$A$92,"<="&$A24)-SUMIFS('09_CF_원금'!$E$6:$E$92,'09_CF_원금'!$C$6:$C$92,"중국",'09_CF_원금'!$A$6:$A$92,"<="&$A24)) -> 340000000 | AE24: =IF($B24="","",MAX($B$5:$B24)) -> 540031674 | AF24: 25896.75 | AG24: 187489663 | AH24: 133885826 | AI24: 45222364 | AJ24: 8381473 | AK24: =IF($A24="","",YEAR($A24)*100+MONTH($A24)) -> 202601 | AL24: =IF($P24="","",IF($P24="😱 극도의 공포",-2,IF($P24="😨 공포",-1,IF($P24="😐 평온",0,IF($P24="😃 탐욕",1,IF($P24="🤑 극도의 탐욕",2,""))))))
A25: 46036 | B25: =IF($A25="","",IF(AND($T25<>"",$U25<>"",$V25<>""),$T25+$U25+$V25,IF(AND($Z25<>"",$G25<>""),$Z25-$G25,IF($AG25<>"",$AD25+$AG25,"")))) | C25: =IF($B25="","",IFERROR($B25-LOOKUP(2,1/($B$5:$B24<>""),$B$5:$B24),"")) | D25: =IF(OR($B25="",$AD25=""),"",$B25-$AD25) | E25: =IF(OR($B25="",$AE25=0,$AE25=""),"",MIN(0,$B25/$AE25-1)) | F25: =IF(OR($Y25="",$Y25=0,$G25="",$G25=0),"",($S25-$G25*'03_포지션'!$B$13)/$Y25) | G25: =IF(OR($S25="",$T25=""),"",$S25-$T25) | H25: =IF(OR($X25="",$Z25=""),"",$X25-($Z25-IF($W25="",0,$W25))) | I25: =IF(OR($G25="",$H25=""),"",$G25+$H25) | J25: =IF(OR($I25="",'09_CF_원금'!$B$108=0),"",$I25/'09_CF_원금'!$B$108) | K25: =IF(OR($X25="",$X25=0,$I25=""),"",$I25/$X25) | L25: =IF(OR($W25="",$X25=""),"",$W25/($X25+$W25)) | M25: =IF($T25<>"",$T25-$AA25,IF($AH25<>"",$AH25,"")) | N25: =IF($U25<>"",$U25-$AB25,IF($AI25<>"",$AI25,"")) | O25: =IF($V25<>"",$V25-$AC25,IF($AJ25<>"",$AJ25,"")) | W25: =IF($A25="","",IF($W24="","",$W24)) | X25: =IF($A25="","",IFERROR(IF(OR($Z25="",$Z24="",$X24="",($Z24-IF($W24="",0,$W24))=0),IF($X24="","",$X24),($Z25-IF($W25="",0,$W25))+($X24-($Z24-IF($W24="",0,$W24)))*(1+2*(($Z25-IF($W25="",0,$W25))/($Z24-IF($W24="",0,$W24))-1))),IF($X24="","",$X24))) | Y25: =IF($A25="","",IFERROR(IF(OR($S25="",$S24="",$Y24="",$S24=0),IF($Y24="","",$Y24),$S25+($Y24-$S24)*(1+2*($S25/$S24-1))),IF($Y24="","",$Y24))) | Z25: =IF($S25="","",$S25+IF($U25="",0,$U25)+IF($V25="",0,$V25)) | AA25: =SUMIFS('09_CF_원금'!$E$6:$E$92,'09_CF_원금'!$D$6:$D$92,"국장",'09_CF_원금'!$A$6:$A$92,"<="&$A25)-SUMIFS('09_CF_원금'!$E$6:$E$92,'09_CF_원금'!$C$6:$C$92,"국장",'09_CF_원금'!$A$6:$A$92,"<="&$A25) -> 150000000 | AB25: =SUMIFS('09_CF_원금'!$E$6:$E$92,'09_CF_원금'!$D$6:$D$92,"미장",'09_CF_원금'!$A$6:$A$92,"<="&$A25)-SUMIFS('09_CF_원금'!$E$6:$E$92,'09_CF_원금'!$C$6:$C$92,"미장",'09_CF_원금'!$A$6:$A$92,"<="&$A25) -> 150000000 | AC25: =SUMIFS('09_CF_원금'!$E$6:$E$92,'09_CF_원금'!$D$6:$D$92,"ISA",'09_CF_원금'!$A$6:$A$92,"<="&$A25)-SUMIFS('09_CF_원금'!$E$6:$E$92,'09_CF_원금'!$C$6:$C$92,"ISA",'09_CF_원금'!$A$6:$A$92,"<="&$A25) -> 40000000 | AD25: =IF($A25="","",$AA25+$AB25+$AC25+SUMIFS('09_CF_원금'!$E$6:$E$92,'09_CF_원금'!$D$6:$D$92,"중국",'09_CF_원금'!$A$6:$A$92,"<="&$A25)-SUMIFS('09_CF_원금'!$E$6:$E$92,'09_CF_원금'!$C$6:$C$92,"중국",'09_CF_원금'!$A$6:$A$92,"<="&$A25)) -> 340000000 | AE25: =IF($B25="","",MAX($B$5:$B25)) | AK25: =IF($A25="","",YEAR($A25)*100+MONTH($A25)) -> 202601 | AL25: =IF($P25="","",IF($P25="😱 극도의 공포",-2,IF($P25="😨 공포",-1,IF($P25="😐 평온",0,IF($P25="😃 탐욕",1,IF($P25="🤑 극도의 탐욕",2,""))))))
